Workbook

Sheet 注文弁当の抽出
A1: 赤 | B1: 24 | C1: 弁当 園児 | F1: キャラ弁（学食） | G1: 24 | I1: 弁当 園児
A2: パンカップ | B2: 69 | C2: パン 園児 | F2: キャラ弁当 | G2: 24 | I2: 弁当 園児
A3: ピクニック | B3: 20 | C3: ピクニック 園児 | F3: =IF(A1<>"",A1,"") -> 赤 | G3: =IF(B1<>"",B1, IF(F3<>"", OFFSET(商品マスタ!$A$1,MATCH("*"&F3&"*",商品マスタ!D:D,0)-1,8),"")) -> 24 | I3: =IF(C1<>"",C1, IF(F3<>"", IF(COUNTIF(OFFSET(商品マスタ!$A$1,MATCH("*"&F3&"*",商品マスタ!D:D,0)-1,2),"*園児*"), OFFSET(商品マスタ!$A$1,MATCH("*"&F3&"*",商品マスタ!D:D,0)-1,2),OFFSET(商品マスタ!$A$1,MATCH("*"&F3&"*",商品マスタ!D:D,0)-1,2)&" 園児"),"")) -> 弁当 園児
A4: 配膳スマ | B4: 0 | C4: 配膳給食 園児 | F4: =IF(A2<>"",A2,"") -> パンカップ | G4: =IF(B2<>"",B2, IF(F4<>"", OFFSET(商品マスタ!$A$1,MATCH("*"&F4&"*",商品マスタ!D:D,0)-1,8),"")) -> 69 | I4: =IF(C2<>"",C2, IF(F4<>"", IF(COUNTIF(OFFSET(商品マスタ!$A$1,MATCH("*"&F4&"*",商品マスタ!D:D,0)-1,2),"*園児*"), OFFSET(商品マスタ!$A$1,MATCH("*"&F4&"*",商品マスタ!D:D,0)-1,2),OFFSET(商品マスタ!$A$1,MATCH("*"&F4&"*",商品マスタ!D:D,0)-1,2)&" 園児"),"")) -> パン 園児
A5: どんぶり給 | F5: =IF(A3<>"",A3,"") -> ピクニック | G5: =IF(B3<>"",B3, IF(F5<>"", OFFSET(商品マスタ!$A$1,MATCH("*"&F5&"*",商品マスタ!D:D,0)-1,8),"")) -> 20 | I5: =IF(C3<>"",C3, IF(F5<>"", IF(COUNTIF(OFFSET(商品マスタ!$A$1,MATCH("*"&F5&"*",商品マスタ!D:D,0)-1,2),"*園児*"), OFFSET(商品マスタ!$A$1,MATCH("*"&F5&"*",商品マスタ!D:D,0)-1,2),OFFSET(商品マスタ!$A$1,MATCH("*"&F5&"*",商品マスタ!D:D,0)-1,2)&" 園児"),"")) -> ピクニック 園児
F6: =IF(A4<>"",A4,"") -> 配膳スマ | G6: =IF(B4<>"",B4, IF(F6<>"", OFFSET(商品マスタ!$A$1,MATCH("*"&F6&"*",商品マスタ!D:D,0)-1,8),"")) -> 0 | I6: =IF(C4<>"",C4, IF(F6<>"", IF(COUNTIF(OFFSET(商品マスタ!$A$1,MATCH("*"&F6&"*",商品マスタ!D:D,0)-1,2),"*園児*"), OFFSET(商品マスタ!$A$1,MATCH("*"&F6&"*",商品マスタ!D:D,0)-1,2),OFFSET(商品マスタ!$A$1,MATCH("*"&F6&"*",商品マスタ!D:D,0)-1,2)&" 園児"),"")) -> 配膳給食 園児
F7: =IF(A5<>"",A5,"") -> どんぶり給 | G7: =IF(B5<>"",B5, IF(F7<>"", OFFSET(商品マスタ!$A$1,MATCH("*"&F7&"*",商品マスタ!D:D,0)-1,8),"")) -> 0 | I7: =IF(C5<>"",C5, IF(F7<>"", IF(COUNTIF(OFFSET(商品マスタ!$A$1,MATCH("*"&F7&"*",商品マスタ!D:D,0)-1,2),"*園児*"), OFFSET(商品マスタ!$A$1,MATCH("*"&F7&"*",商品マスタ!D:D,0)-1,2),OFFSET(商品マスタ!$A$1,MATCH("*"&F7&"*",商品マスタ!D:D,0)-1,2)&" 園児"),"")) -> どんぶり給食 園児
F8: =IF(A6<>"",A6,"") | G8: =IF(B6<>"",B6, IF(F8<>"", OFFSET(商品マスタ!$A$1,MATCH("*"&F8&"*",商品マスタ!D:D,0)-1,8),"")) | I8: =IF(C6<>"",C6, IF(F8<>"", IF(COUNTIF(OFFSET(商品マスタ!$A$1,MATCH("*"&F8&"*",商品マスタ!D:D,0)-1,2),"*園児*"), OFFSET(商品マスタ!$A$1,MATCH("*"&F8&"*",商品マスタ!D:D,0)-1,2),OFFSET(商品マスタ!$A$1,MATCH("*"&F8&"*",商品マスタ!D:D,0)-1,2)&" 園児"),""))
F9: =IF(A7<>"",A7,"") | G9: =IF(B7<>"",B7, IF(F9<>"", OFFSET(商品マスタ!$A$1,MATCH("*"&F9&"*",商品マスタ!D:D,0)-1,8),"")) | I9: =IF(C7<>"",C7, IF(F9<>"", IF(COUNTIF(OFFSET(商品マスタ!$A$1,MATCH("*"&F9&"*",商品マスタ!D:D,0)-1,2),"*園児*"), OFFSET(商品マスタ!$A$1,MATCH("*"&F9&"*",商品マスタ!D:D,0)-1,2),OFFSET(商品マスタ!$A$1,MATCH("*"&F9&"*",商品マスタ!D:D,0)-1,2)&" 園児"),""))
F10: =IF(A8<>"",A8,"") | G10: =IF(B8<>"",B8, IF(F10<>"", OFFSET(商品マスタ!$A$1,MATCH("*"&F10&"*",商品マスタ!D:D,0)-1,8),"")) | I10: =IF(C8<>"",C8, IF(F10<>"", IF(COUNTIF(OFFSET(商品マスタ!$A$1,MATCH("*"&F10&"*",商品マスタ!D:D,0)-1,2),"*園児*"), OFFSET(商品マスタ!$A$1,MATCH("*"&F10&"*",商品マスタ!D:D,0)-1,2),OFFSET(商品マスタ!$A$1,MATCH("*"&F10&"*",商品マスタ!D:D,0)-1,2)&" 園児"),""))
F11: =IF(A9<>"",A9,"") | G11: =IF(B9<>"",B9, IF(F11<>"", OFFSET(商品マスタ!$A$1,MATCH("*"&F11&"*",商品マスタ!D:D,0)-1,8),"")) | I11: =IF(C9<>"",C9, IF(F11<>"", IF(COUNTIF(OFFSET(商品マスタ!$A$1,MATCH("*"&F11&"*",商品マスタ!D:D,0)-1,2),"*園児*"), OFFSET(商品マスタ!$A$1,MATCH("*"&F11&"*",商品マスタ!D:D,0)-1,2),OFFSET(商品マスタ!$A$1,MATCH("*"&F11&"*",商品マスタ!D:D,0)-1,2)&" 園児"),""))
F12: =IF(A10<>"",A10,"") | G12: =IF(B10<>"",B10, IF(F12<>"", OFFSET(商品マスタ!$A$1,MATCH("*"&F12&"*",商品マスタ!D:D,0)-1,8),"")) | I12: =IF(C10<>"",C10, IF(F12<>"", IF(COUNTIF(OFFSET(商品マスタ!$A$1,MATCH("*"&F12&"*",商品マスタ!D:D,0)-1,2),"*園児*"), OFFSET(商品マスタ!$A$1,MATCH("*"&F12&"*",商品マスタ!D:D,0)-1,2),OFFSET(商品マスタ!$A$1,MATCH("*"&F12&"*",商品マスタ!D:D,0)-1,2)&" 園児"),""))
F13: =IF(A11<>"",A11,"") | G13: =IF(B11<>"",B11, IF(F13<>"", OFFSET(商品マスタ!$A$1,MATCH("*"&F13&"*",商品マスタ!D:D,0)-1,8),"")) | I13: =IF(C11<>"",C11, IF(F13<>"", IF(COUNTIF(OFFSET(商品マスタ!$A$1,MATCH("*"&F13&"*",商品マスタ!D:D,0)-1,2),"*園児*"), OFFSET(商品マスタ!$A$1,MATCH("*"&F13&"*",商品マスタ!D:D,0)-1,2),OFFSET(商品マスタ!$A$1,MATCH("*"&F13&"*",商品マスタ!D:D,0)-1,2)&" 園児"),""))
G14: =IF(B12<>"",B12, IF(F14<>"", OFFSET(商品マスタ!$A$1,MATCH("*"&F14&"*",商品マスタ!D:D,0)-1,8),"")) | I14: =IF(C12<>"",C12, IF(F14<>"", IF(COUNTIF(OFFSET(商品マスタ!$A$1,MATCH("*"&F14&"*",商品マスタ!D:D,0)-1,2),"*園児*"), OFFSET(商品マスタ!$A$1,MATCH("*"&F14&"*",商品マスタ!D:D,0)-1,2),OFFSET(商品マスタ!$A$1,MATCH("*"&F14&"*",商品マスタ!D:D,0)-1,2)&" 園児"),""))

Sheet クライアント抽出
A1: 雙葉小学校 web | B1: 92 | C1: 48 | I1: 7 | J1: {=IFERROR(IF(OR(COUNTIF(INDIRECT("数出表_Excel!"&P1&"3"),"*キャラ*"), COUNTIF(INDIRECT("数出表_Excel!"&P1&"3"),"*赤*")), IF(COUNTIF(A1,"*雙葉*"),INDIRECT("数出表_Excel!"&P1&"3"), INDIRECT("数出表_Excel!"&P1&"3") &" "&INDIRECT("数出表_Excel!"&P1&"4") &INDIRECT("数出表_Excel!"&P1&"5")), INDIRECT("数出表_Excel!"&P1&"3")),"")} -> キャラ弁（学食） | K1: {=IFERROR(IF(OR(COUNTIF(INDIRECT("数出表_Excel!"&Q1&"3"),"*キャラ*"), COUNTIF(INDIRECT("数出表_Excel!"&Q1&"3"),"*赤*")), INDIRECT("数出表_Excel!"&Q1&"3") &" "&INDIRECT("数出表_Excel!"&Q1&"4") &INDIRECT("数出表_Excel!"&Q1&"5"), INDIRECT("数出表_Excel!"&Q1&"3")),"")} -> キャラ弁（学食） 飯あり150 | L1: {=IFERROR(IF(OR(COUNTIF(INDIRECT("数出表_Excel!"&R1&"3"),"*キャラ*"), COUNTIF(INDIRECT("数出表_Excel!"&R1&"3"),"*赤*")), INDIRECT("数出表_Excel!"&R1&"3") &" "&INDIRECT("数出表_Excel!"&R1&"4") &INDIRECT("数出表_Excel!"&R1&"5"), INDIRECT("数出表_Excel!"&R1&"3")),"")} | M1: {=IFERROR(IF(OR(COUNTIF(INDIRECT("数出表_Excel!"&S1&"3"),"*キャラ*"), COUNTIF(INDIRECT("数出表_Excel!"&S1&"3"),"*赤*")), INDIRECT("数出表_Excel!"&S1&"3") &" "&INDIRECT("数出表_Excel!"&S1&"4") &INDIRECT("数出表_Excel!"&S1&"5"), INDIRECT("数出表_Excel!"&S1&"3")),"")} | N1: {=IFERROR(IF(OR(COUNTIF(INDIRECT("数出表_Excel!"&T1&"3"),"*キャラ*"), COUNTIF(INDIRECT("数出表_Excel!"&T1&"3"),"*赤*")), INDIRECT("数出表_Excel!"&T1&"3") &" "&INDIRECT("数出表_Excel!"&T1&"4") &INDIRECT("数出表_Excel!"&T1&"5"), INDIRECT("数出表_Excel!"&T1&"3")),"")} | O1: {=IFERROR(IF(OR(COUNTIF(INDIRECT("数出表_Excel!"&U1&"3"),"*キャラ*"), COUNTIF(INDIRECT("数出表_Excel!"&U1&"3"),"*赤*")), INDIRECT("数出表_Excel!"&U1&"3") &" "&INDIRECT("数出表_Excel!"&U1&"4") &INDIRECT("数出表_Excel!"&U1&"5"), INDIRECT("数出表_Excel!"&U1&"3")),"")} | P1: =IFERROR( SUBSTITUTE(ADDRESS(1, IFERROR(COLUMN(INDEX(INDIRECT("数出表_Excel!B"&$I1-1&":T"&$I1-1&""),1,MATCH(TEXT(B1,0),INDIRECT("数出表_Excel!B"&$I1-1&":T"&$I1-1&""),0))),""),4),"1",""), "") -> B | Q1: =IFERROR( SUBSTITUTE(ADDRESS(1, IFERROR(COLUMN(INDEX(INDIRECT("数出表_Excel!B"&$I1-1&":T"&$I1-1&""),1,MATCH(TEXT(C1,0),INDIRECT("数出表_Excel!B"&$I1-1&":T"&$I1-1&""),0))),""),4),"1",""), "") -> C | R1: =IFERROR( SUBSTITUTE(ADDRESS(1, IFERROR(COLUMN(INDEX(INDIRECT("数出表_Excel!B"&$I1-1&":T"&$I1-1&""),1,MATCH(TEXT(D1,0),INDIRECT("数出表_Excel!B"&$I1-1&":T"&$I1-1&""),0))),""),4),"1",""), "") | S1: =IFERROR( SUBSTITUTE(ADDRESS(1, IFERROR(COLUMN(INDEX(INDIRECT("数出表_Excel!B"&$I1&":T"&$I1&""),1,MATCH(TEXT(E1,0),INDIRECT("数出表_Excel!B"&$I1&":T"&$I1&""),0))),""),4),"1",""), "") | T1: =IFERROR( SUBSTITUTE(ADDRESS(1, IFERROR(COLUMN(INDEX(INDIRECT("数出表_Excel!B"&$I1&":T"&$I1&""),1,MATCH(TEXT(F1,0),INDIRECT("数出表_Excel!B"&$I1&":T"&$I1&""),0))),""),4),"1",""), "") | U1: =IFERROR( SUBSTITUTE(ADDRESS(1, IFERROR(COLUMN(INDEX(INDIRECT("数出表_Excel!B"&$I1&":T"&$I1&""),1,MATCH(TEXT(G1,0),INDIRECT("数出表_Excel!B"&$I1&":T"&$I1&""),0))),""),4),"1",""), "") | V1: =TRIM(SUBSTITUTE( IF(COUNTIF(P1:U1,"A")>0,"A ","")& IF(COUNTIF(P1:U1,"B")>0,"B ","")& IF(COUNTIF(P1:U1,"C")>0,"C ","")& IF(COUNTIF(P1:U1,"D")>0,"D ","")& IF(COUNTIF(P1:U1,"E")>0,"E ","")& IF(COUNTIF(P1:U1,"F")>0,"F ","")& IF(COUNTIF(P1:U1,"G")>0,"G ","")& IF(COUNTIF(P1:U1,"H")>0,"H ","")& IF(COUNTIF(P1:U1,"I")>0,"I ","")& IF(COUNTIF(P1:U1,"J")>0,"J ","")& IF(COUNTIF(P1:U1,"K")>0,"K ","")& IF(COUNTIF(P1:U1,"L")>0,"L ","")& IF(COUNTIF(P1:U1,"M")>0,"M ","")& IF(COUNTIF(P1:U1,"N")>0,"N ","")& IF(COUNTIF(P1:U1,"O")>0,"O ","")& IF(COUNTIF(P1:U1,"P")>0,"P ","")& IF(COUNTIF(P1:U1,"Q")>0,"Q ","")& IF(COUNTIF(P1:U1,"R")>0,"R ","")& IF(COUNTIF(P1:U1,"S")>0,"S ","")& IF(COUNTIF(P1:U1,"T")>0,"T ","")& IF(COUNTIF(P1:U1,"U")>0,"U ","")& IF(COUNTIF(P1:U1,"V")>0,"V ","")& IF(COUNTIF(P1:U1,"W")>0,"W ","")& IF(COUNTIF(P1:U1,"X")>0,"X ","")& IF(COUNTIF(P1:U1,"Y")>0,"Y ","")& IF(COUNTIF(P1:U1,"Z")>0,"Z ","")," ",",")) -> B,C,
A2: 雙葉小学校 先生 | B2: 8 | I2: =I1+2 -> 9 | J2: {=IFERROR(IF(OR(COUNTIF(INDIRECT("数出表_Excel!"&P2&"3"),"*キャラ*"), COUNTIF(INDIRECT("数出表_Excel!"&P2&"3"),"*赤*")), IF(COUNTIF(A2,"*雙葉*"),INDIRECT("数出表_Excel!"&P2&"3"), INDIRECT("数出表_Excel!"&P2&"3") &" "&INDIRECT("数出表_Excel!"&P2&"4") &INDIRECT("数出表_Excel!"&P2&"5")), INDIRECT("数出表_Excel!"&P2&"3")),"")} -> キャラ弁（学食） | K2: {=IFERROR(IF(OR(COUNTIF(INDIRECT("数出表_Excel!"&Q2&"3"),"*キャラ*"), COUNTIF(INDIRECT("数出表_Excel!"&Q2&"3"),"*赤*")), INDIRECT("数出表_Excel!"&Q2&"3") &" "&INDIRECT("数出表_Excel!"&Q2&"4") &INDIRECT("数出表_Excel!"&Q2&"5"), INDIRECT("数出表_Excel!"&Q2&"3")),"")} | L2: {=IFERROR(IF(OR(COUNTIF(INDIRECT("数出表_Excel!"&R2&"3"),"*キャラ*"), COUNTIF(INDIRECT("数出表_Excel!"&R2&"3"),"*赤*")), INDIRECT("数出表_Excel!"&R2&"3") &" "&INDIRECT("数出表_Excel!"&R2&"4") &INDIRECT("数出表_Excel!"&R2&"5"), INDIRECT("数出表_Excel!"&R2&"3")),"")} | M2: {=IFERROR(IF(OR(COUNTIF(INDIRECT("数出表_Excel!"&S2&"3"),"*キャラ*"), COUNTIF(INDIRECT("数出表_Excel!"&S2&"3"),"*赤*")), INDIRECT("数出表_Excel!"&S2&"3") &" "&INDIRECT("数出表_Excel!"&S2&"4") &INDIRECT("数出表_Excel!"&S2&"5"), INDIRECT("数出表_Excel!"&S2&"3")),"")} | N2: {=IFERROR(IF(OR(COUNTIF(INDIRECT("数出表_Excel!"&T2&"3"),"*キャラ*"), COUNTIF(INDIRECT("数出表_Excel!"&T2&"3"),"*赤*")), INDIRECT("数出表_Excel!"&T2&"3") &" "&INDIRECT("数出表_Excel!"&T2&"4") &INDIRECT("数出表_Excel!"&T2&"5"), INDIRECT("数出表_Excel!"&T2&"3")),"")} | O2: {=IFERROR(IF(OR(COUNTIF(INDIRECT("数出表_Excel!"&U2&"3"),"*キャラ*"), COUNTIF(INDIRECT("数出表_Excel!"&U2&"3"),"*赤*")), INDIRECT("数出表_Excel!"&U2&"3") &" "&INDIRECT("数出表_Excel!"&U2&"4") &INDIRECT("数出表_Excel!"&U2&"5"), INDIRECT("数出表_Excel!"&U2&"3")),"")} | P2: =IFERROR( SUBSTITUTE(ADDRESS(1, IFERROR(COLUMN(INDEX(INDIRECT("数出表_Excel!B"&$I2-1&":T"&$I2-1&""),1,MATCH(TEXT(B2,0),INDIRECT("数出表_Excel!B"&$I2-1&":T"&$I2-1&""),0))),""),4),"1",""), "") -> C | Q2: =IFERROR( SUBSTITUTE(ADDRESS(1, IFERROR(COLUMN(INDEX(INDIRECT("数出表_Excel!B"&$I2-1&":T"&$I2-1&""),1,MATCH(TEXT(C2,0),INDIRECT("数出表_Excel!B"&$I2-1&":T"&$I2-1&""),0))),""),4),"1",""), "") | R2: =IFERROR( SUBSTITUTE(ADDRESS(1, IFERROR(COLUMN(INDEX(INDIRECT("数出表_Excel!B"&$I2-1&":T"&$I2-1&""),1,MATCH(TEXT(D2,0),INDIRECT("数出表_Excel!B"&$I2-1&":T"&$I2-1&""),0))),""),4),"1",""), "") | S2: =IFERROR( SUBSTITUTE(ADDRESS(1, IFERROR(COLUMN(INDEX(INDIRECT("数出表_Excel!B"&$I2&":T"&$I2&""),1,MATCH(TEXT(E2,0),INDIRECT("数出表_Excel!B"&$I2&":T"&$I2&""),0))),""),4),"1",""), "") | T2: =IFERROR( SUBSTITUTE(ADDRESS(1, IFERROR(COLUMN(INDEX(INDIRECT("数出表_Excel!B"&$I2&":T"&$I2&""),1,MATCH(TEXT(F2,0),INDIRECT("数出表_Excel!B"&$I2&":T"&$I2&""),0))),""),4),"1",""), "") | U2: =IFERROR( SUBSTITUTE(ADDRESS(1, IFERROR(COLUMN(INDEX(INDIRECT("数出表_Excel!B"&$I2&":T"&$I2&""),1,MATCH(TEXT(G2,0),INDIRECT("数出表_Excel!B"&$I2&":T"&$I2&""),0))),""),4),"1",""), "") | V2: =TRIM(SUBSTITUTE( IF(COUNTIF(P2:U2,"A")>0,"A ","")& IF(COUNTIF(P2:U2,"B")>0,"B ","")& IF(COUNTIF(P2:U2,"C")>0,"C ","")& IF(COUNTIF(P2:U2,"D")>0,"D ","")& IF(COUNTIF(P2:U2,"E")>0,"E ","")& IF(COUNTIF(P2:U2,"F")>0,"F ","")& IF(COUNTIF(P2:U2,"G")>0,"G ","")& IF(COUNTIF(P2:U2,"H")>0,"H ","")& IF(COUNTIF(P2:U2,"I")>0,"I ","")& IF(COUNTIF(P2:U2,"J")>0,"J ","")& IF(COUNTIF(P2:U2,"K")>0,"K ","")& IF(COUNTIF(P2:U2,"L")>0,"L ","")& IF(COUNTIF(P2:U2,"M")>0,"M ","")& IF(COUNTIF(P2:U2,"N")>0,"N ","")& IF(COUNTIF(P2:U2,"O")>0,"O ","")& IF(COUNTIF(P2:U2,"P")>0,"P ","")& IF(COUNTIF(P2:U2,"Q")>0,"Q ","")& IF(COUNTIF(P2:U2,"R")>0,"R ","")& IF(COUNTIF(P2:U2,"S")>0,"S ","")& IF(COUNTIF(P2:U2,"T")>0,"T ","")& IF(COUNTIF(P2:U2,"U")>0,"U ","")& IF(COUNTIF(P2:U2,"V")>0,"V ","")& IF(COUNTIF(P2:U2,"W")>0,"W ","")& IF(COUNTIF(P2:U2,"X")>0,"X ","")& IF(COUNTIF(P2:U2,"Y")>0,"Y ","")& IF(COUNTIF(P2:U2,"Z")>0,"Z ","")," ",",")) -> C,
A3: シンキングキッズ | B3: 4 | I3: =I2+2 -> 11 | J3: {=IFERROR(IF(OR(COUNTIF(INDIRECT("数出表_Excel!"&P3&"3"),"*キャラ*"), COUNTIF(INDIRECT("数出表_Excel!"&P3&"3"),"*赤*")), IF(COUNTIF(A3,"*雙葉*"),INDIRECT("数出表_Excel!"&P3&"3"), INDIRECT("数出表_Excel!"&P3&"3") &" "&INDIRECT("数出表_Excel!"&P3&"4") &INDIRECT("数出表_Excel!"&P3&"5")), INDIRECT("数出表_Excel!"&P3&"3")),"")} -> 赤 飯あり120 | K3: {=IFERROR(IF(OR(COUNTIF(INDIRECT("数出表_Excel!"&Q3&"3"),"*キャラ*"), COUNTIF(INDIRECT("数出表_Excel!"&Q3&"3"),"*赤*")), INDIRECT("数出表_Excel!"&Q3&"3") &" "&INDIRECT("数出表_Excel!"&Q3&"4") &INDIRECT("数出表_Excel!"&Q3&"5"), INDIRECT("数出表_Excel!"&Q3&"3")),"")} | L3: {=IFERROR(IF(OR(COUNTIF(INDIRECT("数出表_Excel!"&R3&"3"),"*キャラ*"), COUNTIF(INDIRECT("数出表_Excel!"&R3&"3"),"*赤*")), INDIRECT("数出表_Excel!"&R3&"3") &" "&INDIRECT("数出表_Excel!"&R3&"4") &INDIRECT("数出表_Excel!"&R3&"5"), INDIRECT("数出表_Excel!"&R3&"3")),"")} | M3: {=IFERROR(IF(OR(COUNTIF(INDIRECT("数出表_Excel!"&S3&"3"),"*キャラ*"), COUNTIF(INDIRECT("数出表_Excel!"&S3&"3"),"*赤*")), INDIRECT("数出表_Excel!"&S3&"3") &" "&INDIRECT("数出表_Excel!"&S3&"4") &INDIRECT("数出表_Excel!"&S3&"5"), INDIRECT("数出表_Excel!"&S3&"3")),"")} | N3: {=IFERROR(IF(OR(COUNTIF(INDIRECT("数出表_Excel!"&T3&"3"),"*キャラ*"), COUNTIF(INDIRECT("数出表_Excel!"&T3&"3"),"*赤*")), INDIRECT("数出表_Excel!"&T3&"3") &" "&INDIRECT("数出表_Excel!"&T3&"4") &INDIRECT("数出表_Excel!"&T3&"5"), INDIRECT("数出表_Excel!"&T3&"3")),"")} | O3: {=IFERROR(IF(OR(COUNTIF(INDIRECT("数出表_Excel!"&U3&"3"),"*キャラ*"), COUNTIF(INDIRECT("数出表_Excel!"&U3&"3"),"*赤*")), INDIRECT("数出表_Excel!"&U3&"3") &" "&INDIRECT("数出表_Excel!"&U3&"4") &INDIRECT("数出表_Excel!"&U3&"5"), INDIRECT("数出表_Excel!"&U3&"3")),"")} | P3: =IFERROR( SUBSTITUTE(ADDRESS(1, IFERROR(COLUMN(INDEX(INDIRECT("数出表_Excel!B"&$I3-1&":T"&$I3-1&""),1,MATCH(TEXT(B3,0),INDIRECT("数出表_Excel!B"&$I3-1&":T"&$I3-1&""),0))),""),4),"1",""), "") -> G | Q3: =IFERROR( SUBSTITUTE(ADDRESS(1, IFERROR(COLUMN(INDEX(INDIRECT("数出表_Excel!B"&$I3-1&":T"&$I3-1&""),1,MATCH(TEXT(C3,0),INDIRECT("数出表_Excel!B"&$I3-1&":T"&$I3-1&""),0))),""),4),"1",""), "") | R3: =IFERROR( SUBSTITUTE(ADDRESS(1, IFERROR(COLUMN(INDEX(INDIRECT("数出表_Excel!B"&$I3-1&":T"&$I3-1&""),1,MATCH(TEXT(D3,0),INDIRECT("数出表_Excel!B"&$I3-1&":T"&$I3-1&""),0))),""),4),"1",""), "") | S3: =IFERROR( SUBSTITUTE(ADDRESS(1, IFERROR(COLUMN(INDEX(INDIRECT("数出表_Excel!B"&$I3&":T"&$I3&""),1,MATCH(TEXT(E3,0),INDIRECT("数出表_Excel!B"&$I3&":T"&$I3&""),0))),""),4),"1",""), "") | T3: =IFERROR( SUBSTITUTE(ADDRESS(1, IFERROR(COLUMN(INDEX(INDIRECT("数出表_Excel!B"&$I3&":T"&$I3&""),1,MATCH(TEXT(F3,0),INDIRECT("数出表_Excel!B"&$I3&":T"&$I3&""),0))),""),4),"1",""), "") | U3: =IFERROR( SUBSTITUTE(ADDRESS(1, IFERROR(COLUMN(INDEX(INDIRECT("数出表_Excel!B"&$I3&":T"&$I3&""),1,MATCH(TEXT(G3,0),INDIRECT("数出表_Excel!B"&$I3&":T"&$I3&""),0))),""),4),"1",""), "") | V3: =TRIM(SUBSTITUTE( IF(COUNTIF(P3:U3,"A")>0,"A ","")& IF(COUNTIF(P3:U3,"B")>0,"B ","")& IF(COUNTIF(P3:U3,"C")>0,"C ","")& IF(COUNTIF(P3:U3,"D")>0,"D ","")& IF(COUNTIF(P3:U3,"E")>0,"E ","")& IF(COUNTIF(P3:U3,"F")>0,"F ","")& IF(COUNTIF(P3:U3,"G")>0,"G ","")& IF(COUNTIF(P3:U3,"H")>0,"H ","")& IF(COUNTIF(P3:U3,"I")>0,"I ","")& IF(COUNTIF(P3:U3,"J")>0,"J ","")& IF(COUNTIF(P3:U3,"K")>0,"K ","")& IF(COUNTIF(P3:U3,"L")>0,"L ","")& IF(COUNTIF(P3:U3,"M")>0,"M ","")& IF(COUNTIF(P3:U3,"N")>0,"N ","")& IF(COUNTIF(P3:U3,"O")>0,"O ","")& IF(COUNTIF(P3:U3,"P")>0,"P ","")& IF(COUNTIF(P3:U3,"Q")>0,"Q ","")& IF(COUNTIF(P3:U3,"R")>0,"R ","")& IF(COUNTIF(P3:U3,"S")>0,"S ","")& IF(COUNTIF(P3:U3,"T")>0,"T ","")& IF(COUNTIF(P3:U3,"U")>0,"U ","")& IF(COUNTIF(P3:U3,"V")>0,"V ","")& IF(COUNTIF(P3:U3,"W")>0,"W ","")& IF(COUNTIF(P3:U3,"X")>0,"X ","")& IF(COUNTIF(P3:U3,"Y")>0,"Y ","")& IF(COUNTIF(P3:U3,"Z")>0,"Z ","")," ",",")) -> G,
A4: なないろキッズ | B4: 9 | I4: =I3+2 -> 13 | J4: {=IFERROR(IF(OR(COUNTIF(INDIRECT("数出表_Excel!"&P4&"3"),"*キャラ*"), COUNTIF(INDIRECT("数出表_Excel!"&P4&"3"),"*赤*")), IF(COUNTIF(A4,"*雙葉*"),INDIRECT("数出表_Excel!"&P4&"3"), INDIRECT("数出表_Excel!"&P4&"3") &" "&INDIRECT("数出表_Excel!"&P4&"4") &INDIRECT("数出表_Excel!"&P4&"5")), INDIRECT("数出表_Excel!"&P4&"3")),"")} -> 赤 飯あり120 | K4: {=IFERROR(IF(OR(COUNTIF(INDIRECT("数出表_Excel!"&Q4&"3"),"*キャラ*"), COUNTIF(INDIRECT("数出表_Excel!"&Q4&"3"),"*赤*")), INDIRECT("数出表_Excel!"&Q4&"3") &" "&INDIRECT("数出表_Excel!"&Q4&"4") &INDIRECT("数出表_Excel!"&Q4&"5"), INDIRECT("数出表_Excel!"&Q4&"3")),"")} | L4: {=IFERROR(IF(OR(COUNTIF(INDIRECT("数出表_Excel!"&R4&"3"),"*キャラ*"), COUNTIF(INDIRECT("数出表_Excel!"&R4&"3"),"*赤*")), INDIRECT("数出表_Excel!"&R4&"3") &" "&INDIRECT("数出表_Excel!"&R4&"4") &INDIRECT("数出表_Excel!"&R4&"5"), INDIRECT("数出表_Excel!"&R4&"3")),"")} | M4: {=IFERROR(IF(OR(COUNTIF(INDIRECT("数出表_Excel!"&S4&"3"),"*キャラ*"), COUNTIF(INDIRECT("数出表_Excel!"&S4&"3"),"*赤*")), INDIRECT("数出表_Excel!"&S4&"3") &" "&INDIRECT("数出表_Excel!"&S4&"4") &INDIRECT("数出表_Excel!"&S4&"5"), INDIRECT("数出表_Excel!"&S4&"3")),"")} | N4: {=IFERROR(IF(OR(COUNTIF(INDIRECT("数出表_Excel!"&T4&"3"),"*キャラ*"), COUNTIF(INDIRECT("数出表_Excel!"&T4&"3"),"*赤*")), INDIRECT("数出表_Excel!"&T4&"3") &" "&INDIRECT("数出表_Excel!"&T4&"4") &INDIRECT("数出表_Excel!"&T4&"5"), INDIRECT("数出表_Excel!"&T4&"3")),"")} | O4: {=IFERROR(IF(OR(COUNTIF(INDIRECT("数出表_Excel!"&U4&"3"),"*キャラ*"), COUNTIF(INDIRECT("数出表_Excel!"&U4&"3"),"*赤*")), INDIRECT("数出表_Excel!"&U4&"3") &" "&INDIRECT("数出表_Excel!"&U4&"4") &INDIRECT("数出表_Excel!"&U4&"5"), INDIRECT("数出表_Excel!"&U4&"3")),"")} | P4: =IFERROR( SUBSTITUTE(ADDRESS(1, IFERROR(COLUMN(INDEX(INDIRECT("数出表_Excel!B"&$I4-1&":T"&$I4-1&""),1,MATCH(TEXT(B4,0),INDIRECT("数出表_Excel!B"&$I4-1&":T"&$I4-1&""),0))),""),4),"1",""), "") -> G | Q4: =IFERROR( SUBSTITUTE(ADDRESS(1, IFERROR(COLUMN(INDEX(INDIRECT("数出表_Excel!B"&$I4-1&":T"&$I4-1&""),1,MATCH(TEXT(C4,0),INDIRECT("数出表_Excel!B"&$I4-1&":T"&$I4-1&""),0))),""),4),"1",""), "") | R4: =IFERROR( SUBSTITUTE(ADDRESS(1, IFERROR(COLUMN(INDEX(INDIRECT("数出表_Excel!B"&$I4-1&":T"&$I4-1&""),1,MATCH(TEXT(D4,0),INDIRECT("数出表_Excel!B"&$I4-1&":T"&$I4-1&""),0))),""),4),"1",""), "") | S4: =IFERROR( SUBSTITUTE(ADDRESS(1, IFERROR(COLUMN(INDEX(INDIRECT("数出表_Excel!B"&$I4&":T"&$I4&""),1,MATCH(TEXT(E4,0),INDIRECT("数出表_Excel!B"&$I4&":T"&$I4&""),0))),""),4),"1",""), "") | T4: =IFERROR( SUBSTITUTE(ADDRESS(1, IFERROR(COLUMN(INDEX(INDIRECT("数出表_Excel!B"&$I4&":T"&$I4&""),1,MATCH(TEXT(F4,0),INDIRECT("数出表_Excel!B"&$I4&":T"&$I4&""),0))),""),4),"1",""), "") | U4: =IFERROR( SUBSTITUTE(ADDRESS(1, IFERROR(COLUMN(INDEX(INDIRECT("数出表_Excel!B"&$I4&":T"&$I4&""),1,MATCH(TEXT(G4,0),INDIRECT("数出表_Excel!B"&$I4&":T"&$I4&""),0))),""),4),"1",""), "") | V4: =TRIM(SUBSTITUTE( IF(COUNTIF(P4:U4,"A")>0,"A ","")& IF(COUNTIF(P4:U4,"B")>0,"B ","")& IF(COUNTIF(P4:U4,"C")>0,"C ","")& IF(COUNTIF(P4:U4,"D")>0,"D ","")& IF(COUNTIF(P4:U4,"E")>0,"E ","")& IF(COUNTIF(P4:U4,"F")>0,"F ","")& IF(COUNTIF(P4:U4,"G")>0,"G ","")& IF(COUNTIF(P4:U4,"H")>0,"H ","")& IF(COUNTIF(P4:U4,"I")>0,"I ","")& IF(COUNTIF(P4:U4,"J")>0,"J ","")& IF(COUNTIF(P4:U4,"K")>0,"K ","")& IF(COUNTIF(P4:U4,"L")>0,"L ","")& IF(COUNTIF(P4:U4,"M")>0,"M ","")& IF(COUNTIF(P4:U4,"N")>0,"N ","")& IF(COUNTIF(P4:U4,"O")>0,"O ","")& IF(COUNTIF(P4:U4,"P")>0,"P ","")& IF(COUNTIF(P4:U4,"Q")>0,"Q ","")& IF(COUNTIF(P4:U4,"R")>0,"R ","")& IF(COUNTIF(P4:U4,"S")>0,"S ","")& IF(COUNTIF(P4:U4,"T")>0,"T ","")& IF(COUNTIF(P4:U4,"U")>0,"U ","")& IF(COUNTIF(P4:U4,"V")>0,"V ","")& IF(COUNTIF(P4:U4,"W")>0,"W ","")& IF(COUNTIF(P4:U4,"X")>0,"X ","")& IF(COUNTIF(P4:U4,"Y")>0,"Y ","")& IF(COUNTIF(P4:U4,"Z")>0,"Z ","")," ",",")) -> G,
A5: 博多南 週3ｺｰｽ | B5: 52 | C5: 1 | E5: 12 | F5: 2 | I5: =I4+2 -> 15 | J5: {=IFERROR(IF(OR(COUNTIF(INDIRECT("数出表_Excel!"&P5&"3"),"*キャラ*"), COUNTIF(INDIRECT("数出表_Excel!"&P5&"3"),"*赤*")), IF(COUNTIF(A5,"*雙葉*"),INDIRECT("数出表_Excel!"&P5&"3"), INDIRECT("数出表_Excel!"&P5&"3") &" "&INDIRECT("数出表_Excel!"&P5&"4") &INDIRECT("数出表_Excel!"&P5&"5")), INDIRECT("数出表_Excel!"&P5&"3")),"")} -> キャラ弁当 飯なし | K5: {=IFERROR(IF(OR(COUNTIF(INDIRECT("数出表_Excel!"&Q5&"3"),"*キャラ*"), COUNTIF(INDIRECT("数出表_Excel!"&Q5&"3"),"*赤*")), INDIRECT("数出表_Excel!"&Q5&"3") &" "&INDIRECT("数出表_Excel!"&Q5&"4") &INDIRECT("数出表_Excel!"&Q5&"5"), INDIRECT("数出表_Excel!"&Q5&"3")),"")} -> ピクニック | L5: {=IFERROR(IF(OR(COUNTIF(INDIRECT("数出表_Excel!"&R5&"3"),"*キャラ*"), COUNTIF(INDIRECT("数出表_Excel!"&R5&"3"),"*赤*")), INDIRECT("数出表_Excel!"&R5&"3") &" "&INDIRECT("数出表_Excel!"&R5&"4") &INDIRECT("数出表_Excel!"&R5&"5"), INDIRECT("数出表_Excel!"&R5&"3")),"")} | M5: {=IFERROR(IF(OR(COUNTIF(INDIRECT("数出表_Excel!"&S5&"3"),"*キャラ*"), COUNTIF(INDIRECT("数出表_Excel!"&S5&"3"),"*赤*")), INDIRECT("数出表_Excel!"&S5&"3") &" "&INDIRECT("数出表_Excel!"&S5&"4") &INDIRECT("数出表_Excel!"&S5&"5"), INDIRECT("数出表_Excel!"&S5&"3")),"")} -> キャラ弁当 飯なし | N5: {=IFERROR(IF(OR(COUNTIF(INDIRECT("数出表_Excel!"&T5&"3"),"*キャラ*"), COUNTIF(INDIRECT("数出表_Excel!"&T5&"3"),"*赤*")), INDIRECT("数出表_Excel!"&T5&"3") &" "&INDIRECT("数出表_Excel!"&T5&"4") &INDIRECT("数出表_Excel!"&T5&"5"), INDIRECT("数出表_Excel!"&T5&"3")),"")} -> ピクニック | O5: {=IFERROR(IF(OR(COUNTIF(INDIRECT("数出表_Excel!"&U5&"3"),"*キャラ*"), COUNTIF(INDIRECT("数出表_Excel!"&U5&"3"),"*赤*")), INDIRECT("数出表_Excel!"&U5&"3") &" "&INDIRECT("数出表_Excel!"&U5&"4") &INDIRECT("数出表_Excel!"&U5&"5"), INDIRECT("数出表_Excel!"&U5&"3")),"")} | P5: =IFERROR( SUBSTITUTE(ADDRESS(1, IFERROR(COLUMN(INDEX(INDIRECT("数出表_Excel!B"&$I5-1&":T"&$I5-1&""),1,MATCH(TEXT(B5,0),INDIRECT("数出表_Excel!B"&$I5-1&":T"&$I5-1&""),0))),""),4),"1",""), "") -> F | Q5: =IFERROR( SUBSTITUTE(ADDRESS(1, IFERROR(COLUMN(INDEX(INDIRECT("数出表_Excel!B"&$I5-1&":T"&$I5-1&""),1,MATCH(TEXT(C5,0),INDIRECT("数出表_Excel!B"&$I5-1&":T"&$I5-1&""),0))),""),4),"1",""), "") -> M | R5: =IFERROR( SUBSTITUTE(ADDRESS(1, IFERROR(COLUMN(INDEX(INDIRECT("数出表_Excel!B"&$I5-1&":T"&$I5-1&""),1,MATCH(TEXT(D5,0),INDIRECT("数出表_Excel!B"&$I5-1&":T"&$I5-1&""),0))),""),4),"1",""), "") | S5: =IFERROR( SUBSTITUTE(ADDRESS(1, IFERROR(COLUMN(INDEX(INDIRECT("数出表_Excel!B"&$I5&":T"&$I5&""),1,MATCH(TEXT(E5,0),INDIRECT("数出表_Excel!B"&$I5&":T"&$I5&""),0))),""),4),"1",""), "") -> F | T5: =IFERROR( SUBSTITUTE(ADDRESS(1, IFERROR(COLUMN(INDEX(INDIRECT("数出表_Excel!B"&$I5&":T"&$I5&""),1,MATCH(TEXT(F5,0),INDIRECT("数出表_Excel!B"&$I5&":T"&$I5&""),0))),""),4),"1",""), "") -> M | U5: =IFERROR( SUBSTITUTE(ADDRESS(1, IFERROR(COLUMN(INDEX(INDIRECT("数出表_Excel!B"&$I5&":T"&$I5&""),1,MATCH(TEXT(G5,0),INDIRECT("数出表_Excel!B"&$I5&":T"&$I5&""),0))),""),4),"1",""), "") | V5: =TRIM(SUBSTITUTE( IF(COUNTIF(P5:U5,"A")>0,"A ","")& IF(COUNTIF(P5:U5,"B")>0,"B ","")& IF(COUNTIF(P5:U5,"C")>0,"C ","")& IF(COUNTIF(P5:U5,"D")>0,"D ","")& IF(COUNTIF(P5:U5,"E")>0,"E ","")& IF(COUNTIF(P5:U5,"F")>0,"F ","")& IF(COUNTIF(P5:U5,"G")>0,"G ","")& IF(COUNTIF(P5:U5,"H")>0,"H ","")& IF(COUNTIF(P5:U5,"I")>0,"I ","")& IF(COUNTIF(P5:U5,"J")>0,"J ","")& IF(COUNTIF(P5:U5,"K")>0,"K ","")& IF(COUNTIF(P5:U5,"L")>0,"L ","")& IF(COUNTIF(P5:U5,"M")>0,"M ","")& IF(COUNTIF(P5:U5,"N")>0,"N ","")& IF(COUNTIF(P5:U5,"O")>0,"O ","")& IF(COUNTIF(P5:U5,"P")>0,"P ","")& IF(COUNTIF(P5:U5,"Q")>0,"Q ","")& IF(COUNTIF(P5:U5,"R")>0,"R ","")& IF(COUNTIF(P5:U5,"S")>0,"S ","")& IF(COUNTIF(P5:U5,"T")>0,"T ","")& IF(COUNTIF(P5:U5,"U")>0,"U ","")& IF(COUNTIF(P5:U5,"V")>0,"V ","")& IF(COUNTIF(P5:U5,"W")>0,"W ","")& IF(COUNTIF(P5:U5,"X")>0,"X ","")& IF(COUNTIF(P5:U5,"Y")>0,"Y ","")& IF(COUNTIF(P5:U5,"Z")>0,"Z ","")," ",",")) -> F,M,
A6: 博多南 週5ｺｰｽ | B6: 154 | C6: 36 | I6: =I5+2 -> 17 | J6: {=IFERROR(IF(OR(COUNTIF(INDIRECT("数出表_Excel!"&P6&"3"),"*キャラ*"), COUNTIF(INDIRECT("数出表_Excel!"&P6&"3"),"*赤*")), IF(COUNTIF(A6,"*雙葉*"),INDIRECT("数出表_Excel!"&P6&"3"), INDIRECT("数出表_Excel!"&P6&"3") &" "&INDIRECT("数出表_Excel!"&P6&"4") &INDIRECT("数出表_Excel!"&P6&"5")), INDIRECT("数出表_Excel!"&P6&"3")),"")} -> キャラ弁当 飯なし | K6: {=IFERROR(IF(OR(COUNTIF(INDIRECT("数出表_Excel!"&Q6&"3"),"*キャラ*"), COUNTIF(INDIRECT("数出表_Excel!"&Q6&"3"),"*赤*")), INDIRECT("数出表_Excel!"&Q6&"3") &" "&INDIRECT("数出表_Excel!"&Q6&"4") &INDIRECT("数出表_Excel!"&Q6&"5"), INDIRECT("数出表_Excel!"&Q6&"3")),"")} -> ピクニック | L6: {=IFERROR(IF(OR(COUNTIF(INDIRECT("数出表_Excel!"&R6&"3"),"*キャラ*"), COUNTIF(INDIRECT("数出表_Excel!"&R6&"3"),"*赤*")), INDIRECT("数出表_Excel!"&R6&"3") &" "&INDIRECT("数出表_Excel!"&R6&"4") &INDIRECT("数出表_Excel!"&R6&"5"), INDIRECT("数出表_Excel!"&R6&"3")),"")} | M6: {=IFERROR(IF(OR(COUNTIF(INDIRECT("数出表_Excel!"&S6&"3"),"*キャラ*"), COUNTIF(INDIRECT("数出表_Excel!"&S6&"3"),"*赤*")), INDIRECT("数出表_Excel!"&S6&"3") &" "&INDIRECT("数出表_Excel!"&S6&"4") &INDIRECT("数出表_Excel!"&S6&"5"), INDIRECT("数出表_Excel!"&S6&"3")),"")} | N6: {=IFERROR(IF(OR(COUNTIF(INDIRECT("数出表_Excel!"&T6&"3"),"*キャラ*"), COUNTIF(INDIRECT("数出表_Excel!"&T6&"3"),"*赤*")), INDIRECT("数出表_Excel!"&T6&"3") &" "&INDIRECT("数出表_Excel!"&T6&"4") &INDIRECT("数出表_Excel!"&T6&"5"), INDIRECT("数出表_Excel!"&T6&"3")),"")} | O6: {=IFERROR(IF(OR(COUNTIF(INDIRECT("数出表_Excel!"&U6&"3"),"*キャラ*"), COUNTIF(INDIRECT("数出表_Excel!"&U6&"3"),"*赤*")), INDIRECT("数出表_Excel!"&U6&"3") &" "&INDIRECT("数出表_Excel!"&U6&"4") &INDIRECT("数出表_Excel!"&U6&"5"), INDIRECT("数出表_Excel!"&U6&"3")),"")} | P6: =IFERROR( SUBSTITUTE(ADDRESS(1, IFERROR(COLUMN(INDEX(INDIRECT("数出表_Excel!B"&$I6-1&":T"&$I6-1&""),1,MATCH(TEXT(B6,0),INDIRECT("数出表_Excel!B"&$I6-1&":T"&$I6-1&""),0))),""),4),"1",""), "") -> F | Q6: =IFERROR( SUBSTITUTE(ADDRESS(1, IFERROR(COLUMN(INDEX(INDIRECT("数出表_Excel!B"&$I6-1&":T"&$I6-1&""),1,MATCH(TEXT(C6,0),INDIRECT("数出表_Excel!B"&$I6-1&":T"&$I6-1&""),0))),""),4),"1",""), "") -> M | R6: =IFERROR( SUBSTITUTE(ADDRESS(1, IFERROR(COLUMN(INDEX(INDIRECT("数出表_Excel!B"&$I6-1&":T"&$I6-1&""),1,MATCH(TEXT(D6,0),INDIRECT("数出表_Excel!B"&$I6-1&":T"&$I6-1&""),0))),""),4),"1",""), "") | S6: =IFERROR( SUBSTITUTE(ADDRESS(1, IFERROR(COLUMN(INDEX(INDIRECT("数出表_Excel!B"&$I6&":T"&$I6&""),1,MATCH(TEXT(E6,0),INDIRECT("数出表_Excel!B"&$I6&":T"&$I6&""),0))),""),4),"1",""), "") | T6: =IFERROR( SUBSTITUTE(ADDRESS(1, IFERROR(COLUMN(INDEX(INDIRECT("数出表_Excel!B"&$I6&":T"&$I6&""),1,MATCH(TEXT(F6,0),INDIRECT("数出表_Excel!B"&$I6&":T"&$I6&""),0))),""),4),"1",""), "") | U6: =IFERROR( SUBSTITUTE(ADDRESS(1, IFERROR(COLUMN(INDEX(INDIRECT("数出表_Excel!B"&$I6&":T"&$I6&""),1,MATCH(TEXT(G6,0),INDIRECT("数出表_Excel!B"&$I6&":T"&$I6&""),0))),""),4),"1",""), "") | V6: =TRIM(SUBSTITUTE( IF(COUNTIF(P6:U6,"A")>0,"A ","")& IF(COUNTIF(P6:U6,"B")>0,"B ","")& IF(COUNTIF(P6:U6,"C")>0,"C ","")& IF(COUNTIF(P6:U6,"D")>0,"D ","")& IF(COUNTIF(P6:U6,"E")>0,"E ","")& IF(COUNTIF(P6:U6,"F")>0,"F ","")& IF(COUNTIF(P6:U6,"G")>0,"G ","")& IF(COUNTIF(P6:U6,"H")>0,"H ","")& IF(COUNTIF(P6:U6,"I")>0,"I ","")& IF(COUNTIF(P6:U6,"J")>0,"J ","")& IF(COUNTIF(P6:U6,"K")>0,"K ","")& IF(COUNTIF(P6:U6,"L")>0,"L ","")& IF(COUNTIF(P6:U6,"M")>0,"M ","")& IF(COUNTIF(P6:U6,"N")>0,"N ","")& IF(COUNTIF(P6:U6,"O")>0,"O ","")& IF(COUNTIF(P6:U6,"P")>0,"P ","")& IF(COUNTIF(P6:U6,"Q")>0,"Q ","")& IF(COUNTIF(P6:U6,"R")>0,"R ","")& IF(COUNTIF(P6:U6,"S")>0,"S ","")& IF(COUNTIF(P6:U6,"T")>0,"T ","")& IF(COUNTIF(P6:U6,"U")>0,"U ","")& IF(COUNTIF(P6:U6,"V")>0,"V ","")& IF(COUNTIF(P6:U6,"W")>0,"W ","")& IF(COUNTIF(P6:U6,"X")>0,"X ","")& IF(COUNTIF(P6:U6,"Y")>0,"Y ","")& IF(COUNTIF(P6:U6,"Z")>0,"Z ","")," ",",")) -> F,M,
A7: 博多南（補助教員） web | E7: 4 | I7: =I6+2 -> 19 | J7: {=IFERROR(IF(OR(COUNTIF(INDIRECT("数出表_Excel!"&P7&"3"),"*キャラ*"), COUNTIF(INDIRECT("数出表_Excel!"&P7&"3"),"*赤*")), IF(COUNTIF(A7,"*雙葉*"),INDIRECT("数出表_Excel!"&P7&"3"), INDIRECT("数出表_Excel!"&P7&"3") &" "&INDIRECT("数出表_Excel!"&P7&"4") &INDIRECT("数出表_Excel!"&P7&"5")), INDIRECT("数出表_Excel!"&P7&"3")),"")} | K7: {=IFERROR(IF(OR(COUNTIF(INDIRECT("数出表_Excel!"&Q7&"3"),"*キャラ*"), COUNTIF(INDIRECT("数出表_Excel!"&Q7&"3"),"*赤*")), INDIRECT("数出表_Excel!"&Q7&"3") &" "&INDIRECT("数出表_Excel!"&Q7&"4") &INDIRECT("数出表_Excel!"&Q7&"5"), INDIRECT("数出表_Excel!"&Q7&"3")),"")} | L7: {=IFERROR(IF(OR(COUNTIF(INDIRECT("数出表_Excel!"&R7&"3"),"*キャラ*"), COUNTIF(INDIRECT("数出表_Excel!"&R7&"3"),"*赤*")), INDIRECT("数出表_Excel!"&R7&"3") &" "&INDIRECT("数出表_Excel!"&R7&"4") &INDIRECT("数出表_Excel!"&R7&"5"), INDIRECT("数出表_Excel!"&R7&"3")),"")} | M7: {=IFERROR(IF(OR(COUNTIF(INDIRECT("数出表_Excel!"&S7&"3"),"*キャラ*"), COUNTIF(INDIRECT("数出表_Excel!"&S7&"3"),"*赤*")), INDIRECT("数出表_Excel!"&S7&"3") &" "&INDIRECT("数出表_Excel!"&S7&"4") &INDIRECT("数出表_Excel!"&S7&"5"), INDIRECT("数出表_Excel!"&S7&"3")),"")} -> キャラ弁当 飯あり120 | N7: {=IFERROR(IF(OR(COUNTIF(INDIRECT("数出表_Excel!"&T7&"3"),"*キャラ*"), COUNTIF(INDIRECT("数出表_Excel!"&T7&"3"),"*赤*")), INDIRECT("数出表_Excel!"&T7&"3") &" "&INDIRECT("数出表_Excel!"&T7&"4") &INDIRECT("数出表_Excel!"&T7&"5"), INDIRECT("数出表_Excel!"&T7&"3")),"")} | O7: {=IFERROR(IF(OR(COUNTIF(INDIRECT("数出表_Excel!"&U7&"3"),"*キャラ*"), COUNTIF(INDIRECT("数出表_Excel!"&U7&"3"),"*赤*")), INDIRECT("数出表_Excel!"&U7&"3") &" "&INDIRECT("数出表_Excel!"&U7&"4") &INDIRECT("数出表_Excel!"&U7&"5"), INDIRECT("数出表_Excel!"&U7&"3")),"")} | P7: =IFERROR( SUBSTITUTE(ADDRESS(1, IFERROR(COLUMN(INDEX(INDIRECT("数出表_Excel!B"&$I7-1&":T"&$I7-1&""),1,MATCH(TEXT(B7,0),INDIRECT("数出表_Excel!B"&$I7-1&":T"&$I7-1&""),0))),""),4),"1",""), "") | Q7: =IFERROR( SUBSTITUTE(ADDRESS(1, IFERROR(COLUMN(INDEX(INDIRECT("数出表_Excel!B"&$I7-1&":T"&$I7-1&""),1,MATCH(TEXT(C7,0),INDIRECT("数出表_Excel!B"&$I7-1&":T"&$I7-1&""),0))),""),4),"1",""), "") | R7: =IFERROR( SUBSTITUTE(ADDRESS(1, IFERROR(COLUMN(INDEX(INDIRECT("数出表_Excel!B"&$I7-1&":T"&$I7-1&""),1,MATCH(TEXT(D7,0),INDIRECT("数出表_Excel!B"&$I7-1&":T"&$I7-1&""),0))),""),4),"1",""), "") | S7: =IFERROR( SUBSTITUTE(ADDRESS(1, IFERROR(COLUMN(INDEX(INDIRECT("数出表_Excel!B"&$I7&":T"&$I7&""),1,MATCH(TEXT(E7,0),INDIRECT("数出表_Excel!B"&$I7&":T"&$I7&""),0))),""),4),"1",""), "") -> D | T7: =IFERROR( SUBSTITUTE(ADDRESS(1, IFERROR(COLUMN(INDEX(INDIRECT("数出表_Excel!B"&$I7&":T"&$I7&""),1,MATCH(TEXT(F7,0),INDIRECT("数出表_Excel!B"&$I7&":T"&$I7&""),0))),""),4),"1",""), "") | U7: =IFERROR( SUBSTITUTE(ADDRESS(1, IFERROR(COLUMN(INDEX(INDIRECT("数出表_Excel!B"&$I7&":T"&$I7&""),1,MATCH(TEXT(G7,0),INDIRECT("数出表_Excel!B"&$I7&":T"&$I7&""),0))),""),4),"1",""), "") | V7: =TRIM(SUBSTITUTE( IF(COUNTIF(P7:U7,"A")>0,"A ","")& IF(COUNTIF(P7:U7,"B")>0,"B ","")& IF(COUNTIF(P7:U7,"C")>0,"C ","")& IF(COUNTIF(P7:U7,"D")>0,"D ","")& IF(COUNTIF(P7:U7,"E")>0,"E ","")& IF(COUNTIF(P7:U7,"F")>0,"F ","")& IF(COUNTIF(P7:U7,"G")>0,"G ","")& IF(COUNTIF(P7:U7,"H")>0,"H ","")& IF(COUNTIF(P7:U7,"I")>0,"I ","")& IF(COUNTIF(P7:U7,"J")>0,"J ","")& IF(COUNTIF(P7:U7,"K")>0,"K ","")& IF(COUNTIF(P7:U7,"L")>0,"L ","")& IF(COUNTIF(P7:U7,"M")>0,"M ","")& IF(COUNTIF(P7:U7,"N")>0,"N ","")& IF(COUNTIF(P7:U7,"O")>0,"O ","")& IF(COUNTIF(P7:U7,"P")>0,"P ","")& IF(COUNTIF(P7:U7,"Q")>0,"Q ","")& IF(COUNTIF(P7:U7,"R")>0,"R ","")& IF(COUNTIF(P7:U7,"S")>0,"S ","")& IF(COUNTIF(P7:U7,"T")>0,"T ","")& IF(COUNTIF(P7:U7,"U")>0,"U ","")& IF(COUNTIF(P7:U7,"V")>0,"V ","")& IF(COUNTIF(P7:U7,"W")>0,"W ","")& IF(COUNTIF(P7:U7,"X")>0,"X ","")& IF(COUNTIF(P7:U7,"Y")>0,"Y ","")& IF(COUNTIF(P7:U7,"Z")>0,"Z ","")," ",",")) -> D,
A8: 博多中央 週3ｺｰｽ | B8: 139 | E8: 20 | I8: =I7+2 -> 21 | J8: {=IFERROR(IF(OR(COUNTIF(INDIRECT("数出表_Excel!"&P8&"3"),"*キャラ*"), COUNTIF(INDIRECT("数出表_Excel!"&P8&"3"),"*赤*")), IF(COUNTIF(A8,"*雙葉*"),INDIRECT("数出表_Excel!"&P8&"3"), INDIRECT("数出表_Excel!"&P8&"3") &" "&INDIRECT("数出表_Excel!"&P8&"4") &INDIRECT("数出表_Excel!"&P8&"5")), INDIRECT("数出表_Excel!"&P8&"3")),"")} -> キャラ弁当 飯なし | K8: {=IFERROR(IF(OR(COUNTIF(INDIRECT("数出表_Excel!"&Q8&"3"),"*キャラ*"), COUNTIF(INDIRECT("数出表_Excel!"&Q8&"3"),"*赤*")), INDIRECT("数出表_Excel!"&Q8&"3") &" "&INDIRECT("数出表_Excel!"&Q8&"4") &INDIRECT("数出表_Excel!"&Q8&"5"), INDIRECT("数出表_Excel!"&Q8&"3")),"")} | L8: {=IFERROR(IF(OR(COUNTIF(INDIRECT("数出表_Excel!"&R8&"3"),"*キャラ*"), COUNTIF(INDIRECT("数出表_Excel!"&R8&"3"),"*赤*")), INDIRECT("数出表_Excel!"&R8&"3") &" "&INDIRECT("数出表_Excel!"&R8&"4") &INDIRECT("数出表_Excel!"&R8&"5"), INDIRECT("数出表_Excel!"&R8&"3")),"")} | M8: {=IFERROR(IF(OR(COUNTIF(INDIRECT("数出表_Excel!"&S8&"3"),"*キャラ*"), COUNTIF(INDIRECT("数出表_Excel!"&S8&"3"),"*赤*")), INDIRECT("数出表_Excel!"&S8&"3") &" "&INDIRECT("数出表_Excel!"&S8&"4") &INDIRECT("数出表_Excel!"&S8&"5"), INDIRECT("数出表_Excel!"&S8&"3")),"")} -> キャラ弁当 飯なし | N8: {=IFERROR(IF(OR(COUNTIF(INDIRECT("数出表_Excel!"&T8&"3"),"*キャラ*"), COUNTIF(INDIRECT("数出表_Excel!"&T8&"3"),"*赤*")), INDIRECT("数出表_Excel!"&T8&"3") &" "&INDIRECT("数出表_Excel!"&T8&"4") &INDIRECT("数出表_Excel!"&T8&"5"), INDIRECT("数出表_Excel!"&T8&"3")),"")} | O8: {=IFERROR(IF(OR(COUNTIF(INDIRECT("数出表_Excel!"&U8&"3"),"*キャラ*"), COUNTIF(INDIRECT("数出表_Excel!"&U8&"3"),"*赤*")), INDIRECT("数出表_Excel!"&U8&"3") &" "&INDIRECT("数出表_Excel!"&U8&"4") &INDIRECT("数出表_Excel!"&U8&"5"), INDIRECT("数出表_Excel!"&U8&"3")),"")} | P8: =IFERROR( SUBSTITUTE(ADDRESS(1, IFERROR(COLUMN(INDEX(INDIRECT("数出表_Excel!B"&$I8-1&":T"&$I8-1&""),1,MATCH(TEXT(B8,0),INDIRECT("数出表_Excel!B"&$I8-1&":T"&$I8-1&""),0))),""),4),"1",""), "") -> F | Q8: =IFERROR( SUBSTITUTE(ADDRESS(1, IFERROR(COLUMN(INDEX(INDIRECT("数出表_Excel!B"&$I8-1&":T"&$I8-1&""),1,MATCH(TEXT(C8,0),INDIRECT("数出表_Excel!B"&$I8-1&":T"&$I8-1&""),0))),""),4),"1",""), "") | R8: =IFERROR( SUBSTITUTE(ADDRESS(1, IFERROR(COLUMN(INDEX(INDIRECT("数出表_Excel!B"&$I8-1&":T"&$I8-1&""),1,MATCH(TEXT(D8,0),INDIRECT("数出表_Excel!B"&$I8-1&":T"&$I8-1&""),0))),""),4),"1",""), "") | S8: =IFERROR( SUBSTITUTE(ADDRESS(1, IFERROR(COLUMN(INDEX(INDIRECT("数出表_Excel!B"&$I8&":T"&$I8&""),1,MATCH(TEXT(E8,0),INDIRECT("数出表_Excel!B"&$I8&":T"&$I8&""),0))),""),4),"1",""), "") -> F | T8: =IFERROR( SUBSTITUTE(ADDRESS(1, IFERROR(COLUMN(INDEX(INDIRECT("数出表_Excel!B"&$I8&":T"&$I8&""),1,MATCH(TEXT(F8,0),INDIRECT("数出表_Excel!B"&$I8&":T"&$I8&""),0))),""),4),"1",""), "") | U8: =IFERROR( SUBSTITUTE(ADDRESS(1, IFERROR(COLUMN(INDEX(INDIRECT("数出表_Excel!B"&$I8&":T"&$I8&""),1,MATCH(TEXT(G8,0),INDIRECT("数出表_Excel!B"&$I8&":T"&$I8&""),0))),""),4),"1",""), "") | V8: =TRIM(SUBSTITUTE( IF(COUNTIF(P8:U8,"A")>0,"A ","")& IF(COUNTIF(P8:U8,"B")>0,"B ","")& IF(COUNTIF(P8:U8,"C")>0,"C ","")& IF(COUNTIF(P8:U8,"D")>0,"D ","")& IF(COUNTIF(P8:U8,"E")>0,"E ","")& IF(COUNTIF(P8:U8,"F")>0,"F ","")& IF(COUNTIF(P8:U8,"G")>0,"G ","")& IF(COUNTIF(P8:U8,"H")>0,"H ","")& IF(COUNTIF(P8:U8,"I")>0,"I ","")& IF(COUNTIF(P8:U8,"J")>0,"J ","")& IF(COUNTIF(P8:U8,"K")>0,"K ","")& IF(COUNTIF(P8:U8,"L")>0,"L ","")& IF(COUNTIF(P8:U8,"M")>0,"M ","")& IF(COUNTIF(P8:U8,"N")>0,"N ","")& IF(COUNTIF(P8:U8,"O")>0,"O ","")& IF(COUNTIF(P8:U8,"P")>0,"P ","")& IF(COUNTIF(P8:U8,"Q")>0,"Q ","")& IF(COUNTIF(P8:U8,"R")>0,"R ","")& IF(COUNTIF(P8:U8,"S")>0,"S ","")& IF(COUNTIF(P8:U8,"T")>0,"T ","")& IF(COUNTIF(P8:U8,"U")>0,"U ","")& IF(COUNTIF(P8:U8,"V")>0,"V ","")& IF(COUNTIF(P8:U8,"W")>0,"W ","")& IF(COUNTIF(P8:U8,"X")>0,"X ","")& IF(COUNTIF(P8:U8,"Y")>0,"Y ","")& IF(COUNTIF(P8:U8,"Z")>0,"Z ","")," ",",")) -> F,
A9: 博多中央 週5ｺｰｽ | B9: 179 | I9: =I8+2 -> 23 | J9: {=IFERROR(IF(OR(COUNTIF(INDIRECT("数出表_Excel!"&P9&"3"),"*キャラ*"), COUNTIF(INDIRECT("数出表_Excel!"&P9&"3"),"*赤*")), IF(COUNTIF(A9,"*雙葉*"),INDIRECT("数出表_Excel!"&P9&"3"), INDIRECT("数出表_Excel!"&P9&"3") &" "&INDIRECT("数出表_Excel!"&P9&"4") &INDIRECT("数出表_Excel!"&P9&"5")), INDIRECT("数出表_Excel!"&P9&"3")),"")} -> キャラ弁当 飯なし | K9: {=IFERROR(IF(OR(COUNTIF(INDIRECT("数出表_Excel!"&Q9&"3"),"*キャラ*"), COUNTIF(INDIRECT("数出表_Excel!"&Q9&"3"),"*赤*")), INDIRECT("数出表_Excel!"&Q9&"3") &" "&INDIRECT("数出表_Excel!"&Q9&"4") &INDIRECT("数出表_Excel!"&Q9&"5"), INDIRECT("数出表_Excel!"&Q9&"3")),"")} | L9: {=IFERROR(IF(OR(COUNTIF(INDIRECT("数出表_Excel!"&R9&"3"),"*キャラ*"), COUNTIF(INDIRECT("数出表_Excel!"&R9&"3"),"*赤*")), INDIRECT("数出表_Excel!"&R9&"3") &" "&INDIRECT("数出表_Excel!"&R9&"4") &INDIRECT("数出表_Excel!"&R9&"5"), INDIRECT("数出表_Excel!"&R9&"3")),"")} | M9: {=IFERROR(IF(OR(COUNTIF(INDIRECT("数出表_Excel!"&S9&"3"),"*キャラ*"), COUNTIF(INDIRECT("数出表_Excel!"&S9&"3"),"*赤*")), INDIRECT("数出表_Excel!"&S9&"3") &" "&INDIRECT("数出表_Excel!"&S9&"4") &INDIRECT("数出表_Excel!"&S9&"5"), INDIRECT("数出表_Excel!"&S9&"3")),"")} | N9: {=IFERROR(IF(OR(COUNTIF(INDIRECT("数出表_Excel!"&T9&"3"),"*キャラ*"), COUNTIF(INDIRECT("数出表_Excel!"&T9&"3"),"*赤*")), INDIRECT("数出表_Excel!"&T9&"3") &" "&INDIRECT("数出表_Excel!"&T9&"4") &INDIRECT("数出表_Excel!"&T9&"5"), INDIRECT("数出表_Excel!"&T9&"3")),"")} | O9: {=IFERROR(IF(OR(COUNTIF(INDIRECT("数出表_Excel!"&U9&"3"),"*キャラ*"), COUNTIF(INDIRECT("数出表_Excel!"&U9&"3"),"*赤*")), INDIRECT("数出表_Excel!"&U9&"3") &" "&INDIRECT("数出表_Excel!"&U9&"4") &INDIRECT("数出表_Excel!"&U9&"5"), INDIRECT("数出表_Excel!"&U9&"3")),"")} | P9: =IFERROR( SUBSTITUTE(ADDRESS(1, IFERROR(COLUMN(INDEX(INDIRECT("数出表_Excel!B"&$I9-1&":T"&$I9-1&""),1,MATCH(TEXT(B9,0),INDIRECT("数出表_Excel!B"&$I9-1&":T"&$I9-1&""),0))),""),4),"1",""), "") -> F | Q9: =IFERROR( SUBSTITUTE(ADDRESS(1, IFERROR(COLUMN(INDEX(INDIRECT("数出表_Excel!B"&$I9-1&":T"&$I9-1&""),1,MATCH(TEXT(C9,0),INDIRECT("数出表_Excel!B"&$I9-1&":T"&$I9-1&""),0))),""),4),"1",""), "") | R9: =IFERROR( SUBSTITUTE(ADDRESS(1, IFERROR(COLUMN(INDEX(INDIRECT("数出表_Excel!B"&$I9-1&":T"&$I9-1&""),1,MATCH(TEXT(D9,0),INDIRECT("数出表_Excel!B"&$I9-1&":T"&$I9-1&""),0))),""),4),"1",""), "") | S9: =IFERROR( SUBSTITUTE(ADDRESS(1, IFERROR(COLUMN(INDEX(INDIRECT("数出表_Excel!B"&$I9&":T"&$I9&""),1,MATCH(TEXT(E9,0),INDIRECT("数出表_Excel!B"&$I9&":T"&$I9&""),0))),""),4),"1",""), "") | T9: =IFERROR( SUBSTITUTE(ADDRESS(1, IFERROR(COLUMN(INDEX(INDIRECT("数出表_Excel!B"&$I9&":T"&$I9&""),1,MATCH(TEXT(F9,0),INDIRECT("数出表_Excel!B"&$I9&":T"&$I9&""),0))),""),4),"1",""), "") | U9: =IFERROR( SUBSTITUTE(ADDRESS(1, IFERROR(COLUMN(INDEX(INDIRECT("数出表_Excel!B"&$I9&":T"&$I9&""),1,MATCH(TEXT(G9,0),INDIRECT("数出表_Excel!B"&$I9&":T"&$I9&""),0))),""),4),"1",""), "") | V9: =TRIM(SUBSTITUTE( IF(COUNTIF(P9:U9,"A")>0,"A ","")& IF(COUNTIF(P9:U9,"B")>0,"B ","")& IF(COUNTIF(P9:U9,"C")>0,"C ","")& IF(COUNTIF(P9:U9,"D")>0,"D ","")& IF(COUNTIF(P9:U9,"E")>0,"E ","")& IF(COUNTIF(P9:U9,"F")>0,"F ","")& IF(COUNTIF(P9:U9,"G")>0,"G ","")& IF(COUNTIF(P9:U9,"H")>0,"H ","")& IF(COUNTIF(P9:U9,"I")>0,"I ","")& IF(COUNTIF(P9:U9,"J")>0,"J ","")& IF(COUNTIF(P9:U9,"K")>0,"K ","")& IF(COUNTIF(P9:U9,"L")>0,"L ","")& IF(COUNTIF(P9:U9,"M")>0,"M ","")& IF(COUNTIF(P9:U9,"N")>0,"N ","")& IF(COUNTIF(P9:U9,"O")>0,"O ","")& IF(COUNTIF(P9:U9,"P")>0,"P ","")& IF(COUNTIF(P9:U9,"Q")>0,"Q ","")& IF(COUNTIF(P9:U9,"R")>0,"R ","")& IF(COUNTIF(P9:U9,"S")>0,"S ","")& IF(COUNTIF(P9:U9,"T")>0,"T ","")& IF(COUNTIF(P9:U9,"U")>0,"U ","")& IF(COUNTIF(P9:U9,"V")>0,"V ","")& IF(COUNTIF(P9:U9,"W")>0,"W ","")& IF(COUNTIF(P9:U9,"X")>0,"X ","")& IF(COUNTIF(P9:U9,"Y")>0,"Y ","")& IF(COUNTIF(P9:U9,"Z")>0,"Z ","")," ",",")) -> F,
A10: 博多中央（補助教員） web | E10: 5 | I10: =I9+2 -> 25 | J10: {=IFERROR(IF(OR(COUNTIF(INDIRECT("数出表_Excel!"&P10&"3"),"*キャラ*"), COUNTIF(INDIRECT("数出表_Excel!"&P10&"3"),"*赤*")), IF(COUNTIF(A10,"*雙葉*"),INDIRECT("数出表_Excel!"&P10&"3"), INDIRECT("数出表_Excel!"&P10&"3") &" "&INDIRECT("数出表_Excel!"&P10&"4") &INDIRECT("数出表_Excel!"&P10&"5")), INDIRECT("数出表_Excel!"&P10&"3")),"")} | K10: {=IFERROR(IF(OR(COUNTIF(INDIRECT("数出表_Excel!"&Q10&"3"),"*キャラ*"), COUNTIF(INDIRECT("数出表_Excel!"&Q10&"3"),"*赤*")), INDIRECT("数出表_Excel!"&Q10&"3") &" "&INDIRECT("数出表_Excel!"&Q10&"4") &INDIRECT("数出表_Excel!"&Q10&"5"), INDIRECT("数出表_Excel!"&Q10&"3")),"")} | L10: {=IFERROR(IF(OR(COUNTIF(INDIRECT("数出表_Excel!"&R10&"3"),"*キャラ*"), COUNTIF(INDIRECT("数出表_Excel!"&R10&"3"),"*赤*")), INDIRECT("数出表_Excel!"&R10&"3") &" "&INDIRECT("数出表_Excel!"&R10&"4") &INDIRECT("数出表_Excel!"&R10&"5"), INDIRECT("数出表_Excel!"&R10&"3")),"")} | M10: {=IFERROR(IF(OR(COUNTIF(INDIRECT("数出表_Excel!"&S10&"3"),"*キャラ*"), COUNTIF(INDIRECT("数出表_Excel!"&S10&"3"),"*赤*")), INDIRECT("数出表_Excel!"&S10&"3") &" "&INDIRECT("数出表_Excel!"&S10&"4") &INDIRECT("数出表_Excel!"&S10&"5"), INDIRECT("数出表_Excel!"&S10&"3")),"")} -> キャラ弁当 飯あり120 | N10: {=IFERROR(IF(OR(COUNTIF(INDIRECT("数出表_Excel!"&T10&"3"),"*キャラ*"), COUNTIF(INDIRECT("数出表_Excel!"&T10&"3"),"*赤*")), INDIRECT("数出表_Excel!"&T10&"3") &" "&INDIRECT("数出表_Excel!"&T10&"4") &INDIRECT("数出表_Excel!"&T10&"5"), INDIRECT("数出表_Excel!"&T10&"3")),"")} | O10: {=IFERROR(IF(OR(COUNTIF(INDIRECT("数出表_Excel!"&U10&"3"),"*キャラ*"), COUNTIF(INDIRECT("数出表_Excel!"&U10&"3"),"*赤*")), INDIRECT("数出表_Excel!"&U10&"3") &" "&INDIRECT("数出表_Excel!"&U10&"4") &INDIRECT("数出表_Excel!"&U10&"5"), INDIRECT("数出表_Excel!"&U10&"3")),"")} | P10: =IFERROR( SUBSTITUTE(ADDRESS(1, IFERROR(COLUMN(INDEX(INDIRECT("数出表_Excel!B"&$I10-1&":T"&$I10-1&""),1,MATCH(TEXT(B10,0),INDIRECT("数出表_Excel!B"&$I10-1&":T"&$I10-1&""),0))),""),4),"1",""), "") | Q10: =IFERROR( SUBSTITUTE(ADDRESS(1, IFERROR(COLUMN(INDEX(INDIRECT("数出表_Excel!B"&$I10-1&":T"&$I10-1&""),1,MATCH(TEXT(C10,0),INDIRECT("数出表_Excel!B"&$I10-1&":T"&$I10-1&""),0))),""),4),"1",""), "") | R10: =IFERROR( SUBSTITUTE(ADDRESS(1, IFERROR(COLUMN(INDEX(INDIRECT("数出表_Excel!B"&$I10-1&":T"&$I10-1&""),1,MATCH(TEXT(D10,0),INDIRECT("数出表_Excel!B"&$I10-1&":T"&$I10-1&""),0))),""),4),"1",""), "") | S10: =IFERROR( SUBSTITUTE(ADDRESS(1, IFERROR(COLUMN(INDEX(INDIRECT("数出表_Excel!B"&$I10&":T"&$I10&""),1,MATCH(TEXT(E10,0),INDIRECT("数出表_Excel!B"&$I10&":T"&$I10&""),0))),""),4),"1",""), "") -> D | T10: =IFERROR( SUBSTITUTE(ADDRESS(1, IFERROR(COLUMN(INDEX(INDIRECT("数出表_Excel!B"&$I10&":T"&$I10&""),1,MATCH(TEXT(F10,0),INDIRECT("数出表_Excel!B"&$I10&":T"&$I10&""),0))),""),4),"1",""), "") | U10: =IFERROR( SUBSTITUTE(ADDRESS(1, IFERROR(COLUMN(INDEX(INDIRECT("数出表_Excel!B"&$I10&":T"&$I10&""),1,MATCH(TEXT(G10,0),INDIRECT("数出表_Excel!B"&$I10&":T"&$I10&""),0))),""),4),"1",""), "") | V10: =TRIM(SUBSTITUTE( IF(COUNTIF(P10:U10,"A")>0,"A ","")& IF(COUNTIF(P10:U10,"B")>0,"B ","")& IF(COUNTIF(P10:U10,"C")>0,"C ","")& IF(COUNTIF(P10:U10,"D")>0,"D ","")& IF(COUNTIF(P10:U10,"E")>0,"E ","")& IF(COUNTIF(P10:U10,"F")>0,"F ","")& IF(COUNTIF(P10:U10,"G")>0,"G ","")& IF(COUNTIF(P10:U10,"H")>0,"H ","")& IF(COUNTIF(P10:U10,"I")>0,"I ","")& IF(COUNTIF(P10:U10,"J")>0,"J ","")& IF(COUNTIF(P10:U10,"K")>0,"K ","")& IF(COUNTIF(P10:U10,"L")>0,"L ","")& IF(COUNTIF(P10:U10,"M")>0,"M ","")& IF(COUNTIF(P10:U10,"N")>0,"N ","")& IF(COUNTIF(P10:U10,"O")>0,"O ","")& IF(COUNTIF(P10:U10,"P")>0,"P ","")& IF(COUNTIF(P10:U10,"Q")>0,"Q ","")& IF(COUNTIF(P10:U10,"R")>0,"R ","")& IF(COUNTIF(P10:U10,"S")>0,"S ","")& IF(COUNTIF(P10:U10,"T")>0,"T ","")& IF(COUNTIF(P10:U10,"U")>0,"U ","")& IF(COUNTIF(P10:U10,"V")>0,"V ","")& IF(COUNTIF(P10:U10,"W")>0,"W ","")& IF(COUNTIF(P10:U10,"X")>0,"X ","")& IF(COUNTIF(P10:U10,"Y")>0,"Y ","")& IF(COUNTIF(P10:U10,"Z")>0,"Z ","")," ",",")) -> D,
A11: 博多 週3ｺｰｽ | B11: 69 | E11: 22 | I11: =I10+2 -> 27 | J11: {=IFERROR(IF(OR(COUNTIF(INDIRECT("数出表_Excel!"&P11&"3"),"*キャラ*"), COUNTIF(INDIRECT("数出表_Excel!"&P11&"3"),"*赤*")), IF(COUNTIF(A11,"*雙葉*"),INDIRECT("数出表_Excel!"&P11&"3"), INDIRECT("数出表_Excel!"&P11&"3") &" "&INDIRECT("数出表_Excel!"&P11&"4") &INDIRECT("数出表_Excel!"&P11&"5")), INDIRECT("数出表_Excel!"&P11&"3")),"")} -> キャラ弁当 飯なし | K11: {=IFERROR(IF(OR(COUNTIF(INDIRECT("数出表_Excel!"&Q11&"3"),"*キャラ*"), COUNTIF(INDIRECT("数出表_Excel!"&Q11&"3"),"*赤*")), INDIRECT("数出表_Excel!"&Q11&"3") &" "&INDIRECT("数出表_Excel!"&Q11&"4") &INDIRECT("数出表_Excel!"&Q11&"5"), INDIRECT("数出表_Excel!"&Q11&"3")),"")} | L11: {=IFERROR(IF(OR(COUNTIF(INDIRECT("数出表_Excel!"&R11&"3"),"*キャラ*"), COUNTIF(INDIRECT("数出表_Excel!"&R11&"3"),"*赤*")), INDIRECT("数出表_Excel!"&R11&"3") &" "&INDIRECT("数出表_Excel!"&R11&"4") &INDIRECT("数出表_Excel!"&R11&"5"), INDIRECT("数出表_Excel!"&R11&"3")),"")} | M11: {=IFERROR(IF(OR(COUNTIF(INDIRECT("数出表_Excel!"&S11&"3"),"*キャラ*"), COUNTIF(INDIRECT("数出表_Excel!"&S11&"3"),"*赤*")), INDIRECT("数出表_Excel!"&S11&"3") &" "&INDIRECT("数出表_Excel!"&S11&"4") &INDIRECT("数出表_Excel!"&S11&"5"), INDIRECT("数出表_Excel!"&S11&"3")),"")} -> キャラ弁当 飯なし | N11: {=IFERROR(IF(OR(COUNTIF(INDIRECT("数出表_Excel!"&T11&"3"),"*キャラ*"), COUNTIF(INDIRECT("数出表_Excel!"&T11&"3"),"*赤*")), INDIRECT("数出表_Excel!"&T11&"3") &" "&INDIRECT("数出表_Excel!"&T11&"4") &INDIRECT("数出表_Excel!"&T11&"5"), INDIRECT("数出表_Excel!"&T11&"3")),"")} | O11: {=IFERROR(IF(OR(COUNTIF(INDIRECT("数出表_Excel!"&U11&"3"),"*キャラ*"), COUNTIF(INDIRECT("数出表_Excel!"&U11&"3"),"*赤*")), INDIRECT("数出表_Excel!"&U11&"3") &" "&INDIRECT("数出表_Excel!"&U11&"4") &INDIRECT("数出表_Excel!"&U11&"5"), INDIRECT("数出表_Excel!"&U11&"3")),"")} | P11: =IFERROR( SUBSTITUTE(ADDRESS(1, IFERROR(COLUMN(INDEX(INDIRECT("数出表_Excel!B"&$I11-1&":T"&$I11-1&""),1,MATCH(TEXT(B11,0),INDIRECT("数出表_Excel!B"&$I11-1&":T"&$I11-1&""),0))),""),4),"1",""), "") -> F | Q11: =IFERROR( SUBSTITUTE(ADDRESS(1, IFERROR(COLUMN(INDEX(INDIRECT("数出表_Excel!B"&$I11-1&":T"&$I11-1&""),1,MATCH(TEXT(C11,0),INDIRECT("数出表_Excel!B"&$I11-1&":T"&$I11-1&""),0))),""),4),"1",""), "") | R11: =IFERROR( SUBSTITUTE(ADDRESS(1, IFERROR(COLUMN(INDEX(INDIRECT("数出表_Excel!B"&$I11-1&":T"&$I11-1&""),1,MATCH(TEXT(D11,0),INDIRECT("数出表_Excel!B"&$I11-1&":T"&$I11-1&""),0))),""),4),"1",""), "") | S11: =IFERROR( SUBSTITUTE(ADDRESS(1, IFERROR(COLUMN(INDEX(INDIRECT("数出表_Excel!B"&$I11&":T"&$I11&""),1,MATCH(TEXT(E11,0),INDIRECT("数出表_Excel!B"&$I11&":T"&$I11&""),0))),""),4),"1",""), "") -> F | T11: =IFERROR( SUBSTITUTE(ADDRESS(1, IFERROR(COLUMN(INDEX(INDIRECT("数出表_Excel!B"&$I11&":T"&$I11&""),1,MATCH(TEXT(F11,0),INDIRECT("数出表_Excel!B"&$I11&":T"&$I11&""),0))),""),4),"1",""), "") | U11: =IFERROR( SUBSTITUTE(ADDRESS(1, IFERROR(COLUMN(INDEX(INDIRECT("数出表_Excel!B"&$I11&":T"&$I11&""),1,MATCH(TEXT(G11,0),INDIRECT("数出表_Excel!B"&$I11&":T"&$I11&""),0))),""),4),"1",""), "") | V11: =TRIM(SUBSTITUTE( IF(COUNTIF(P11:U11,"A")>0,"A ","")& IF(COUNTIF(P11:U11,"B")>0,"B ","")& IF(COUNTIF(P11:U11,"C")>0,"C ","")& IF(COUNTIF(P11:U11,"D")>0,"D ","")& IF(COUNTIF(P11:U11,"E")>0,"E ","")& IF(COUNTIF(P11:U11,"F")>0,"F ","")& IF(COUNTIF(P11:U11,"G")>0,"G ","")& IF(COUNTIF(P11:U11,"H")>0,"H ","")& IF(COUNTIF(P11:U11,"I")>0,"I ","")& IF(COUNTIF(P11:U11,"J")>0,"J ","")& IF(COUNTIF(P11:U11,"K")>0,"K ","")& IF(COUNTIF(P11:U11,"L")>0,"L ","")& IF(COUNTIF(P11:U11,"M")>0,"M ","")& IF(COUNTIF(P11:U11,"N")>0,"N ","")& IF(COUNTIF(P11:U11,"O")>0,"O ","")& IF(COUNTIF(P11:U11,"P")>0,"P ","")& IF(COUNTIF(P11:U11,"Q")>0,"Q ","")& IF(COUNTIF(P11:U11,"R")>0,"R ","")& IF(COUNTIF(P11:U11,"S")>0,"S ","")& IF(COUNTIF(P11:U11,"T")>0,"T ","")& IF(COUNTIF(P11:U11,"U")>0,"U ","")& IF(COUNTIF(P11:U11,"V")>0,"V ","")& IF(COUNTIF(P11:U11,"W")>0,"W ","")& IF(COUNTIF(P11:U11,"X")>0,"X ","")& IF(COUNTIF(P11:U11,"Y")>0,"Y ","")& IF(COUNTIF(P11:U11,"Z")>0,"Z ","")," ",",")) -> F,
A12: 博多 週5ｺｰｽ | B12: 360 | I12: =I11+2 -> 29 | J12: {=IFERROR(IF(OR(COUNTIF(INDIRECT("数出表_Excel!"&P12&"3"),"*キャラ*"), COUNTIF(INDIRECT("数出表_Excel!"&P12&"3"),"*赤*")), IF(COUNTIF(A12,"*雙葉*"),INDIRECT("数出表_Excel!"&P12&"3"), INDIRECT("数出表_Excel!"&P12&"3") &" "&INDIRECT("数出表_Excel!"&P12&"4") &INDIRECT("数出表_Excel!"&P12&"5")), INDIRECT("数出表_Excel!"&P12&"3")),"")} -> キャラ弁当 飯なし | K12: {=IFERROR(IF(OR(COUNTIF(INDIRECT("数出表_Excel!"&Q12&"3"),"*キャラ*"), COUNTIF(INDIRECT("数出表_Excel!"&Q12&"3"),"*赤*")), INDIRECT("数出表_Excel!"&Q12&"3") &" "&INDIRECT("数出表_Excel!"&Q12&"4") &INDIRECT("数出表_Excel!"&Q12&"5"), INDIRECT("数出表_Excel!"&Q12&"3")),"")} | L12: {=IFERROR(IF(OR(COUNTIF(INDIRECT("数出表_Excel!"&R12&"3"),"*キャラ*"), COUNTIF(INDIRECT("数出表_Excel!"&R12&"3"),"*赤*")), INDIRECT("数出表_Excel!"&R12&"3") &" "&INDIRECT("数出表_Excel!"&R12&"4") &INDIRECT("数出表_Excel!"&R12&"5"), INDIRECT("数出表_Excel!"&R12&"3")),"")} | M12: {=IFERROR(IF(OR(COUNTIF(INDIRECT("数出表_Excel!"&S12&"3"),"*キャラ*"), COUNTIF(INDIRECT("数出表_Excel!"&S12&"3"),"*赤*")), INDIRECT("数出表_Excel!"&S12&"3") &" "&INDIRECT("数出表_Excel!"&S12&"4") &INDIRECT("数出表_Excel!"&S12&"5"), INDIRECT("数出表_Excel!"&S12&"3")),"")} | N12: {=IFERROR(IF(OR(COUNTIF(INDIRECT("数出表_Excel!"&T12&"3"),"*キャラ*"), COUNTIF(INDIRECT("数出表_Excel!"&T12&"3"),"*赤*")), INDIRECT("数出表_Excel!"&T12&"3") &" "&INDIRECT("数出表_Excel!"&T12&"4") &INDIRECT("数出表_Excel!"&T12&"5"), INDIRECT("数出表_Excel!"&T12&"3")),"")} | O12: {=IFERROR(IF(OR(COUNTIF(INDIRECT("数出表_Excel!"&U12&"3"),"*キャラ*"), COUNTIF(INDIRECT("数出表_Excel!"&U12&"3"),"*赤*")), INDIRECT("数出表_Excel!"&U12&"3") &" "&INDIRECT("数出表_Excel!"&U12&"4") &INDIRECT("数出表_Excel!"&U12&"5"), INDIRECT("数出表_Excel!"&U12&"3")),"")} | P12: =IFERROR( SUBSTITUTE(ADDRESS(1, IFERROR(COLUMN(INDEX(INDIRECT("数出表_Excel!B"&$I12-1&":T"&$I12-1&""),1,MATCH(TEXT(B12,0),INDIRECT("数出表_Excel!B"&$I12-1&":T"&$I12-1&""),0))),""),4),"1",""), "") -> F | Q12: =IFERROR( SUBSTITUTE(ADDRESS(1, IFERROR(COLUMN(INDEX(INDIRECT("数出表_Excel!B"&$I12-1&":T"&$I12-1&""),1,MATCH(TEXT(C12,0),INDIRECT("数出表_Excel!B"&$I12-1&":T"&$I12-1&""),0))),""),4),"1",""), "") | R12: =IFERROR( SUBSTITUTE(ADDRESS(1, IFERROR(COLUMN(INDEX(INDIRECT("数出表_Excel!B"&$I12-1&":T"&$I12-1&""),1,MATCH(TEXT(D12,0),INDIRECT("数出表_Excel!B"&$I12-1&":T"&$I12-1&""),0))),""),4),"1",""), "") | S12: =IFERROR( SUBSTITUTE(ADDRESS(1, IFERROR(COLUMN(INDEX(INDIRECT("数出表_Excel!B"&$I12&":T"&$I12&""),1,MATCH(TEXT(E12,0),INDIRECT("数出表_Excel!B"&$I12&":T"&$I12&""),0))),""),4),"1",""), "") | T12: =IFERROR( SUBSTITUTE(ADDRESS(1, IFERROR(COLUMN(INDEX(INDIRECT("数出表_Excel!B"&$I12&":T"&$I12&""),1,MATCH(TEXT(F12,0),INDIRECT("数出表_Excel!B"&$I12&":T"&$I12&""),0))),""),4),"1",""), "") | U12: =IFERROR( SUBSTITUTE(ADDRESS(1, IFERROR(COLUMN(INDEX(INDIRECT("数出表_Excel!B"&$I12&":T"&$I12&""),1,MATCH(TEXT(G12,0),INDIRECT("数出表_Excel!B"&$I12&":T"&$I12&""),0))),""),4),"1",""), "") | V12: =TRIM(SUBSTITUTE( IF(COUNTIF(P12:U12,"A")>0,"A ","")& IF(COUNTIF(P12:U12,"B")>0,"B ","")& IF(COUNTIF(P12:U12,"C")>0,"C ","")& IF(COUNTIF(P12:U12,"D")>0,"D ","")& IF(COUNTIF(P12:U12,"E")>0,"E ","")& IF(COUNTIF(P12:U12,"F")>0,"F ","")& IF(COUNTIF(P12:U12,"G")>0,"G ","")& IF(COUNTIF(P12:U12,"H")>0,"H ","")& IF(COUNTIF(P12:U12,"I")>0,"I ","")& IF(COUNTIF(P12:U12,"J")>0,"J ","")& IF(COUNTIF(P12:U12,"K")>0,"K ","")& IF(COUNTIF(P12:U12,"L")>0,"L ","")& IF(COUNTIF(P12:U12,"M")>0,"M ","")& IF(COUNTIF(P12:U12,"N")>0,"N ","")& IF(COUNTIF(P12:U12,"O")>0,"O ","")& IF(COUNTIF(P12:U12,"P")>0,"P ","")& IF(COUNTIF(P12:U12,"Q")>0,"Q ","")& IF(COUNTIF(P12:U12,"R")>0,"R ","")& IF(COUNTIF(P12:U12,"S")>0,"S ","")& IF(COUNTIF(P12:U12,"T")>0,"T ","")& IF(COUNTIF(P12:U12,"U")>0,"U ","")& IF(COUNTIF(P12:U12,"V")>0,"V ","")& IF(COUNTIF(P12:U12,"W")>0,"W ","")& IF(COUNTIF(P12:U12,"X")>0,"X ","")& IF(COUNTIF(P12:U12,"Y")>0,"Y ","")& IF(COUNTIF(P12:U12,"Z")>0,"Z ","")," ",",")) -> F,
A13: 博多（補助教員） web | E13: 13 | I13: =I12+2 -> 31 | J13: {=IFERROR(IF(OR(COUNTIF(INDIRECT("数出表_Excel!"&P13&"3"),"*キャラ*"), COUNTIF(INDIRECT("数出表_Excel!"&P13&"3"),"*赤*")), IF(COUNTIF(A13,"*雙葉*"),INDIRECT("数出表_Excel!"&P13&"3"), INDIRECT("数出表_Excel!"&P13&"3") &" "&INDIRECT("数出表_Excel!"&P13&"4") &INDIRECT("数出表_Excel!"&P13&"5")), INDIRECT("数出表_Excel!"&P13&"3")),"")} | K13: {=IFERROR(IF(OR(COUNTIF(INDIRECT("数出表_Excel!"&Q13&"3"),"*キャラ*"), COUNTIF(INDIRECT("数出表_Excel!"&Q13&"3"),"*赤*")), INDIRECT("数出表_Excel!"&Q13&"3") &" "&INDIRECT("数出表_Excel!"&Q13&"4") &INDIRECT("数出表_Excel!"&Q13&"5"), INDIRECT("数出表_Excel!"&Q13&"3")),"")} | L13: {=IFERROR(IF(OR(COUNTIF(INDIRECT("数出表_Excel!"&R13&"3"),"*キャラ*"), COUNTIF(INDIRECT("数出表_Excel!"&R13&"3"),"*赤*")), INDIRECT("数出表_Excel!"&R13&"3") &" "&INDIRECT("数出表_Excel!"&R13&"4") &INDIRECT("数出表_Excel!"&R13&"5"), INDIRECT("数出表_Excel!"&R13&"3")),"")} | M13: {=IFERROR(IF(OR(COUNTIF(INDIRECT("数出表_Excel!"&S13&"3"),"*キャラ*"), COUNTIF(INDIRECT("数出表_Excel!"&S13&"3"),"*赤*")), INDIRECT("数出表_Excel!"&S13&"3") &" "&INDIRECT("数出表_Excel!"&S13&"4") &INDIRECT("数出表_Excel!"&S13&"5"), INDIRECT("数出表_Excel!"&S13&"3")),"")} -> キャラ弁当 飯あり120 | N13: {=IFERROR(IF(OR(COUNTIF(INDIRECT("数出表_Excel!"&T13&"3"),"*キャラ*"), COUNTIF(INDIRECT("数出表_Excel!"&T13&"3"),"*赤*")), INDIRECT("数出表_Excel!"&T13&"3") &" "&INDIRECT("数出表_Excel!"&T13&"4") &INDIRECT("数出表_Excel!"&T13&"5"), INDIRECT("数出表_Excel!"&T13&"3")),"")} | O13: {=IFERROR(IF(OR(COUNTIF(INDIRECT("数出表_Excel!"&U13&"3"),"*キャラ*"), COUNTIF(INDIRECT("数出表_Excel!"&U13&"3"),"*赤*")), INDIRECT("数出表_Excel!"&U13&"3") &" "&INDIRECT("数出表_Excel!"&U13&"4") &INDIRECT("数出表_Excel!"&U13&"5"), INDIRECT("数出表_Excel!"&U13&"3")),"")} | P13: =IFERROR( SUBSTITUTE(ADDRESS(1, IFERROR(COLUMN(INDEX(INDIRECT("数出表_Excel!B"&$I13-1&":T"&$I13-1&""),1,MATCH(TEXT(B13,0),INDIRECT("数出表_Excel!B"&$I13-1&":T"&$I13-1&""),0))),""),4),"1",""), "") | Q13: =IFERROR( SUBSTITUTE(ADDRESS(1, IFERROR(COLUMN(INDEX(INDIRECT("数出表_Excel!B"&$I13-1&":T"&$I13-1&""),1,MATCH(TEXT(C13,0),INDIRECT("数出表_Excel!B"&$I13-1&":T"&$I13-1&""),0))),""),4),"1",""), "") | R13: =IFERROR( SUBSTITUTE(ADDRESS(1, IFERROR(COLUMN(INDEX(INDIRECT("数出表_Excel!B"&$I13-1&":T"&$I13-1&""),1,MATCH(TEXT(D13,0),INDIRECT("数出表_Excel!B"&$I13-1&":T"&$I13-1&""),0))),""),4),"1",""), "") | S13: =IFERROR( SUBSTITUTE(ADDRESS(1, IFERROR(COLUMN(INDEX(INDIRECT("数出表_Excel!B"&$I13&":T"&$I13&""),1,MATCH(TEXT(E13,0),INDIRECT("数出表_Excel!B"&$I13&":T"&$I13&""),0))),""),4),"1",""), "") -> D | T13: =IFERROR( SUBSTITUTE(ADDRESS(1, IFERROR(COLUMN(INDEX(INDIRECT("数出表_Excel!B"&$I13&":T"&$I13&""),1,MATCH(TEXT(F13,0),INDIRECT("数出表_Excel!B"&$I13&":T"&$I13&""),0))),""),4),"1",""), "") | U13: =IFERROR( SUBSTITUTE(ADDRESS(1, IFERROR(COLUMN(INDEX(INDIRECT("数出表_Excel!B"&$I13&":T"&$I13&""),1,MATCH(TEXT(G13,0),INDIRECT("数出表_Excel!B"&$I13&":T"&$I13&""),0))),""),4),"1",""), "") | V13: =TRIM(SUBSTITUTE( IF(COUNTIF(P13:U13,"A")>0,"A ","")& IF(COUNTIF(P13:U13,"B")>0,"B ","")& IF(COUNTIF(P13:U13,"C")>0,"C ","")& IF(COUNTIF(P13:U13,"D")>0,"D ","")& IF(COUNTIF(P13:U13,"E")>0,"E ","")& IF(COUNTIF(P13:U13,"F")>0,"F ","")& IF(COUNTIF(P13:U13,"G")>0,"G ","")& IF(COUNTIF(P13:U13,"H")>0,"H ","")& IF(COUNTIF(P13:U13,"I")>0,"I ","")& IF(COUNTIF(P13:U13,"J")>0,"J ","")& IF(COUNTIF(P13:U13,"K")>0,"K ","")& IF(COUNTIF(P13:U13,"L")>0,"L ","")& IF(COUNTIF(P13:U13,"M")>0,"M ","")& IF(COUNTIF(P13:U13,"N")>0,"N ","")& IF(COUNTIF(P13:U13,"O")>0,"O ","")& IF(COUNTIF(P13:U13,"P")>0,"P ","")& IF(COUNTIF(P13:U13,"Q")>0,"Q ","")& IF(COUNTIF(P13:U13,"R")>0,"R ","")& IF(COUNTIF(P13:U13,"S")>0,"S ","")& IF(COUNTIF(P13:U13,"T")>0,"T ","")& IF(COUNTIF(P13:U13,"U")>0,"U ","")& IF(COUNTIF(P13:U13,"V")>0,"V ","")& IF(COUNTIF(P13:U13,"W")>0,"W ","")& IF(COUNTIF(P13:U13,"X")>0,"X ","")& IF(COUNTIF(P13:U13,"Y")>0,"Y ","")& IF(COUNTIF(P13:U13,"Z")>0,"Z ","")," ",",")) -> D,
A14: 奈良屋幼稚園 | B14: 61 | I14: =I13+2 -> 33 | J14: {=IFERROR(IF(OR(COUNTIF(INDIRECT("数出表_Excel!"&P14&"3"),"*キャラ*"), COUNTIF(INDIRECT("数出表_Excel!"&P14&"3"),"*赤*")), IF(COUNTIF(A14,"*雙葉*"),INDIRECT("数出表_Excel!"&P14&"3"), INDIRECT("数出表_Excel!"&P14&"3") &" "&INDIRECT("数出表_Excel!"&P14&"4") &INDIRECT("数出表_Excel!"&P14&"5")), INDIRECT("数出表_Excel!"&P14&"3")),"")} -> パンカップ | K14: {=IFERROR(IF(OR(COUNTIF(INDIRECT("数出表_Excel!"&Q14&"3"),"*キャラ*"), COUNTIF(INDIRECT("数出表_Excel!"&Q14&"3"),"*赤*")), INDIRECT("数出表_Excel!"&Q14&"3") &" "&INDIRECT("数出表_Excel!"&Q14&"4") &INDIRECT("数出表_Excel!"&Q14&"5"), INDIRECT("数出表_Excel!"&Q14&"3")),"")} | L14: {=IFERROR(IF(OR(COUNTIF(INDIRECT("数出表_Excel!"&R14&"3"),"*キャラ*"), COUNTIF(INDIRECT("数出表_Excel!"&R14&"3"),"*赤*")), INDIRECT("数出表_Excel!"&R14&"3") &" "&INDIRECT("数出表_Excel!"&R14&"4") &INDIRECT("数出表_Excel!"&R14&"5"), INDIRECT("数出表_Excel!"&R14&"3")),"")} | M14: {=IFERROR(IF(OR(COUNTIF(INDIRECT("数出表_Excel!"&S14&"3"),"*キャラ*"), COUNTIF(INDIRECT("数出表_Excel!"&S14&"3"),"*赤*")), INDIRECT("数出表_Excel!"&S14&"3") &" "&INDIRECT("数出表_Excel!"&S14&"4") &INDIRECT("数出表_Excel!"&S14&"5"), INDIRECT("数出表_Excel!"&S14&"3")),"")} | N14: {=IFERROR(IF(OR(COUNTIF(INDIRECT("数出表_Excel!"&T14&"3"),"*キャラ*"), COUNTIF(INDIRECT("数出表_Excel!"&T14&"3"),"*赤*")), INDIRECT("数出表_Excel!"&T14&"3") &" "&INDIRECT("数出表_Excel!"&T14&"4") &INDIRECT("数出表_Excel!"&T14&"5"), INDIRECT("数出表_Excel!"&T14&"3")),"")} | O14: {=IFERROR(IF(OR(COUNTIF(INDIRECT("数出表_Excel!"&U14&"3"),"*キャラ*"), COUNTIF(INDIRECT("数出表_Excel!"&U14&"3"),"*赤*")), INDIRECT("数出表_Excel!"&U14&"3") &" "&INDIRECT("数出表_Excel!"&U14&"4") &INDIRECT("数出表_Excel!"&U14&"5"), INDIRECT("数出表_Excel!"&U14&"3")),"")} | P14: =IFERROR( SUBSTITUTE(ADDRESS(1, IFERROR(COLUMN(INDEX(INDIRECT("数出表_Excel!B"&$I14-1&":T"&$I14-1&""),1,MATCH(TEXT(B14,0),INDIRECT("数出表_Excel!B"&$I14-1&":T"&$I14-1&""),0))),""),4),"1",""), "") -> L | Q14: =IFERROR( SUBSTITUTE(ADDRESS(1, IFERROR(COLUMN(INDEX(INDIRECT("数出表_Excel!B"&$I14-1&":T"&$I14-1&""),1,MATCH(TEXT(C14,0),INDIRECT("数出表_Excel!B"&$I14-1&":T"&$I14-1&""),0))),""),4),"1",""), "") | R14: =IFERROR( SUBSTITUTE(ADDRESS(1, IFERROR(COLUMN(INDEX(INDIRECT("数出表_Excel!B"&$I14-1&":T"&$I14-1&""),1,MATCH(TEXT(D14,0),INDIRECT("数出表_Excel!B"&$I14-1&":T"&$I14-1&""),0))),""),4),"1",""), "") | S14: =IFERROR( SUBSTITUTE(ADDRESS(1, IFERROR(COLUMN(INDEX(INDIRECT("数出表_Excel!B"&$I14&":T"&$I14&""),1,MATCH(TEXT(E14,0),INDIRECT("数出表_Excel!B"&$I14&":T"&$I14&""),0))),""),4),"1",""), "") | T14: =IFERROR( SUBSTITUTE(ADDRESS(1, IFERROR(COLUMN(INDEX(INDIRECT("数出表_Excel!B"&$I14&":T"&$I14&""),1,MATCH(TEXT(F14,0),INDIRECT("数出表_Excel!B"&$I14&":T"&$I14&""),0))),""),4),"1",""), "") | U14: =IFERROR( SUBSTITUTE(ADDRESS(1, IFERROR(COLUMN(INDEX(INDIRECT("数出表_Excel!B"&$I14&":T"&$I14&""),1,MATCH(TEXT(G14,0),INDIRECT("数出表_Excel!B"&$I14&":T"&$I14&""),0))),""),4),"1",""), "") | V14: =TRIM(SUBSTITUTE( IF(COUNTIF(P14:U14,"A")>0,"A ","")& IF(COUNTIF(P14:U14,"B")>0,"B ","")& IF(COUNTIF(P14:U14,"C")>0,"C ","")& IF(COUNTIF(P14:U14,"D")>0,"D ","")& IF(COUNTIF(P14:U14,"E")>0,"E ","")& IF(COUNTIF(P14:U14,"F")>0,"F ","")& IF(COUNTIF(P14:U14,"G")>0,"G ","")& IF(COUNTIF(P14:U14,"H")>0,"H ","")& IF(COUNTIF(P14:U14,"I")>0,"I ","")& IF(COUNTIF(P14:U14,"J")>0,"J ","")& IF(COUNTIF(P14:U14,"K")>0,"K ","")& IF(COUNTIF(P14:U14,"L")>0,"L ","")& IF(COUNTIF(P14:U14,"M")>0,"M ","")& IF(COUNTIF(P14:U14,"N")>0,"N ","")& IF(COUNTIF(P14:U14,"O")>0,"O ","")& IF(COUNTIF(P14:U14,"P")>0,"P ","")& IF(COUNTIF(P14:U14,"Q")>0,"Q ","")& IF(COUNTIF(P14:U14,"R")>0,"R ","")& IF(COUNTIF(P14:U14,"S")>0,"S ","")& IF(COUNTIF(P14:U14,"T")>0,"T ","")& IF(COUNTIF(P14:U14,"U")>0,"U ","")& IF(COUNTIF(P14:U14,"V")>0,"V ","")& IF(COUNTIF(P14:U14,"W")>0,"W ","")& IF(COUNTIF(P14:U14,"X")>0,"X ","")& IF(COUNTIF(P14:U14,"Y")>0,"Y ","")& IF(COUNTIF(P14:U14,"Z")>0,"Z ","")," ",",")) -> L,
