Workbook

Sheet 貼り付け1

Sheet 貼り付け2
O1: 日付・学年の行 | P1: 種類の行 | R1: 日付・学年の行（まとめ） | S1: 種類の行（まとめ） | U1: 学年1 | V1: 学年2 | W1: 学年3 | X1: 学年4 | Z1: 種類1 | AA1: 種類2 | AB1: 種類3 | AC1: 種類4 | AE1: クライアント名1 | AF1: クライアント名2 | AG1: クライアント名3 | AH1: クライアント名4 | AI1: クライアント名3’ | AJ1: クライアント名4’
O2: =IF(COUNTIF(A2,"*/*"),ROW(),0) -> 0 | P2: =IF(O2<>0,O2-1,0) -> 0 | R2: {=IFERROR(_xlfn.AGGREGATE(15, 6, ($O$2:$O$350)/($O$2:$O$350<>0), ROWS($R$2:R2)), "")} | S2: {=IFERROR(_xlfn.AGGREGATE(15, 6, ($P$2:$P$350)/($P$2:$P$350<>0), ROWS($R$2:R2)), "")} | U2: =IF(R2<>"", IF(COUNTIF(OFFSET($A$1,$R2-1,0),"*/*"), IF(COUNTIF(OFFSET($A$1,$R2-1,1),"*/*"),"",2),1),"") | V2: =IF(R2<>"",IF(U2<>"", IF(COUNTIF(OFFSET($A$1,$R2-1,U2),"*/*"), IF(COUNTIF(OFFSET($A$1,$R2-1,U2+1),"*/*"),"",U2+2),U2+1), IF(COUNTIF(OFFSET($A$1,$R2-1,1),"*/*"), IF(COUNTIF(OFFSET($A$1,$R2-1,1+1),"*/*"),"",1+2),1+1)),"") | W2: =IF(R2<>"",IF(V2<>"", IF(COUNTIF(OFFSET($A$1,$R2-1,V2),"*/*"), IF(COUNTIF(OFFSET($A$1,$R2-1,V2+1),"*/*"),"",V2+2),V2+1), IF(COUNTIF(OFFSET($A$1,$R2-1,2),"*/*"), IF(COUNTIF(OFFSET($A$1,$R2-1,2+1),"*/*"),"",2+2),2+1)),"") | X2: =IF(R2<>"",IF(W2<>"", IF(COUNTIF(OFFSET($A$1,$R2-1,W2),"*/*"), IF(COUNTIF(OFFSET($A$1,$R2-1,W2+1),"*/*"),"",W2+2),W2+1), IF(COUNTIF(OFFSET($A$1,$R2-1,5),"*/*"), IF(COUNTIF(OFFSET($A$1,$R2-1,5+1),"*/*"),"", IF(OFFSET($A$1,R2-1,5+2-1)=0,"",5+2)),IF(OFFSET($A$1,R2-1,5+1-1)=0,"",5+1))),"") | Z2: =IF(S2<>"", IF(COUNTIF(OFFSET($A$1,$S2-1,0),"*g*"), 1,IF(COUNTIF(OFFSET($A$1,$S2-1,1),"*g*"),2, IF(OFFSET($A$1,$S2-1,0)=".","", IF(OFFSET($A$1,$S2-1,0)=OFFSET($A$1,$S2-1,1),1,2)))),"") | AA2: =IFERROR(IF(S2<>"", IF(Z2<>"", IF(COUNTIF(OFFSET($A$1,$S2-1,Z2),"*g*"), Z2,IF(COUNTIF(OFFSET($A$1,$S2-1,Z2+1),"*g*"),Z2+2, IF(OFFSET($A$1,$S2-1,Z2)=".","", IF(OFFSET($A$1,$S2-1,Z2)=OFFSET($A$1,$S2-1,Z2+1),Z2+1,Z2+2)))), IF(COUNTIF(OFFSET($A$1,$S2-1,2),"*g*"), 2,IF(COUNTIF(OFFSET($A$1,$S2-1,2+1),"*g*"),2+2, IF(OFFSET($A$1,$S2-1,2)=".","", IF(OFFSET($A$1,$S2-1,2)=OFFSET($A$1,$S2-1,2+1), IF(OFFSET($A$1,$S2-1,2+1)=0,"",2+1), IF(OFFSET($A$1,$S2-1,2)<>"",2, IF(OFFSET($A$1,$S2-1,2+1)<>"",2+1,""))))))),""),"") | AB2: =IFERROR(IF(S2<>"", IF(COUNTIF(OFFSET($A$1,$S2-1,AA2),"*g*"), AA2,IF(COUNTIF(OFFSET($A$1,$S2-1,AA2+1),"*g*"),AA2+2, IF(OFFSET($A$1,$S2-1,AA2)=".","", IF(OFFSET($A$1,$S2-1,AA2)=OFFSET($A$1,$S2-1,AA2+1),AA2+1,AA2+2)))),""),"") | AC2: =IFERROR(IF(S2<>"", IF(COUNTIF(OFFSET($A$1,$S2-1,AB2),"*g*"), AB2,IF(COUNTIF(OFFSET($A$1,$S2-1,AB2+1),"*g*"),AB2+2, IF(OFFSET($A$1,$S2-1,AB2)=".","", IF(OFFSET($A$1,$S2-1,AB2)=OFFSET($A$1,$S2-1,AB2+1),AB2+1, IF(OFFSET($A$1,$S2-1,AB2+1)<>0,AB2+2, IF(OFFSET($A$1,$S2-1,AB2)<>0,AB2+1,"")))))),""),"") | AE2: =IF($S2-1>2, IF(COUNTIF(OFFSET($A$1,$S2-3,0),"*様*"),1, IF(COUNTIF(OFFSET($A$1,$S2-3,1),"*様*"),2, IF(COUNTIF(OFFSET($A$1,$S2-3,2),"*様*"),3,4))), IF(COUNTIF(OFFSET($A$1,$S2-2,0),"*様*"),1, IF(COUNTIF(OFFSET($A$1,$S2-2,1),"*様*"),2, IF(COUNTIF(OFFSET($A$1,$S2-2,2),"*様*"),3,4)))) -> #VALUE! | AF2: =IF($S2-1>2, IF(COUNTIF(OFFSET($A$1,$S2-1-2,AE2),"*様*"),1+AE2, IF(COUNTIF(OFFSET($A$1,$S2-1-2,AE2+1),"*様*"),2+AE2, IF(COUNTIF(OFFSET($A$1,$S2-1-2,AE2+2),"*様*"),3+AE2,4+AE2))), IF(COUNTIF(OFFSET($A$1,$S2-1-1,AE2),"*様*"),1+AE2, IF(COUNTIF(OFFSET($A$1,$S2-1-1,AE2+1),"*様*"),2+AE2, IF(COUNTIF(OFFSET($A$1,$S2-1-1,AE2+2),"*様*"),3+AE2,4+AE2)))) -> #VALUE! | AG2: =IF($S2-1>2, IF(COUNTIF(OFFSET($A$1,$S2-1-2,AF2),"*様*"),1+AF2, IF(COUNTIF(OFFSET($A$1,$S2-1-2,AF2+1),"*様*"),2+AF2, IF(COUNTIF(OFFSET($A$1,$S2-1-2,AF2+2),"*様*"),3+AF2,4+AF2))), IF(COUNTIF(OFFSET($A$1,$S2-1-1,AF2),"*様*"),1+AF2, IF(COUNTIF(OFFSET($A$1,$S2-1-1,AF2+1),"*様*"),2+AF2, IF(COUNTIF(OFFSET($A$1,$S2-1-1,AF2+2),"*様*"),3+AF2,4+AF2)))) -> #VALUE! | AH2: =IF($S2-1>2, IF(COUNTIF(OFFSET($A$1,$S2-1-2,AG2),"*様*"),1+AG2, IF(COUNTIF(OFFSET($A$1,$S2-1-2,AG2+1),"*様*"),2+AG2, IF(COUNTIF(OFFSET($A$1,$S2-1-2,AG2+2),"*様*"),3+AG2,4+AG2))), IF(COUNTIF(OFFSET($A$1,$S2-1-1,AG2),"*様*"),1+AG2, IF(COUNTIF(OFFSET($A$1,$S2-1-1,AG2+1),"*様*"),2+AG2, IF(COUNTIF(OFFSET($A$1,$S2-1-1,AG2+2),"*様*"),3+AG2,4+AG2)))) -> #VALUE!
O3: =IF(COUNTIF(A3,"*/*"),ROW(),0) -> 0 | P3: =IF(O3<>0,O3-1,0) -> 0 | R3: {=IFERROR(_xlfn.AGGREGATE(15, 6, ($O$2:$O$350)/($O$2:$O$350<>0), ROWS($R$2:R3)), "")} | S3: {=IFERROR(_xlfn.AGGREGATE(15, 6, ($P$2:$P$350)/($P$2:$P$350<>0), ROWS($R$2:R3)), "")} | U3: =IF(R3<>"", IF(COUNTIF(OFFSET($A$1,$R3-1,0),"*/*"), IF(COUNTIF(OFFSET($A$1,$R3-1,1),"*/*"),"",2),1),"") | V3: =IF(R3<>"",IF(U3<>"", IF(COUNTIF(OFFSET($A$1,$R3-1,U3),"*/*"), IF(COUNTIF(OFFSET($A$1,$R3-1,U3+1),"*/*"),"",U3+2),U3+1), IF(COUNTIF(OFFSET($A$1,$R3-1,1),"*/*"), IF(COUNTIF(OFFSET($A$1,$R3-1,1+1),"*/*"),"",1+2),1+1)),"") | W3: =IF(R3<>"",IF(V3<>"", IF(COUNTIF(OFFSET($A$1,$R3-1,V3),"*/*"), IF(COUNTIF(OFFSET($A$1,$R3-1,V3+1),"*/*"),"",V3+2),V3+1), IF(COUNTIF(OFFSET($A$1,$R3-1,2),"*/*"), IF(COUNTIF(OFFSET($A$1,$R3-1,2+1),"*/*"),"",2+2),2+1)),"") | X3: =IF(R3<>"",IF(W3<>"", IF(COUNTIF(OFFSET($A$1,$R3-1,W3),"*/*"), IF(COUNTIF(OFFSET($A$1,$R3-1,W3+1),"*/*"),"",W3+2),W3+1), IF(COUNTIF(OFFSET($A$1,$R3-1,5),"*/*"), IF(COUNTIF(OFFSET($A$1,$R3-1,5+1),"*/*"),"", IF(OFFSET($A$1,R3-1,5+2-1)=0,"",5+2)),IF(OFFSET($A$1,R3-1,5+1-1)=0,"",5+1))),"") | Z3: =IF(S3<>"", IF(COUNTIF(OFFSET($A$1,$S3-1,0),"*g*"), 1,IF(COUNTIF(OFFSET($A$1,$S3-1,1),"*g*"),2, IF(OFFSET($A$1,$S3-1,0)=".","", IF(OFFSET($A$1,$S3-1,0)=OFFSET($A$1,$S3-1,1),1,2)))),"") | AA3: =IFERROR(IF(S3<>"", IF(Z3<>"", IF(COUNTIF(OFFSET($A$1,$S3-1,Z3),"*g*"), Z3,IF(COUNTIF(OFFSET($A$1,$S3-1,Z3+1),"*g*"),Z3+2, IF(OFFSET($A$1,$S3-1,Z3)=".","", IF(OFFSET($A$1,$S3-1,Z3)=OFFSET($A$1,$S3-1,Z3+1),Z3+1,Z3+2)))), IF(COUNTIF(OFFSET($A$1,$S3-1,2),"*g*"), 2,IF(COUNTIF(OFFSET($A$1,$S3-1,2+1),"*g*"),2+2, IF(OFFSET($A$1,$S3-1,2)=".","", IF(OFFSET($A$1,$S3-1,2)=OFFSET($A$1,$S3-1,2+1), IF(OFFSET($A$1,$S3-1,2+1)=0,"",2+1), IF(OFFSET($A$1,$S3-1,2)<>"",2, IF(OFFSET($A$1,$S3-1,2+1)<>"",2+1,""))))))),""),"") | AB3: =IFERROR(IF(S3<>"", IF(COUNTIF(OFFSET($A$1,$S3-1,AA3),"*g*"), AA3,IF(COUNTIF(OFFSET($A$1,$S3-1,AA3+1),"*g*"),AA3+2, IF(OFFSET($A$1,$S3-1,AA3)=".","", IF(OFFSET($A$1,$S3-1,AA3)=OFFSET($A$1,$S3-1,AA3+1),AA3+1,AA3+2)))),""),"") | AC3: =IFERROR(IF(S3<>"", IF(COUNTIF(OFFSET($A$1,$S3-1,AB3),"*g*"), AB3,IF(COUNTIF(OFFSET($A$1,$S3-1,AB3+1),"*g*"),AB3+2, IF(OFFSET($A$1,$S3-1,AB3)=".","", IF(OFFSET($A$1,$S3-1,AB3)=OFFSET($A$1,$S3-1,AB3+1),AB3+1, IF(OFFSET($A$1,$S3-1,AB3+1)<>0,AB3+2, IF(OFFSET($A$1,$S3-1,AB3)<>0,AB3+1,"")))))),""),"") | AE3: =IF(R3<>"", IF(AND($S3-$R2>3,COUNTIF(OFFSET($A$1,$R2+($S3-$R2-4),0),"<>*テキスト*")), IF(OFFSET($A$1,$R2+($S3-$R2-4),0)=OFFSET($A$1,$R2+($S3-$R2-4),1),1, IF(OFFSET($A$1,$R2+($S3-$R2-4),0)=OFFSET($A$1,$R2+($S3-$R2-4),2),2, IF(OFFSET($A$1,$R2+($S3-$R2-4),0)=OFFSET($A$1,$R2+($S3-$R2-4),3),3,4))), IF(AND($S3-$R2>2,COUNTIF(OFFSET($A$1,$R2+($S3-$R2-3),0),"<>*テキスト*")), IF(OFFSET($A$1,$R2+($S3-$R2-3),0)=OFFSET($A$1,$R2+($S3-$R2-3),1),1, IF(OFFSET($A$1,$R2+($S3-$R2-3),0)=OFFSET($A$1,$R2+($S3-$R2-3),2),2, IF(OFFSET($A$1,$R2+($S3-$R2-3),0)=OFFSET($A$1,$R2+($S3-$R2-3),3),3,4))), IF(COUNTIF(OFFSET($A$1,$R2+($S3-$R2-2),0),"*様*"),1, IF(COUNTIF(OFFSET($A$1,$R2+($S3-$R2-2),1),"*様*"),2, IF(COUNTIF(OFFSET($A$1,$R2+($S3-$R2-2),2),"*様*"),3,4))))),"") | AF3: =IF(R3<>"", IF(AND($S3-$R2>3,COUNTIF(OFFSET($A$1,$R2+($S3-$R2-4),0),"<>*テキスト*")), IFERROR(IF(OFFSET($A$1,$R2+($S3-$R2-4),AE3)=0,"", IF(OFFSET($A$1,$R2+($S3-$R2-4),AE3)=OFFSET($A$1,$R2+($S3-$R2-4),AE3+1),1+AE3, IF(OFFSET($A$1,$R2+($S3-$R2-4),AE3)=OFFSET($A$1,$R2+($S3-$R2-4),AE3+2),2+AE3, IF(OFFSET($A$1,$R2+($S3-$R2-4),AE3)=OFFSET($A$1,$R2+($S3-$R2-4),AE3+3),3+AE3,3+AE3)))),""), IF(AND($S3-$R2>2,COUNTIF(OFFSET($A$1,$R2+($S3-$R2-3),0),"<>*テキスト*")), IFERROR(IF(OFFSET($A$1,$R2+($S3-$R2-3),AE3)=0,"", IF(OFFSET($A$1,$R2+($S3-$R2-3),AE3)=OFFSET($A$1,$R2+($S3-$R2-3),AE3+1),1+AE3, IF(OFFSET($A$1,$R2+($S3-$R2-3),AE3)=OFFSET($A$1,$R2+($S3-$R2-3),AE3+2),2+AE3, IF(OFFSET($A$1,$R2+($S3-$R2-3),AE3)=OFFSET($A$1,$R2+($S3-$R2-3),AE3+3),3+AE3,3+AE3)))),""), IF(COUNTIF(OFFSET($A$1,$R2+($S3-$R2-2),AE3),"*様*"),1+AE3, IF(COUNTIF(OFFSET($A$1,$R2+($S3-$R2-2),AE3+1),"*様*"),2+AE3, IF(COUNTIF(OFFSET($A$1,$R2+($S3-$R2-2),AE3+2),"*様*"),3+AE3,4+AE3))))),"") | AG3: =IF(R3<>"", IF(AND($S3-$R2>3,COUNTIF(OFFSET($A$1,$R2+($S3-$R2-4),0),"<>*テキスト*")), IFERROR(IF(OFFSET($A$1,$R2+($S3-$R2-4),AF3)=0,"", IF(OFFSET($A$1,$R2+($S3-$R2-4),AF3)=OFFSET($A$1,$R2+($S3-$R2-4),AF3+1),1+AF3, IF(OFFSET($A$1,$R2+($S3-$R2-4),AF3)=OFFSET($A$1,$R2+($S3-$R2-4),AF3+2),2+AF3, IF(OFFSET($A$1,$R2+($S3-$R2-4),AF3)=OFFSET($A$1,$R2+($S3-$R2-4),AF3+3),3+AF3,3+AF3)))),""), IF(AND($S3-$R2>2,COUNTIF(OFFSET($A$1,$R2+($S3-$R2-3),0),"<>*テキスト*")), IFERROR(IF(OFFSET($A$1,$R2+($S3-$R2-3),AF3)=0,"", IF(OFFSET($A$1,$R2+($S3-$R2-3),AF3)=OFFSET($A$1,$R2+($S3-$R2-3),AF3+1),1+AF3, IF(OFFSET($A$1,$R2+($S3-$R2-3),AF3)=OFFSET($A$1,$R2+($S3-$R2-3),AF3+2),2+AF3, IF(OFFSET($A$1,$R2+($S3-$R2-3),AF3)=OFFSET($A$1,$R2+($S3-$R2-3),AF3+3),3+AF3,3+AF3)))),""), IF(COUNTIF(OFFSET($A$1,$R2+($S3-$R2-2),AF3),"*様*"),1+AF3, IF(COUNTIF(OFFSET($A$1,$R2+($S3-$R2-2),AF3+1),"*様*"),2+AF3, IF(COUNTIF(OFFSET($A$1,$R2+($S3-$R2-2),AF3+2),"*様*"),3+AF3,4+AF3))))),"") | AH3: =IF(R3<>"", IF(AND($S3-$R2>3,COUNTIF(OFFSET($A$1,$R2+($S3-$R2-4),0),"<>*テキスト*")), IFERROR(IF(OFFSET($A$1,$R2+($S3-$R2-4),AG3)=0,"", IF(OFFSET($A$1,$R2+($S3-$R2-4),AG3)=OFFSET($A$1,$R2+($S3-$R2-4),AG3+1),1+AG3, IF(OFFSET($A$1,$R2+($S3-$R2-4),AG3)=OFFSET($A$1,$R2+($S3-$R2-4),AG3+2),2+AG3, IF(OFFSET($A$1,$R2+($S3-$R2-4),AG3)=OFFSET($A$1,$R2+($S3-$R2-4),AG3+3),3+AG3,3+AG3)))),""), IF(AND($S3-$R2>2,COUNTIF(OFFSET($A$1,$R2+($S3-$R2-3),0),"<>*テキスト*")), IFERROR(IF(OFFSET($A$1,$R2+($S3-$R2-3),AG3)=0,"", IF(OFFSET($A$1,$R2+($S3-$R2-3),AG3)=OFFSET($A$1,$R2+($S3-$R2-3),AG3+1),1+AG3, IF(OFFSET($A$1,$R2+($S3-$R2-3),AG3)=OFFSET($A$1,$R2+($S3-$R2-3),AG3+2),2+AG3, IF(OFFSET($A$1,$R2+($S3-$R2-3),AG3)=OFFSET($A$1,$R2+($S3-$R2-3),AG3+3),3+AG3,3+AG3)))),""), IF(COUNTIF(OFFSET($A$1,$R2+($S3-$R2-2),AG3),"*様*"),1+AG3, IF(COUNTIF(OFFSET($A$1,$R2+($S3-$R2-2),AG3+1),"*様*"),2+AG3, IF(COUNTIF(OFFSET($A$1,$R2+($S3-$R2-2),AG3+2),"*様*"),3+AG3,4+AG3))))),"") | AI3: =IF(R3<>"", IF(AG3<>"","", IF(COUNTIF(OFFSET($A$1,$R2+($S3-$R2-3),0),"*様*"),1, IF(COUNTIF(OFFSET($A$1,$R2+($S3-$R2-3),1),"*様*"),2, IF(COUNTIF(OFFSET($A$1,$R2+($S3-$R2-3),2),"*様*"),3,4)))),"") | AJ3: =IF(R3<>"", IF(AH3<>"","", IF(AI3<>"", IF(COUNTIF(OFFSET($A$1,$R2+($S3-$R2-3),AI3),"*様*"),1+AI3, IF(COUNTIF(OFFSET($A$1,$R2+($S3-$R2-3),AI3+1),"*様*"),2+AI3, IF(COUNTIF(OFFSET($A$1,$R2+($S3-$R2-3),AI3+2),"*様*"),3+AI3,4+AI3))), IF(COUNTIF(OFFSET($A$1,$R2+($S3-$R2-3),0),"*様*"),1, IF(COUNTIF(OFFSET($A$1,$R2+($S3-$R2-3),1),"*様*"),2, IF(COUNTIF(OFFSET($A$1,$R2+($S3-$R2-3),2),"*様*"),3,4))))),"")
O4: =IF(COUNTIF(A4,"*/*"),ROW(),0) -> 0 | P4: =IF(O4<>0,O4-1,0) -> 0 | R4: {=IFERROR(_xlfn.AGGREGATE(15, 6, ($O$2:$O$350)/($O$2:$O$350<>0), ROWS($R$2:R4)), "")} | S4: {=IFERROR(_xlfn.AGGREGATE(15, 6, ($P$2:$P$350)/($P$2:$P$350<>0), ROWS($R$2:R4)), "")} | U4: =IF(R4<>"", IF(COUNTIF(OFFSET($A$1,$R4-1,0),"*/*"), IF(COUNTIF(OFFSET($A$1,$R4-1,1),"*/*"),"",2),1),"") | V4: =IF(R4<>"",IF(U4<>"", IF(COUNTIF(OFFSET($A$1,$R4-1,U4),"*/*"), IF(COUNTIF(OFFSET($A$1,$R4-1,U4+1),"*/*"),"",U4+2),U4+1), IF(COUNTIF(OFFSET($A$1,$R4-1,1),"*/*"), IF(COUNTIF(OFFSET($A$1,$R4-1,1+1),"*/*"),"",1+2),1+1)),"") | W4: =IF(R4<>"",IF(V4<>"", IF(COUNTIF(OFFSET($A$1,$R4-1,V4),"*/*"), IF(COUNTIF(OFFSET($A$1,$R4-1,V4+1),"*/*"),"",V4+2),V4+1), IF(COUNTIF(OFFSET($A$1,$R4-1,2),"*/*"), IF(COUNTIF(OFFSET($A$1,$R4-1,2+1),"*/*"),"",2+2),2+1)),"") | X4: =IF(R4<>"",IF(W4<>"", IF(COUNTIF(OFFSET($A$1,$R4-1,W4),"*/*"), IF(COUNTIF(OFFSET($A$1,$R4-1,W4+1),"*/*"),"",W4+2),W4+1), IF(COUNTIF(OFFSET($A$1,$R4-1,5),"*/*"), IF(COUNTIF(OFFSET($A$1,$R4-1,5+1),"*/*"),"", IF(OFFSET($A$1,R4-1,5+2-1)=0,"",5+2)),IF(OFFSET($A$1,R4-1,5+1-1)=0,"",5+1))),"") | Z4: =IF(S4<>"", IF(COUNTIF(OFFSET($A$1,$S4-1,0),"*g*"), 1,IF(COUNTIF(OFFSET($A$1,$S4-1,1),"*g*"),2, IF(OFFSET($A$1,$S4-1,0)=".","", IF(OFFSET($A$1,$S4-1,0)=OFFSET($A$1,$S4-1,1),1,2)))),"") | AA4: =IFERROR(IF(S4<>"", IF(Z4<>"", IF(COUNTIF(OFFSET($A$1,$S4-1,Z4),"*g*"), Z4,IF(COUNTIF(OFFSET($A$1,$S4-1,Z4+1),"*g*"),Z4+2, IF(OFFSET($A$1,$S4-1,Z4)=".","", IF(OFFSET($A$1,$S4-1,Z4)=OFFSET($A$1,$S4-1,Z4+1),Z4+1,Z4+2)))), IF(COUNTIF(OFFSET($A$1,$S4-1,2),"*g*"), 2,IF(COUNTIF(OFFSET($A$1,$S4-1,2+1),"*g*"),2+2, IF(OFFSET($A$1,$S4-1,2)=".","", IF(OFFSET($A$1,$S4-1,2)=OFFSET($A$1,$S4-1,2+1), IF(OFFSET($A$1,$S4-1,2+1)=0,"",2+1), IF(OFFSET($A$1,$S4-1,2)<>"",2, IF(OFFSET($A$1,$S4-1,2+1)<>"",2+1,""))))))),""),"") | AB4: =IFERROR(IF(S4<>"", IF(COUNTIF(OFFSET($A$1,$S4-1,AA4),"*g*"), AA4,IF(COUNTIF(OFFSET($A$1,$S4-1,AA4+1),"*g*"),AA4+2, IF(OFFSET($A$1,$S4-1,AA4)=".","", IF(OFFSET($A$1,$S4-1,AA4)=OFFSET($A$1,$S4-1,AA4+1),AA4+1,AA4+2)))),""),"") | AC4: =IFERROR(IF(S4<>"", IF(COUNTIF(OFFSET($A$1,$S4-1,AB4),"*g*"), AB4,IF(COUNTIF(OFFSET($A$1,$S4-1,AB4+1),"*g*"),AB4+2, IF(OFFSET($A$1,$S4-1,AB4)=".","", IF(OFFSET($A$1,$S4-1,AB4)=OFFSET($A$1,$S4-1,AB4+1),AB4+1, IF(OFFSET($A$1,$S4-1,AB4+1)<>0,AB4+2, IF(OFFSET($A$1,$S4-1,AB4)<>0,AB4+1,"")))))),""),"") | AE4: =IF(R4<>"", IF(AND($S4-$R3>3,COUNTIF(OFFSET($A$1,$R3+($S4-$R3-4),0),"<>*テキスト*")), IF(OFFSET($A$1,$R3+($S4-$R3-4),0)=OFFSET($A$1,$R3+($S4-$R3-4),1),1, IF(OFFSET($A$1,$R3+($S4-$R3-4),0)=OFFSET($A$1,$R3+($S4-$R3-4),2),2, IF(OFFSET($A$1,$R3+($S4-$R3-4),0)=OFFSET($A$1,$R3+($S4-$R3-4),3),3,4))), IF(AND($S4-$R3>2,COUNTIF(OFFSET($A$1,$R3+($S4-$R3-3),0),"<>*テキスト*")), IF(OFFSET($A$1,$R3+($S4-$R3-3),0)=OFFSET($A$1,$R3+($S4-$R3-3),1),1, IF(OFFSET($A$1,$R3+($S4-$R3-3),0)=OFFSET($A$1,$R3+($S4-$R3-3),2),2, IF(OFFSET($A$1,$R3+($S4-$R3-3),0)=OFFSET($A$1,$R3+($S4-$R3-3),3),3,4))), IF(COUNTIF(OFFSET($A$1,$R3+($S4-$R3-2),0),"*様*"),1, IF(COUNTIF(OFFSET($A$1,$R3+($S4-$R3-2),1),"*様*"),2, IF(COUNTIF(OFFSET($A$1,$R3+($S4-$R3-2),2),"*様*"),3,4))))),"") | AF4: =IF(R4<>"", IF(AND($S4-$R3>3,COUNTIF(OFFSET($A$1,$R3+($S4-$R3-4),0),"<>*テキスト*")), IFERROR(IF(OFFSET($A$1,$R3+($S4-$R3-4),AE4)=0,"", IF(OFFSET($A$1,$R3+($S4-$R3-4),AE4)=OFFSET($A$1,$R3+($S4-$R3-4),AE4+1),1+AE4, IF(OFFSET($A$1,$R3+($S4-$R3-4),AE4)=OFFSET($A$1,$R3+($S4-$R3-4),AE4+2),2+AE4, IF(OFFSET($A$1,$R3+($S4-$R3-4),AE4)=OFFSET($A$1,$R3+($S4-$R3-4),AE4+3),3+AE4,3+AE4)))),""), IF(AND($S4-$R3>2,COUNTIF(OFFSET($A$1,$R3+($S4-$R3-3),0),"<>*テキスト*")), IFERROR(IF(OFFSET($A$1,$R3+($S4-$R3-3),AE4)=0,"", IF(OFFSET($A$1,$R3+($S4-$R3-3),AE4)=OFFSET($A$1,$R3+($S4-$R3-3),AE4+1),1+AE4, IF(OFFSET($A$1,$R3+($S4-$R3-3),AE4)=OFFSET($A$1,$R3+($S4-$R3-3),AE4+2),2+AE4, IF(OFFSET($A$1,$R3+($S4-$R3-3),AE4)=OFFSET($A$1,$R3+($S4-$R3-3),AE4+3),3+AE4,3+AE4)))),""), IF(COUNTIF(OFFSET($A$1,$R3+($S4-$R3-2),AE4),"*様*"),1+AE4, IF(COUNTIF(OFFSET($A$1,$R3+($S4-$R3-2),AE4+1),"*様*"),2+AE4, IF(COUNTIF(OFFSET($A$1,$R3+($S4-$R3-2),AE4+2),"*様*"),3+AE4,4+AE4))))),"") | AG4: =IF(R4<>"", IF(AND($S4-$R3>3,COUNTIF(OFFSET($A$1,$R3+($S4-$R3-4),0),"<>*テキスト*")), IFERROR(IF(OFFSET($A$1,$R3+($S4-$R3-4),AF4)=0,"", IF(OFFSET($A$1,$R3+($S4-$R3-4),AF4)=OFFSET($A$1,$R3+($S4-$R3-4),AF4+1),1+AF4, IF(OFFSET($A$1,$R3+($S4-$R3-4),AF4)=OFFSET($A$1,$R3+($S4-$R3-4),AF4+2),2+AF4, IF(OFFSET($A$1,$R3+($S4-$R3-4),AF4)=OFFSET($A$1,$R3+($S4-$R3-4),AF4+3),3+AF4,3+AF4)))),""), IF(AND($S4-$R3>2,COUNTIF(OFFSET($A$1,$R3+($S4-$R3-3),0),"<>*テキスト*")), IFERROR(IF(OFFSET($A$1,$R3+($S4-$R3-3),AF4)=0,"", IF(OFFSET($A$1,$R3+($S4-$R3-3),AF4)=OFFSET($A$1,$R3+($S4-$R3-3),AF4+1),1+AF4, IF(OFFSET($A$1,$R3+($S4-$R3-3),AF4)=OFFSET($A$1,$R3+($S4-$R3-3),AF4+2),2+AF4, IF(OFFSET($A$1,$R3+($S4-$R3-3),AF4)=OFFSET($A$1,$R3+($S4-$R3-3),AF4+3),3+AF4,3+AF4)))),""), IF(COUNTIF(OFFSET($A$1,$R3+($S4-$R3-2),AF4),"*様*"),1+AF4, IF(COUNTIF(OFFSET($A$1,$R3+($S4-$R3-2),AF4+1),"*様*"),2+AF4, IF(COUNTIF(OFFSET($A$1,$R3+($S4-$R3-2),AF4+2),"*様*"),3+AF4,4+AF4))))),"") | AH4: =IF(R4<>"", IF(AND($S4-$R3>3,COUNTIF(OFFSET($A$1,$R3+($S4-$R3-4),0),"<>*テキスト*")), IFERROR(IF(OFFSET($A$1,$R3+($S4-$R3-4),AG4)=0,"", IF(OFFSET($A$1,$R3+($S4-$R3-4),AG4)=OFFSET($A$1,$R3+($S4-$R3-4),AG4+1),1+AG4, IF(OFFSET($A$1,$R3+($S4-$R3-4),AG4)=OFFSET($A$1,$R3+($S4-$R3-4),AG4+2),2+AG4, IF(OFFSET($A$1,$R3+($S4-$R3-4),AG4)=OFFSET($A$1,$R3+($S4-$R3-4),AG4+3),3+AG4,3+AG4)))),""), IF(AND($S4-$R3>2,COUNTIF(OFFSET($A$1,$R3+($S4-$R3-3),0),"<>*テキスト*")), IFERROR(IF(OFFSET($A$1,$R3+($S4-$R3-3),AG4)=0,"", IF(OFFSET($A$1,$R3+($S4-$R3-3),AG4)=OFFSET($A$1,$R3+($S4-$R3-3),AG4+1),1+AG4, IF(OFFSET($A$1,$R3+($S4-$R3-3),AG4)=OFFSET($A$1,$R3+($S4-$R3-3),AG4+2),2+AG4, IF(OFFSET($A$1,$R3+($S4-$R3-3),AG4)=OFFSET($A$1,$R3+($S4-$R3-3),AG4+3),3+AG4,3+AG4)))),""), IF(COUNTIF(OFFSET($A$1,$R3+($S4-$R3-2),AG4),"*様*"),1+AG4, IF(COUNTIF(OFFSET($A$1,$R3+($S4-$R3-2),AG4+1),"*様*"),2+AG4, IF(COUNTIF(OFFSET($A$1,$R3+($S4-$R3-2),AG4+2),"*様*"),3+AG4,4+AG4))))),"") | AI4: =IF(R4<>"", IF(AG4<>"","", IF(COUNTIF(OFFSET($A$1,$R3+($S4-$R3-3),0),"*様*"),1, IF(COUNTIF(OFFSET($A$1,$R3+($S4-$R3-3),1),"*様*"),2, IF(COUNTIF(OFFSET($A$1,$R3+($S4-$R3-3),2),"*様*"),3,4)))),"") | AJ4: =IF(R4<>"", IF(AH4<>"","", IF(AI4<>"", IF(COUNTIF(OFFSET($A$1,$R3+($S4-$R3-3),AI4),"*様*"),1+AI4, IF(COUNTIF(OFFSET($A$1,$R3+($S4-$R3-3),AI4+1),"*様*"),2+AI4, IF(COUNTIF(OFFSET($A$1,$R3+($S4-$R3-3),AI4+2),"*様*"),3+AI4,4+AI4))), IF(COUNTIF(OFFSET($A$1,$R3+($S4-$R3-3),0),"*様*"),1, IF(COUNTIF(OFFSET($A$1,$R3+($S4-$R3-3),1),"*様*"),2, IF(COUNTIF(OFFSET($A$1,$R3+($S4-$R3-3),2),"*様*"),3,4))))),"")
O5: =IF(COUNTIF(A5,"*/*"),ROW(),0) -> 0 | P5: =IF(O5<>0,O5-1,0) -> 0 | R5: {=IFERROR(_xlfn.AGGREGATE(15, 6, ($O$2:$O$350)/($O$2:$O$350<>0), ROWS($R$2:R5)), "")} | S5: {=IFERROR(_xlfn.AGGREGATE(15, 6, ($P$2:$P$350)/($P$2:$P$350<>0), ROWS($R$2:R5)), "")} | U5: =IF(R5<>"", IF(COUNTIF(OFFSET($A$1,$R5-1,0),"*/*"), IF(COUNTIF(OFFSET($A$1,$R5-1,1),"*/*"),"",2),1),"") | V5: =IF(R5<>"",IF(U5<>"", IF(COUNTIF(OFFSET($A$1,$R5-1,U5),"*/*"), IF(COUNTIF(OFFSET($A$1,$R5-1,U5+1),"*/*"),"",U5+2),U5+1), IF(COUNTIF(OFFSET($A$1,$R5-1,1),"*/*"), IF(COUNTIF(OFFSET($A$1,$R5-1,1+1),"*/*"),"",1+2),1+1)),"") | W5: =IF(R5<>"",IF(V5<>"", IF(COUNTIF(OFFSET($A$1,$R5-1,V5),"*/*"), IF(COUNTIF(OFFSET($A$1,$R5-1,V5+1),"*/*"),"",V5+2),V5+1), IF(COUNTIF(OFFSET($A$1,$R5-1,2),"*/*"), IF(COUNTIF(OFFSET($A$1,$R5-1,2+1),"*/*"),"",2+2),2+1)),"") | X5: =IF(R5<>"",IF(W5<>"", IF(COUNTIF(OFFSET($A$1,$R5-1,W5),"*/*"), IF(COUNTIF(OFFSET($A$1,$R5-1,W5+1),"*/*"),"",W5+2),W5+1), IF(COUNTIF(OFFSET($A$1,$R5-1,5),"*/*"), IF(COUNTIF(OFFSET($A$1,$R5-1,5+1),"*/*"),"", IF(OFFSET($A$1,R5-1,5+2-1)=0,"",5+2)),IF(OFFSET($A$1,R5-1,5+1-1)=0,"",5+1))),"") | Z5: =IF(S5<>"", IF(COUNTIF(OFFSET($A$1,$S5-1,0),"*g*"), 1,IF(COUNTIF(OFFSET($A$1,$S5-1,1),"*g*"),2, IF(OFFSET($A$1,$S5-1,0)=".","", IF(OFFSET($A$1,$S5-1,0)=OFFSET($A$1,$S5-1,1),1,2)))),"") | AA5: =IFERROR(IF(S5<>"", IF(Z5<>"", IF(COUNTIF(OFFSET($A$1,$S5-1,Z5),"*g*"), Z5,IF(COUNTIF(OFFSET($A$1,$S5-1,Z5+1),"*g*"),Z5+2, IF(OFFSET($A$1,$S5-1,Z5)=".","", IF(OFFSET($A$1,$S5-1,Z5)=OFFSET($A$1,$S5-1,Z5+1),Z5+1,Z5+2)))), IF(COUNTIF(OFFSET($A$1,$S5-1,2),"*g*"), 2,IF(COUNTIF(OFFSET($A$1,$S5-1,2+1),"*g*"),2+2, IF(OFFSET($A$1,$S5-1,2)=".","", IF(OFFSET($A$1,$S5-1,2)=OFFSET($A$1,$S5-1,2+1), IF(OFFSET($A$1,$S5-1,2+1)=0,"",2+1), IF(OFFSET($A$1,$S5-1,2)<>"",2, IF(OFFSET($A$1,$S5-1,2+1)<>"",2+1,""))))))),""),"") | AB5: =IFERROR(IF(S5<>"", IF(COUNTIF(OFFSET($A$1,$S5-1,AA5),"*g*"), AA5,IF(COUNTIF(OFFSET($A$1,$S5-1,AA5+1),"*g*"),AA5+2, IF(OFFSET($A$1,$S5-1,AA5)=".","", IF(OFFSET($A$1,$S5-1,AA5)=OFFSET($A$1,$S5-1,AA5+1),AA5+1,AA5+2)))),""),"") | AC5: =IFERROR(IF(S5<>"", IF(COUNTIF(OFFSET($A$1,$S5-1,AB5),"*g*"), AB5,IF(COUNTIF(OFFSET($A$1,$S5-1,AB5+1),"*g*"),AB5+2, IF(OFFSET($A$1,$S5-1,AB5)=".","", IF(OFFSET($A$1,$S5-1,AB5)=OFFSET($A$1,$S5-1,AB5+1),AB5+1, IF(OFFSET($A$1,$S5-1,AB5+1)<>0,AB5+2, IF(OFFSET($A$1,$S5-1,AB5)<>0,AB5+1,"")))))),""),"") | AE5: =IF(R5<>"", IF(AND($S5-$R4>3,COUNTIF(OFFSET($A$1,$R4+($S5-$R4-4),0),"<>*テキスト*")), IF(OFFSET($A$1,$R4+($S5-$R4-4),0)=OFFSET($A$1,$R4+($S5-$R4-4),1),1, IF(OFFSET($A$1,$R4+($S5-$R4-4),0)=OFFSET($A$1,$R4+($S5-$R4-4),2),2, IF(OFFSET($A$1,$R4+($S5-$R4-4),0)=OFFSET($A$1,$R4+($S5-$R4-4),3),3,4))), IF(AND($S5-$R4>2,COUNTIF(OFFSET($A$1,$R4+($S5-$R4-3),0),"<>*テキスト*")), IF(OFFSET($A$1,$R4+($S5-$R4-3),0)=OFFSET($A$1,$R4+($S5-$R4-3),1),1, IF(OFFSET($A$1,$R4+($S5-$R4-3),0)=OFFSET($A$1,$R4+($S5-$R4-3),2),2, IF(OFFSET($A$1,$R4+($S5-$R4-3),0)=OFFSET($A$1,$R4+($S5-$R4-3),3),3,4))), IF(COUNTIF(OFFSET($A$1,$R4+($S5-$R4-2),0),"*様*"),1, IF(COUNTIF(OFFSET($A$1,$R4+($S5-$R4-2),1),"*様*"),2, IF(COUNTIF(OFFSET($A$1,$R4+($S5-$R4-2),2),"*様*"),3,4))))),"") | AF5: =IF(R5<>"", IF(AND($S5-$R4>3,COUNTIF(OFFSET($A$1,$R4+($S5-$R4-4),0),"<>*テキスト*")), IFERROR(IF(OFFSET($A$1,$R4+($S5-$R4-4),AE5)=0,"", IF(OFFSET($A$1,$R4+($S5-$R4-4),AE5)=OFFSET($A$1,$R4+($S5-$R4-4),AE5+1),1+AE5, IF(OFFSET($A$1,$R4+($S5-$R4-4),AE5)=OFFSET($A$1,$R4+($S5-$R4-4),AE5+2),2+AE5, IF(OFFSET($A$1,$R4+($S5-$R4-4),AE5)=OFFSET($A$1,$R4+($S5-$R4-4),AE5+3),3+AE5,3+AE5)))),""), IF(AND($S5-$R4>2,COUNTIF(OFFSET($A$1,$R4+($S5-$R4-3),0),"<>*テキスト*")), IFERROR(IF(OFFSET($A$1,$R4+($S5-$R4-3),AE5)=0,"", IF(OFFSET($A$1,$R4+($S5-$R4-3),AE5)=OFFSET($A$1,$R4+($S5-$R4-3),AE5+1),1+AE5, IF(OFFSET($A$1,$R4+($S5-$R4-3),AE5)=OFFSET($A$1,$R4+($S5-$R4-3),AE5+2),2+AE5, IF(OFFSET($A$1,$R4+($S5-$R4-3),AE5)=OFFSET($A$1,$R4+($S5-$R4-3),AE5+3),3+AE5,3+AE5)))),""), IF(COUNTIF(OFFSET($A$1,$R4+($S5-$R4-2),AE5),"*様*"),1+AE5, IF(COUNTIF(OFFSET($A$1,$R4+($S5-$R4-2),AE5+1),"*様*"),2+AE5, IF(COUNTIF(OFFSET($A$1,$R4+($S5-$R4-2),AE5+2),"*様*"),3+AE5,4+AE5))))),"") | AG5: =IF(R5<>"", IF(AND($S5-$R4>3,COUNTIF(OFFSET($A$1,$R4+($S5-$R4-4),0),"<>*テキスト*")), IFERROR(IF(OFFSET($A$1,$R4+($S5-$R4-4),AF5)=0,"", IF(OFFSET($A$1,$R4+($S5-$R4-4),AF5)=OFFSET($A$1,$R4+($S5-$R4-4),AF5+1),1+AF5, IF(OFFSET($A$1,$R4+($S5-$R4-4),AF5)=OFFSET($A$1,$R4+($S5-$R4-4),AF5+2),2+AF5, IF(OFFSET($A$1,$R4+($S5-$R4-4),AF5)=OFFSET($A$1,$R4+($S5-$R4-4),AF5+3),3+AF5,3+AF5)))),""), IF(AND($S5-$R4>2,COUNTIF(OFFSET($A$1,$R4+($S5-$R4-3),0),"<>*テキスト*")), IFERROR(IF(OFFSET($A$1,$R4+($S5-$R4-3),AF5)=0,"", IF(OFFSET($A$1,$R4+($S5-$R4-3),AF5)=OFFSET($A$1,$R4+($S5-$R4-3),AF5+1),1+AF5, IF(OFFSET($A$1,$R4+($S5-$R4-3),AF5)=OFFSET($A$1,$R4+($S5-$R4-3),AF5+2),2+AF5, IF(OFFSET($A$1,$R4+($S5-$R4-3),AF5)=OFFSET($A$1,$R4+($S5-$R4-3),AF5+3),3+AF5,3+AF5)))),""), IF(COUNTIF(OFFSET($A$1,$R4+($S5-$R4-2),AF5),"*様*"),1+AF5, IF(COUNTIF(OFFSET($A$1,$R4+($S5-$R4-2),AF5+1),"*様*"),2+AF5, IF(COUNTIF(OFFSET($A$1,$R4+($S5-$R4-2),AF5+2),"*様*"),3+AF5,4+AF5))))),"") | AH5: =IF(R5<>"", IF(AND($S5-$R4>3,COUNTIF(OFFSET($A$1,$R4+($S5-$R4-4),0),"<>*テキスト*")), IFERROR(IF(OFFSET($A$1,$R4+($S5-$R4-4),AG5)=0,"", IF(OFFSET($A$1,$R4+($S5-$R4-4),AG5)=OFFSET($A$1,$R4+($S5-$R4-4),AG5+1),1+AG5, IF(OFFSET($A$1,$R4+($S5-$R4-4),AG5)=OFFSET($A$1,$R4+($S5-$R4-4),AG5+2),2+AG5, IF(OFFSET($A$1,$R4+($S5-$R4-4),AG5)=OFFSET($A$1,$R4+($S5-$R4-4),AG5+3),3+AG5,3+AG5)))),""), IF(AND($S5-$R4>2,COUNTIF(OFFSET($A$1,$R4+($S5-$R4-3),0),"<>*テキスト*")), IFERROR(IF(OFFSET($A$1,$R4+($S5-$R4-3),AG5)=0,"", IF(OFFSET($A$1,$R4+($S5-$R4-3),AG5)=OFFSET($A$1,$R4+($S5-$R4-3),AG5+1),1+AG5, IF(OFFSET($A$1,$R4+($S5-$R4-3),AG5)=OFFSET($A$1,$R4+($S5-$R4-3),AG5+2),2+AG5, IF(OFFSET($A$1,$R4+($S5-$R4-3),AG5)=OFFSET($A$1,$R4+($S5-$R4-3),AG5+3),3+AG5,3+AG5)))),""), IF(COUNTIF(OFFSET($A$1,$R4+($S5-$R4-2),AG5),"*様*"),1+AG5, IF(COUNTIF(OFFSET($A$1,$R4+($S5-$R4-2),AG5+1),"*様*"),2+AG5, IF(COUNTIF(OFFSET($A$1,$R4+($S5-$R4-2),AG5+2),"*様*"),3+AG5,4+AG5))))),"") | AI5: =IF(R5<>"", IF(AG5<>"","", IF(COUNTIF(OFFSET($A$1,$R4+($S5-$R4-3),0),"*様*"),1, IF(COUNTIF(OFFSET($A$1,$R4+($S5-$R4-3),1),"*様*"),2, IF(COUNTIF(OFFSET($A$1,$R4+($S5-$R4-3),2),"*様*"),3,4)))),"") | AJ5: =IF(R5<>"", IF(AH5<>"","", IF(AI5<>"", IF(COUNTIF(OFFSET($A$1,$R4+($S5-$R4-3),AI5),"*様*"),1+AI5, IF(COUNTIF(OFFSET($A$1,$R4+($S5-$R4-3),AI5+1),"*様*"),2+AI5, IF(COUNTIF(OFFSET($A$1,$R4+($S5-$R4-3),AI5+2),"*様*"),3+AI5,4+AI5))), IF(COUNTIF(OFFSET($A$1,$R4+($S5-$R4-3),0),"*様*"),1, IF(COUNTIF(OFFSET($A$1,$R4+($S5-$R4-3),1),"*様*"),2, IF(COUNTIF(OFFSET($A$1,$R4+($S5-$R4-3),2),"*様*"),3,4))))),"")
O6: =IF(COUNTIF(A6,"*/*"),ROW(),0) -> 0 | P6: =IF(O6<>0,O6-1,0) -> 0 | R6: {=IFERROR(_xlfn.AGGREGATE(15, 6, ($O$2:$O$350)/($O$2:$O$350<>0), ROWS($R$2:R6)), "")} | S6: {=IFERROR(_xlfn.AGGREGATE(15, 6, ($P$2:$P$350)/($P$2:$P$350<>0), ROWS($R$2:R6)), "")} | U6: =IF(R6<>"", IF(COUNTIF(OFFSET($A$1,$R6-1,0),"*/*"), IF(COUNTIF(OFFSET($A$1,$R6-1,1),"*/*"),"",2),1),"") | V6: =IF(R6<>"",IF(U6<>"", IF(COUNTIF(OFFSET($A$1,$R6-1,U6),"*/*"), IF(COUNTIF(OFFSET($A$1,$R6-1,U6+1),"*/*"),"",U6+2),U6+1), IF(COUNTIF(OFFSET($A$1,$R6-1,1),"*/*"), IF(COUNTIF(OFFSET($A$1,$R6-1,1+1),"*/*"),"",1+2),1+1)),"") | W6: =IF(R6<>"",IF(V6<>"", IF(COUNTIF(OFFSET($A$1,$R6-1,V6),"*/*"), IF(COUNTIF(OFFSET($A$1,$R6-1,V6+1),"*/*"),"",V6+2),V6+1), IF(COUNTIF(OFFSET($A$1,$R6-1,2),"*/*"), IF(COUNTIF(OFFSET($A$1,$R6-1,2+1),"*/*"),"",2+2),2+1)),"") | X6: =IF(R6<>"",IF(W6<>"", IF(COUNTIF(OFFSET($A$1,$R6-1,W6),"*/*"), IF(COUNTIF(OFFSET($A$1,$R6-1,W6+1),"*/*"),"",W6+2),W6+1), IF(COUNTIF(OFFSET($A$1,$R6-1,5),"*/*"), IF(COUNTIF(OFFSET($A$1,$R6-1,5+1),"*/*"),"", IF(OFFSET($A$1,R6-1,5+2-1)=0,"",5+2)),IF(OFFSET($A$1,R6-1,5+1-1)=0,"",5+1))),"") | Z6: =IF(S6<>"", IF(COUNTIF(OFFSET($A$1,$S6-1,0),"*g*"), 1,IF(COUNTIF(OFFSET($A$1,$S6-1,1),"*g*"),2, IF(OFFSET($A$1,$S6-1,0)=".","", IF(OFFSET($A$1,$S6-1,0)=OFFSET($A$1,$S6-1,1),1,2)))),"") | AA6: =IFERROR(IF(S6<>"", IF(Z6<>"", IF(COUNTIF(OFFSET($A$1,$S6-1,Z6),"*g*"), Z6,IF(COUNTIF(OFFSET($A$1,$S6-1,Z6+1),"*g*"),Z6+2, IF(OFFSET($A$1,$S6-1,Z6)=".","", IF(OFFSET($A$1,$S6-1,Z6)=OFFSET($A$1,$S6-1,Z6+1),Z6+1,Z6+2)))), IF(COUNTIF(OFFSET($A$1,$S6-1,2),"*g*"), 2,IF(COUNTIF(OFFSET($A$1,$S6-1,2+1),"*g*"),2+2, IF(OFFSET($A$1,$S6-1,2)=".","", IF(OFFSET($A$1,$S6-1,2)=OFFSET($A$1,$S6-1,2+1), IF(OFFSET($A$1,$S6-1,2+1)=0,"",2+1), IF(OFFSET($A$1,$S6-1,2)<>"",2, IF(OFFSET($A$1,$S6-1,2+1)<>"",2+1,""))))))),""),"") | AB6: =IFERROR(IF(S6<>"", IF(COUNTIF(OFFSET($A$1,$S6-1,AA6),"*g*"), AA6,IF(COUNTIF(OFFSET($A$1,$S6-1,AA6+1),"*g*"),AA6+2, IF(OFFSET($A$1,$S6-1,AA6)=".","", IF(OFFSET($A$1,$S6-1,AA6)=OFFSET($A$1,$S6-1,AA6+1),AA6+1,AA6+2)))),""),"") | AC6: =IFERROR(IF(S6<>"", IF(COUNTIF(OFFSET($A$1,$S6-1,AB6),"*g*"), AB6,IF(COUNTIF(OFFSET($A$1,$S6-1,AB6+1),"*g*"),AB6+2, IF(OFFSET($A$1,$S6-1,AB6)=".","", IF(OFFSET($A$1,$S6-1,AB6)=OFFSET($A$1,$S6-1,AB6+1),AB6+1, IF(OFFSET($A$1,$S6-1,AB6+1)<>0,AB6+2, IF(OFFSET($A$1,$S6-1,AB6)<>0,AB6+1,"")))))),""),"") | AE6: =IF(R6<>"", IF(AND($S6-$R5>3,COUNTIF(OFFSET($A$1,$R5+($S6-$R5-4),0),"<>*テキスト*")), IF(OFFSET($A$1,$R5+($S6-$R5-4),0)=OFFSET($A$1,$R5+($S6-$R5-4),1),1, IF(OFFSET($A$1,$R5+($S6-$R5-4),0)=OFFSET($A$1,$R5+($S6-$R5-4),2),2, IF(OFFSET($A$1,$R5+($S6-$R5-4),0)=OFFSET($A$1,$R5+($S6-$R5-4),3),3,4))), IF(AND($S6-$R5>2,COUNTIF(OFFSET($A$1,$R5+($S6-$R5-3),0),"<>*テキスト*")), IF(OFFSET($A$1,$R5+($S6-$R5-3),0)=OFFSET($A$1,$R5+($S6-$R5-3),1),1, IF(OFFSET($A$1,$R5+($S6-$R5-3),0)=OFFSET($A$1,$R5+($S6-$R5-3),2),2, IF(OFFSET($A$1,$R5+($S6-$R5-3),0)=OFFSET($A$1,$R5+($S6-$R5-3),3),3,4))), IF(COUNTIF(OFFSET($A$1,$R5+($S6-$R5-2),0),"*様*"),1, IF(COUNTIF(OFFSET($A$1,$R5+($S6-$R5-2),1),"*様*"),2, IF(COUNTIF(OFFSET($A$1,$R5+($S6-$R5-2),2),"*様*"),3,4))))),"") | AF6: =IF(R6<>"", IF(AND($S6-$R5>3,COUNTIF(OFFSET($A$1,$R5+($S6-$R5-4),0),"<>*テキスト*")), IFERROR(IF(OFFSET($A$1,$R5+($S6-$R5-4),AE6)=0,"", IF(OFFSET($A$1,$R5+($S6-$R5-4),AE6)=OFFSET($A$1,$R5+($S6-$R5-4),AE6+1),1+AE6, IF(OFFSET($A$1,$R5+($S6-$R5-4),AE6)=OFFSET($A$1,$R5+($S6-$R5-4),AE6+2),2+AE6, IF(OFFSET($A$1,$R5+($S6-$R5-4),AE6)=OFFSET($A$1,$R5+($S6-$R5-4),AE6+3),3+AE6,3+AE6)))),""), IF(AND($S6-$R5>2,COUNTIF(OFFSET($A$1,$R5+($S6-$R5-3),0),"<>*テキスト*")), IFERROR(IF(OFFSET($A$1,$R5+($S6-$R5-3),AE6)=0,"", IF(OFFSET($A$1,$R5+($S6-$R5-3),AE6)=OFFSET($A$1,$R5+($S6-$R5-3),AE6+1),1+AE6, IF(OFFSET($A$1,$R5+($S6-$R5-3),AE6)=OFFSET($A$1,$R5+($S6-$R5-3),AE6+2),2+AE6, IF(OFFSET($A$1,$R5+($S6-$R5-3),AE6)=OFFSET($A$1,$R5+($S6-$R5-3),AE6+3),3+AE6,3+AE6)))),""), IF(COUNTIF(OFFSET($A$1,$R5+($S6-$R5-2),AE6),"*様*"),1+AE6, IF(COUNTIF(OFFSET($A$1,$R5+($S6-$R5-2),AE6+1),"*様*"),2+AE6, IF(COUNTIF(OFFSET($A$1,$R5+($S6-$R5-2),AE6+2),"*様*"),3+AE6,4+AE6))))),"") | AG6: =IF(R6<>"", IF(AND($S6-$R5>3,COUNTIF(OFFSET($A$1,$R5+($S6-$R5-4),0),"<>*テキスト*")), IFERROR(IF(OFFSET($A$1,$R5+($S6-$R5-4),AF6)=0,"", IF(OFFSET($A$1,$R5+($S6-$R5-4),AF6)=OFFSET($A$1,$R5+($S6-$R5-4),AF6+1),1+AF6, IF(OFFSET($A$1,$R5+($S6-$R5-4),AF6)=OFFSET($A$1,$R5+($S6-$R5-4),AF6+2),2+AF6, IF(OFFSET($A$1,$R5+($S6-$R5-4),AF6)=OFFSET($A$1,$R5+($S6-$R5-4),AF6+3),3+AF6,3+AF6)))),""), IF(AND($S6-$R5>2,COUNTIF(OFFSET($A$1,$R5+($S6-$R5-3),0),"<>*テキスト*")), IFERROR(IF(OFFSET($A$1,$R5+($S6-$R5-3),AF6)=0,"", IF(OFFSET($A$1,$R5+($S6-$R5-3),AF6)=OFFSET($A$1,$R5+($S6-$R5-3),AF6+1),1+AF6, IF(OFFSET($A$1,$R5+($S6-$R5-3),AF6)=OFFSET($A$1,$R5+($S6-$R5-3),AF6+2),2+AF6, IF(OFFSET($A$1,$R5+($S6-$R5-3),AF6)=OFFSET($A$1,$R5+($S6-$R5-3),AF6+3),3+AF6,3+AF6)))),""), IF(COUNTIF(OFFSET($A$1,$R5+($S6-$R5-2),AF6),"*様*"),1+AF6, IF(COUNTIF(OFFSET($A$1,$R5+($S6-$R5-2),AF6+1),"*様*"),2+AF6, IF(COUNTIF(OFFSET($A$1,$R5+($S6-$R5-2),AF6+2),"*様*"),3+AF6,4+AF6))))),"") | AH6: =IF(R6<>"", IF(AND($S6-$R5>3,COUNTIF(OFFSET($A$1,$R5+($S6-$R5-4),0),"<>*テキスト*")), IFERROR(IF(OFFSET($A$1,$R5+($S6-$R5-4),AG6)=0,"", IF(OFFSET($A$1,$R5+($S6-$R5-4),AG6)=OFFSET($A$1,$R5+($S6-$R5-4),AG6+1),1+AG6, IF(OFFSET($A$1,$R5+($S6-$R5-4),AG6)=OFFSET($A$1,$R5+($S6-$R5-4),AG6+2),2+AG6, IF(OFFSET($A$1,$R5+($S6-$R5-4),AG6)=OFFSET($A$1,$R5+($S6-$R5-4),AG6+3),3+AG6,3+AG6)))),""), IF(AND($S6-$R5>2,COUNTIF(OFFSET($A$1,$R5+($S6-$R5-3),0),"<>*テキスト*")), IFERROR(IF(OFFSET($A$1,$R5+($S6-$R5-3),AG6)=0,"", IF(OFFSET($A$1,$R5+($S6-$R5-3),AG6)=OFFSET($A$1,$R5+($S6-$R5-3),AG6+1),1+AG6, IF(OFFSET($A$1,$R5+($S6-$R5-3),AG6)=OFFSET($A$1,$R5+($S6-$R5-3),AG6+2),2+AG6, IF(OFFSET($A$1,$R5+($S6-$R5-3),AG6)=OFFSET($A$1,$R5+($S6-$R5-3),AG6+3),3+AG6,3+AG6)))),""), IF(COUNTIF(OFFSET($A$1,$R5+($S6-$R5-2),AG6),"*様*"),1+AG6, IF(COUNTIF(OFFSET($A$1,$R5+($S6-$R5-2),AG6+1),"*様*"),2+AG6, IF(COUNTIF(OFFSET($A$1,$R5+($S6-$R5-2),AG6+2),"*様*"),3+AG6,4+AG6))))),"") | AI6: =IF(R6<>"", IF(AG6<>"","", IF(COUNTIF(OFFSET($A$1,$R5+($S6-$R5-3),0),"*様*"),1, IF(COUNTIF(OFFSET($A$1,$R5+($S6-$R5-3),1),"*様*"),2, IF(COUNTIF(OFFSET($A$1,$R5+($S6-$R5-3),2),"*様*"),3,4)))),"") | AJ6: =IF(R6<>"", IF(AH6<>"","", IF(AI6<>"", IF(COUNTIF(OFFSET($A$1,$R5+($S6-$R5-3),AI6),"*様*"),1+AI6, IF(COUNTIF(OFFSET($A$1,$R5+($S6-$R5-3),AI6+1),"*様*"),2+AI6, IF(COUNTIF(OFFSET($A$1,$R5+($S6-$R5-3),AI6+2),"*様*"),3+AI6,4+AI6))), IF(COUNTIF(OFFSET($A$1,$R5+($S6-$R5-3),0),"*様*"),1, IF(COUNTIF(OFFSET($A$1,$R5+($S6-$R5-3),1),"*様*"),2, IF(COUNTIF(OFFSET($A$1,$R5+($S6-$R5-3),2),"*様*"),3,4))))),"")
O7: =IF(COUNTIF(A7,"*/*"),ROW(),0) -> 0 | P7: =IF(O7<>0,O7-1,0) -> 0 | R7: {=IFERROR(_xlfn.AGGREGATE(15, 6, ($O$2:$O$350)/($O$2:$O$350<>0), ROWS($R$2:R7)), "")} | S7: {=IFERROR(_xlfn.AGGREGATE(15, 6, ($P$2:$P$350)/($P$2:$P$350<>0), ROWS($R$2:R7)), "")} | U7: =IF(R7<>"", IF(COUNTIF(OFFSET($A$1,$R7-1,0),"*/*"), IF(COUNTIF(OFFSET($A$1,$R7-1,1),"*/*"),"",2),1),"") | V7: =IF(R7<>"",IF(U7<>"", IF(COUNTIF(OFFSET($A$1,$R7-1,U7),"*/*"), IF(COUNTIF(OFFSET($A$1,$R7-1,U7+1),"*/*"),"",U7+2),U7+1), IF(COUNTIF(OFFSET($A$1,$R7-1,1),"*/*"), IF(COUNTIF(OFFSET($A$1,$R7-1,1+1),"*/*"),"",1+2),1+1)),"") | W7: =IF(R7<>"",IF(V7<>"", IF(COUNTIF(OFFSET($A$1,$R7-1,V7),"*/*"), IF(COUNTIF(OFFSET($A$1,$R7-1,V7+1),"*/*"),"",V7+2),V7+1), IF(COUNTIF(OFFSET($A$1,$R7-1,2),"*/*"), IF(COUNTIF(OFFSET($A$1,$R7-1,2+1),"*/*"),"",2+2),2+1)),"") | X7: =IF(R7<>"",IF(W7<>"", IF(COUNTIF(OFFSET($A$1,$R7-1,W7),"*/*"), IF(COUNTIF(OFFSET($A$1,$R7-1,W7+1),"*/*"),"",W7+2),W7+1), IF(COUNTIF(OFFSET($A$1,$R7-1,5),"*/*"), IF(COUNTIF(OFFSET($A$1,$R7-1,5+1),"*/*"),"", IF(OFFSET($A$1,R7-1,5+2-1)=0,"",5+2)),IF(OFFSET($A$1,R7-1,5+1-1)=0,"",5+1))),"") | Z7: =IF(S7<>"", IF(COUNTIF(OFFSET($A$1,$S7-1,0),"*g*"), 1,IF(COUNTIF(OFFSET($A$1,$S7-1,1),"*g*"),2, IF(OFFSET($A$1,$S7-1,0)=".","", IF(OFFSET($A$1,$S7-1,0)=OFFSET($A$1,$S7-1,1),1,2)))),"") | AA7: =IFERROR(IF(S7<>"", IF(Z7<>"", IF(COUNTIF(OFFSET($A$1,$S7-1,Z7),"*g*"), Z7,IF(COUNTIF(OFFSET($A$1,$S7-1,Z7+1),"*g*"),Z7+2, IF(OFFSET($A$1,$S7-1,Z7)=".","", IF(OFFSET($A$1,$S7-1,Z7)=OFFSET($A$1,$S7-1,Z7+1),Z7+1,Z7+2)))), IF(COUNTIF(OFFSET($A$1,$S7-1,2),"*g*"), 2,IF(COUNTIF(OFFSET($A$1,$S7-1,2+1),"*g*"),2+2, IF(OFFSET($A$1,$S7-1,2)=".","", IF(OFFSET($A$1,$S7-1,2)=OFFSET($A$1,$S7-1,2+1), IF(OFFSET($A$1,$S7-1,2+1)=0,"",2+1), IF(OFFSET($A$1,$S7-1,2)<>"",2, IF(OFFSET($A$1,$S7-1,2+1)<>"",2+1,""))))))),""),"") | AB7: =IFERROR(IF(S7<>"", IF(COUNTIF(OFFSET($A$1,$S7-1,AA7),"*g*"), AA7,IF(COUNTIF(OFFSET($A$1,$S7-1,AA7+1),"*g*"),AA7+2, IF(OFFSET($A$1,$S7-1,AA7)=".","", IF(OFFSET($A$1,$S7-1,AA7)=OFFSET($A$1,$S7-1,AA7+1),AA7+1,AA7+2)))),""),"") | AC7: =IFERROR(IF(S7<>"", IF(COUNTIF(OFFSET($A$1,$S7-1,AB7),"*g*"), AB7,IF(COUNTIF(OFFSET($A$1,$S7-1,AB7+1),"*g*"),AB7+2, IF(OFFSET($A$1,$S7-1,AB7)=".","", IF(OFFSET($A$1,$S7-1,AB7)=OFFSET($A$1,$S7-1,AB7+1),AB7+1, IF(OFFSET($A$1,$S7-1,AB7+1)<>0,AB7+2, IF(OFFSET($A$1,$S7-1,AB7)<>0,AB7+1,"")))))),""),"") | AE7: =IF(R7<>"", IF(AND($S7-$R6>3,COUNTIF(OFFSET($A$1,$R6+($S7-$R6-4),0),"<>*テキスト*")), IF(OFFSET($A$1,$R6+($S7-$R6-4),0)=OFFSET($A$1,$R6+($S7-$R6-4),1),1, IF(OFFSET($A$1,$R6+($S7-$R6-4),0)=OFFSET($A$1,$R6+($S7-$R6-4),2),2, IF(OFFSET($A$1,$R6+($S7-$R6-4),0)=OFFSET($A$1,$R6+($S7-$R6-4),3),3,4))), IF(AND($S7-$R6>2,COUNTIF(OFFSET($A$1,$R6+($S7-$R6-3),0),"<>*テキスト*")), IF(OFFSET($A$1,$R6+($S7-$R6-3),0)=OFFSET($A$1,$R6+($S7-$R6-3),1),1, IF(OFFSET($A$1,$R6+($S7-$R6-3),0)=OFFSET($A$1,$R6+($S7-$R6-3),2),2, IF(OFFSET($A$1,$R6+($S7-$R6-3),0)=OFFSET($A$1,$R6+($S7-$R6-3),3),3,4))), IF(COUNTIF(OFFSET($A$1,$R6+($S7-$R6-2),0),"*様*"),1, IF(COUNTIF(OFFSET($A$1,$R6+($S7-$R6-2),1),"*様*"),2, IF(COUNTIF(OFFSET($A$1,$R6+($S7-$R6-2),2),"*様*"),3,4))))),"") | AF7: =IF(R7<>"", IF(AND($S7-$R6>3,COUNTIF(OFFSET($A$1,$R6+($S7-$R6-4),0),"<>*テキスト*")), IFERROR(IF(OFFSET($A$1,$R6+($S7-$R6-4),AE7)=0,"", IF(OFFSET($A$1,$R6+($S7-$R6-4),AE7)=OFFSET($A$1,$R6+($S7-$R6-4),AE7+1),1+AE7, IF(OFFSET($A$1,$R6+($S7-$R6-4),AE7)=OFFSET($A$1,$R6+($S7-$R6-4),AE7+2),2+AE7, IF(OFFSET($A$1,$R6+($S7-$R6-4),AE7)=OFFSET($A$1,$R6+($S7-$R6-4),AE7+3),3+AE7,3+AE7)))),""), IF(AND($S7-$R6>2,COUNTIF(OFFSET($A$1,$R6+($S7-$R6-3),0),"<>*テキスト*")), IFERROR(IF(OFFSET($A$1,$R6+($S7-$R6-3),AE7)=0,"", IF(OFFSET($A$1,$R6+($S7-$R6-3),AE7)=OFFSET($A$1,$R6+($S7-$R6-3),AE7+1),1+AE7, IF(OFFSET($A$1,$R6+($S7-$R6-3),AE7)=OFFSET($A$1,$R6+($S7-$R6-3),AE7+2),2+AE7, IF(OFFSET($A$1,$R6+($S7-$R6-3),AE7)=OFFSET($A$1,$R6+($S7-$R6-3),AE7+3),3+AE7,3+AE7)))),""), IF(COUNTIF(OFFSET($A$1,$R6+($S7-$R6-2),AE7),"*様*"),1+AE7, IF(COUNTIF(OFFSET($A$1,$R6+($S7-$R6-2),AE7+1),"*様*"),2+AE7, IF(COUNTIF(OFFSET($A$1,$R6+($S7-$R6-2),AE7+2),"*様*"),3+AE7,4+AE7))))),"") | AG7: =IF(R7<>"", IF(AND($S7-$R6>3,COUNTIF(OFFSET($A$1,$R6+($S7-$R6-4),0),"<>*テキスト*")), IFERROR(IF(OFFSET($A$1,$R6+($S7-$R6-4),AF7)=0,"", IF(OFFSET($A$1,$R6+($S7-$R6-4),AF7)=OFFSET($A$1,$R6+($S7-$R6-4),AF7+1),1+AF7, IF(OFFSET($A$1,$R6+($S7-$R6-4),AF7)=OFFSET($A$1,$R6+($S7-$R6-4),AF7+2),2+AF7, IF(OFFSET($A$1,$R6+($S7-$R6-4),AF7)=OFFSET($A$1,$R6+($S7-$R6-4),AF7+3),3+AF7,3+AF7)))),""), IF(AND($S7-$R6>2,COUNTIF(OFFSET($A$1,$R6+($S7-$R6-3),0),"<>*テキスト*")), IFERROR(IF(OFFSET($A$1,$R6+($S7-$R6-3),AF7)=0,"", IF(OFFSET($A$1,$R6+($S7-$R6-3),AF7)=OFFSET($A$1,$R6+($S7-$R6-3),AF7+1),1+AF7, IF(OFFSET($A$1,$R6+($S7-$R6-3),AF7)=OFFSET($A$1,$R6+($S7-$R6-3),AF7+2),2+AF7, IF(OFFSET($A$1,$R6+($S7-$R6-3),AF7)=OFFSET($A$1,$R6+($S7-$R6-3),AF7+3),3+AF7,3+AF7)))),""), IF(COUNTIF(OFFSET($A$1,$R6+($S7-$R6-2),AF7),"*様*"),1+AF7, IF(COUNTIF(OFFSET($A$1,$R6+($S7-$R6-2),AF7+1),"*様*"),2+AF7, IF(COUNTIF(OFFSET($A$1,$R6+($S7-$R6-2),AF7+2),"*様*"),3+AF7,4+AF7))))),"") | AH7: =IF(R7<>"", IF(AND($S7-$R6>3,COUNTIF(OFFSET($A$1,$R6+($S7-$R6-4),0),"<>*テキスト*")), IFERROR(IF(OFFSET($A$1,$R6+($S7-$R6-4),AG7)=0,"", IF(OFFSET($A$1,$R6+($S7-$R6-4),AG7)=OFFSET($A$1,$R6+($S7-$R6-4),AG7+1),1+AG7, IF(OFFSET($A$1,$R6+($S7-$R6-4),AG7)=OFFSET($A$1,$R6+($S7-$R6-4),AG7+2),2+AG7, IF(OFFSET($A$1,$R6+($S7-$R6-4),AG7)=OFFSET($A$1,$R6+($S7-$R6-4),AG7+3),3+AG7,3+AG7)))),""), IF(AND($S7-$R6>2,COUNTIF(OFFSET($A$1,$R6+($S7-$R6-3),0),"<>*テキスト*")), IFERROR(IF(OFFSET($A$1,$R6+($S7-$R6-3),AG7)=0,"", IF(OFFSET($A$1,$R6+($S7-$R6-3),AG7)=OFFSET($A$1,$R6+($S7-$R6-3),AG7+1),1+AG7, IF(OFFSET($A$1,$R6+($S7-$R6-3),AG7)=OFFSET($A$1,$R6+($S7-$R6-3),AG7+2),2+AG7, IF(OFFSET($A$1,$R6+($S7-$R6-3),AG7)=OFFSET($A$1,$R6+($S7-$R6-3),AG7+3),3+AG7,3+AG7)))),""), IF(COUNTIF(OFFSET($A$1,$R6+($S7-$R6-2),AG7),"*様*"),1+AG7, IF(COUNTIF(OFFSET($A$1,$R6+($S7-$R6-2),AG7+1),"*様*"),2+AG7, IF(COUNTIF(OFFSET($A$1,$R6+($S7-$R6-2),AG7+2),"*様*"),3+AG7,4+AG7))))),"") | AI7: =IF(R7<>"", IF(AG7<>"","", IF(COUNTIF(OFFSET($A$1,$R6+($S7-$R6-3),0),"*様*"),1, IF(COUNTIF(OFFSET($A$1,$R6+($S7-$R6-3),1),"*様*"),2, IF(COUNTIF(OFFSET($A$1,$R6+($S7-$R6-3),2),"*様*"),3,4)))),"") | AJ7: =IF(R7<>"", IF(AH7<>"","", IF(AI7<>"", IF(COUNTIF(OFFSET($A$1,$R6+($S7-$R6-3),AI7),"*様*"),1+AI7, IF(COUNTIF(OFFSET($A$1,$R6+($S7-$R6-3),AI7+1),"*様*"),2+AI7, IF(COUNTIF(OFFSET($A$1,$R6+($S7-$R6-3),AI7+2),"*様*"),3+AI7,4+AI7))), IF(COUNTIF(OFFSET($A$1,$R6+($S7-$R6-3),0),"*様*"),1, IF(COUNTIF(OFFSET($A$1,$R6+($S7-$R6-3),1),"*様*"),2, IF(COUNTIF(OFFSET($A$1,$R6+($S7-$R6-3),2),"*様*"),3,4))))),"")
O8: =IF(COUNTIF(A8,"*/*"),ROW(),0) -> 0 | P8: =IF(O8<>0,O8-1,0) -> 0 | R8: {=IFERROR(_xlfn.AGGREGATE(15, 6, ($O$2:$O$350)/($O$2:$O$350<>0), ROWS($R$2:R8)), "")} | S8: {=IFERROR(_xlfn.AGGREGATE(15, 6, ($P$2:$P$350)/($P$2:$P$350<>0), ROWS($R$2:R8)), "")} | U8: =IF(R8<>"", IF(COUNTIF(OFFSET($A$1,$R8-1,0),"*/*"), IF(COUNTIF(OFFSET($A$1,$R8-1,1),"*/*"),"",2),1),"") | V8: =IF(R8<>"",IF(U8<>"", IF(COUNTIF(OFFSET($A$1,$R8-1,U8),"*/*"), IF(COUNTIF(OFFSET($A$1,$R8-1,U8+1),"*/*"),"",U8+2),U8+1), IF(COUNTIF(OFFSET($A$1,$R8-1,1),"*/*"), IF(COUNTIF(OFFSET($A$1,$R8-1,1+1),"*/*"),"",1+2),1+1)),"") | W8: =IF(R8<>"",IF(V8<>"", IF(COUNTIF(OFFSET($A$1,$R8-1,V8),"*/*"), IF(COUNTIF(OFFSET($A$1,$R8-1,V8+1),"*/*"),"",V8+2),V8+1), IF(COUNTIF(OFFSET($A$1,$R8-1,2),"*/*"), IF(COUNTIF(OFFSET($A$1,$R8-1,2+1),"*/*"),"",2+2),2+1)),"") | X8: =IF(R8<>"",IF(W8<>"", IF(COUNTIF(OFFSET($A$1,$R8-1,W8),"*/*"), IF(COUNTIF(OFFSET($A$1,$R8-1,W8+1),"*/*"),"",W8+2),W8+1), IF(COUNTIF(OFFSET($A$1,$R8-1,5),"*/*"), IF(COUNTIF(OFFSET($A$1,$R8-1,5+1),"*/*"),"", IF(OFFSET($A$1,R8-1,5+2-1)=0,"",5+2)),IF(OFFSET($A$1,R8-1,5+1-1)=0,"",5+1))),"") | Z8: =IF(S8<>"", IF(COUNTIF(OFFSET($A$1,$S8-1,0),"*g*"), 1,IF(COUNTIF(OFFSET($A$1,$S8-1,1),"*g*"),2, IF(OFFSET($A$1,$S8-1,0)=".","", IF(OFFSET($A$1,$S8-1,0)=OFFSET($A$1,$S8-1,1),1,2)))),"") | AA8: =IFERROR(IF(S8<>"", IF(Z8<>"", IF(COUNTIF(OFFSET($A$1,$S8-1,Z8),"*g*"), Z8,IF(COUNTIF(OFFSET($A$1,$S8-1,Z8+1),"*g*"),Z8+2, IF(OFFSET($A$1,$S8-1,Z8)=".","", IF(OFFSET($A$1,$S8-1,Z8)=OFFSET($A$1,$S8-1,Z8+1),Z8+1,Z8+2)))), IF(COUNTIF(OFFSET($A$1,$S8-1,2),"*g*"), 2,IF(COUNTIF(OFFSET($A$1,$S8-1,2+1),"*g*"),2+2, IF(OFFSET($A$1,$S8-1,2)=".","", IF(OFFSET($A$1,$S8-1,2)=OFFSET($A$1,$S8-1,2+1), IF(OFFSET($A$1,$S8-1,2+1)=0,"",2+1), IF(OFFSET($A$1,$S8-1,2)<>"",2, IF(OFFSET($A$1,$S8-1,2+1)<>"",2+1,""))))))),""),"") | AB8: =IFERROR(IF(S8<>"", IF(COUNTIF(OFFSET($A$1,$S8-1,AA8),"*g*"), AA8,IF(COUNTIF(OFFSET($A$1,$S8-1,AA8+1),"*g*"),AA8+2, IF(OFFSET($A$1,$S8-1,AA8)=".","", IF(OFFSET($A$1,$S8-1,AA8)=OFFSET($A$1,$S8-1,AA8+1),AA8+1,AA8+2)))),""),"") | AC8: =IFERROR(IF(S8<>"", IF(COUNTIF(OFFSET($A$1,$S8-1,AB8),"*g*"), AB8,IF(COUNTIF(OFFSET($A$1,$S8-1,AB8+1),"*g*"),AB8+2, IF(OFFSET($A$1,$S8-1,AB8)=".","", IF(OFFSET($A$1,$S8-1,AB8)=OFFSET($A$1,$S8-1,AB8+1),AB8+1, IF(OFFSET($A$1,$S8-1,AB8+1)<>0,AB8+2, IF(OFFSET($A$1,$S8-1,AB8)<>0,AB8+1,"")))))),""),"") | AE8: =IF(R8<>"", IF(AND($S8-$R7>3,COUNTIF(OFFSET($A$1,$R7+($S8-$R7-4),0),"<>*テキスト*")), IF(OFFSET($A$1,$R7+($S8-$R7-4),0)=OFFSET($A$1,$R7+($S8-$R7-4),1),1, IF(OFFSET($A$1,$R7+($S8-$R7-4),0)=OFFSET($A$1,$R7+($S8-$R7-4),2),2, IF(OFFSET($A$1,$R7+($S8-$R7-4),0)=OFFSET($A$1,$R7+($S8-$R7-4),3),3,4))), IF(AND($S8-$R7>2,COUNTIF(OFFSET($A$1,$R7+($S8-$R7-3),0),"<>*テキスト*")), IF(OFFSET($A$1,$R7+($S8-$R7-3),0)=OFFSET($A$1,$R7+($S8-$R7-3),1),1, IF(OFFSET($A$1,$R7+($S8-$R7-3),0)=OFFSET($A$1,$R7+($S8-$R7-3),2),2, IF(OFFSET($A$1,$R7+($S8-$R7-3),0)=OFFSET($A$1,$R7+($S8-$R7-3),3),3,4))), IF(COUNTIF(OFFSET($A$1,$R7+($S8-$R7-2),0),"*様*"),1, IF(COUNTIF(OFFSET($A$1,$R7+($S8-$R7-2),1),"*様*"),2, IF(COUNTIF(OFFSET($A$1,$R7+($S8-$R7-2),2),"*様*"),3,4))))),"") | AF8: =IF(R8<>"", IF(AND($S8-$R7>3,COUNTIF(OFFSET($A$1,$R7+($S8-$R7-4),0),"<>*テキスト*")), IFERROR(IF(OFFSET($A$1,$R7+($S8-$R7-4),AE8)=0,"", IF(OFFSET($A$1,$R7+($S8-$R7-4),AE8)=OFFSET($A$1,$R7+($S8-$R7-4),AE8+1),1+AE8, IF(OFFSET($A$1,$R7+($S8-$R7-4),AE8)=OFFSET($A$1,$R7+($S8-$R7-4),AE8+2),2+AE8, IF(OFFSET($A$1,$R7+($S8-$R7-4),AE8)=OFFSET($A$1,$R7+($S8-$R7-4),AE8+3),3+AE8,3+AE8)))),""), IF(AND($S8-$R7>2,COUNTIF(OFFSET($A$1,$R7+($S8-$R7-3),0),"<>*テキスト*")), IFERROR(IF(OFFSET($A$1,$R7+($S8-$R7-3),AE8)=0,"", IF(OFFSET($A$1,$R7+($S8-$R7-3),AE8)=OFFSET($A$1,$R7+($S8-$R7-3),AE8+1),1+AE8, IF(OFFSET($A$1,$R7+($S8-$R7-3),AE8)=OFFSET($A$1,$R7+($S8-$R7-3),AE8+2),2+AE8, IF(OFFSET($A$1,$R7+($S8-$R7-3),AE8)=OFFSET($A$1,$R7+($S8-$R7-3),AE8+3),3+AE8,3+AE8)))),""), IF(COUNTIF(OFFSET($A$1,$R7+($S8-$R7-2),AE8),"*様*"),1+AE8, IF(COUNTIF(OFFSET($A$1,$R7+($S8-$R7-2),AE8+1),"*様*"),2+AE8, IF(COUNTIF(OFFSET($A$1,$R7+($S8-$R7-2),AE8+2),"*様*"),3+AE8,4+AE8))))),"") | AG8: =IF(R8<>"", IF(AND($S8-$R7>3,COUNTIF(OFFSET($A$1,$R7+($S8-$R7-4),0),"<>*テキスト*")), IFERROR(IF(OFFSET($A$1,$R7+($S8-$R7-4),AF8)=0,"", IF(OFFSET($A$1,$R7+($S8-$R7-4),AF8)=OFFSET($A$1,$R7+($S8-$R7-4),AF8+1),1+AF8, IF(OFFSET($A$1,$R7+($S8-$R7-4),AF8)=OFFSET($A$1,$R7+($S8-$R7-4),AF8+2),2+AF8, IF(OFFSET($A$1,$R7+($S8-$R7-4),AF8)=OFFSET($A$1,$R7+($S8-$R7-4),AF8+3),3+AF8,3+AF8)))),""), IF(AND($S8-$R7>2,COUNTIF(OFFSET($A$1,$R7+($S8-$R7-3),0),"<>*テキスト*")), IFERROR(IF(OFFSET($A$1,$R7+($S8-$R7-3),AF8)=0,"", IF(OFFSET($A$1,$R7+($S8-$R7-3),AF8)=OFFSET($A$1,$R7+($S8-$R7-3),AF8+1),1+AF8, IF(OFFSET($A$1,$R7+($S8-$R7-3),AF8)=OFFSET($A$1,$R7+($S8-$R7-3),AF8+2),2+AF8, IF(OFFSET($A$1,$R7+($S8-$R7-3),AF8)=OFFSET($A$1,$R7+($S8-$R7-3),AF8+3),3+AF8,3+AF8)))),""), IF(COUNTIF(OFFSET($A$1,$R7+($S8-$R7-2),AF8),"*様*"),1+AF8, IF(COUNTIF(OFFSET($A$1,$R7+($S8-$R7-2),AF8+1),"*様*"),2+AF8, IF(COUNTIF(OFFSET($A$1,$R7+($S8-$R7-2),AF8+2),"*様*"),3+AF8,4+AF8))))),"") | AH8: =IF(R8<>"", IF(AND($S8-$R7>3,COUNTIF(OFFSET($A$1,$R7+($S8-$R7-4),0),"<>*テキスト*")), IFERROR(IF(OFFSET($A$1,$R7+($S8-$R7-4),AG8)=0,"", IF(OFFSET($A$1,$R7+($S8-$R7-4),AG8)=OFFSET($A$1,$R7+($S8-$R7-4),AG8+1),1+AG8, IF(OFFSET($A$1,$R7+($S8-$R7-4),AG8)=OFFSET($A$1,$R7+($S8-$R7-4),AG8+2),2+AG8, IF(OFFSET($A$1,$R7+($S8-$R7-4),AG8)=OFFSET($A$1,$R7+($S8-$R7-4),AG8+3),3+AG8,3+AG8)))),""), IF(AND($S8-$R7>2,COUNTIF(OFFSET($A$1,$R7+($S8-$R7-3),0),"<>*テキスト*")), IFERROR(IF(OFFSET($A$1,$R7+($S8-$R7-3),AG8)=0,"", IF(OFFSET($A$1,$R7+($S8-$R7-3),AG8)=OFFSET($A$1,$R7+($S8-$R7-3),AG8+1),1+AG8, IF(OFFSET($A$1,$R7+($S8-$R7-3),AG8)=OFFSET($A$1,$R7+($S8-$R7-3),AG8+2),2+AG8, IF(OFFSET($A$1,$R7+($S8-$R7-3),AG8)=OFFSET($A$1,$R7+($S8-$R7-3),AG8+3),3+AG8,3+AG8)))),""), IF(COUNTIF(OFFSET($A$1,$R7+($S8-$R7-2),AG8),"*様*"),1+AG8, IF(COUNTIF(OFFSET($A$1,$R7+($S8-$R7-2),AG8+1),"*様*"),2+AG8, IF(COUNTIF(OFFSET($A$1,$R7+($S8-$R7-2),AG8+2),"*様*"),3+AG8,4+AG8))))),"") | AI8: =IF(R8<>"", IF(AG8<>"","", IF(COUNTIF(OFFSET($A$1,$R7+($S8-$R7-3),0),"*様*"),1, IF(COUNTIF(OFFSET($A$1,$R7+($S8-$R7-3),1),"*様*"),2, IF(COUNTIF(OFFSET($A$1,$R7+($S8-$R7-3),2),"*様*"),3,4)))),"") | AJ8: =IF(R8<>"", IF(AH8<>"","", IF(AI8<>"", IF(COUNTIF(OFFSET($A$1,$R7+($S8-$R7-3),AI8),"*様*"),1+AI8, IF(COUNTIF(OFFSET($A$1,$R7+($S8-$R7-3),AI8+1),"*様*"),2+AI8, IF(COUNTIF(OFFSET($A$1,$R7+($S8-$R7-3),AI8+2),"*様*"),3+AI8,4+AI8))), IF(COUNTIF(OFFSET($A$1,$R7+($S8-$R7-3),0),"*様*"),1, IF(COUNTIF(OFFSET($A$1,$R7+($S8-$R7-3),1),"*様*"),2, IF(COUNTIF(OFFSET($A$1,$R7+($S8-$R7-3),2),"*様*"),3,4))))),"")
O9: =IF(COUNTIF(A9,"*/*"),ROW(),0) -> 0 | P9: =IF(O9<>0,O9-1,0) -> 0 | R9: {=IFERROR(_xlfn.AGGREGATE(15, 6, ($O$2:$O$350)/($O$2:$O$350<>0), ROWS($R$2:R9)), "")} | S9: {=IFERROR(_xlfn.AGGREGATE(15, 6, ($P$2:$P$350)/($P$2:$P$350<>0), ROWS($R$2:R9)), "")} | U9: =IF(R9<>"", IF(COUNTIF(OFFSET($A$1,$R9-1,0),"*/*"), IF(COUNTIF(OFFSET($A$1,$R9-1,1),"*/*"),"",2),1),"") | V9: =IF(R9<>"",IF(U9<>"", IF(COUNTIF(OFFSET($A$1,$R9-1,U9),"*/*"), IF(COUNTIF(OFFSET($A$1,$R9-1,U9+1),"*/*"),"",U9+2),U9+1), IF(COUNTIF(OFFSET($A$1,$R9-1,1),"*/*"), IF(COUNTIF(OFFSET($A$1,$R9-1,1+1),"*/*"),"",1+2),1+1)),"") | W9: =IF(R9<>"",IF(V9<>"", IF(COUNTIF(OFFSET($A$1,$R9-1,V9),"*/*"), IF(COUNTIF(OFFSET($A$1,$R9-1,V9+1),"*/*"),"",V9+2),V9+1), IF(COUNTIF(OFFSET($A$1,$R9-1,2),"*/*"), IF(COUNTIF(OFFSET($A$1,$R9-1,2+1),"*/*"),"",2+2),2+1)),"") | X9: =IF(R9<>"",IF(W9<>"", IF(COUNTIF(OFFSET($A$1,$R9-1,W9),"*/*"), IF(COUNTIF(OFFSET($A$1,$R9-1,W9+1),"*/*"),"",W9+2),W9+1), IF(COUNTIF(OFFSET($A$1,$R9-1,5),"*/*"), IF(COUNTIF(OFFSET($A$1,$R9-1,5+1),"*/*"),"", IF(OFFSET($A$1,R9-1,5+2-1)=0,"",5+2)),IF(OFFSET($A$1,R9-1,5+1-1)=0,"",5+1))),"") | Z9: =IF(S9<>"", IF(COUNTIF(OFFSET($A$1,$S9-1,0),"*g*"), 1,IF(COUNTIF(OFFSET($A$1,$S9-1,1),"*g*"),2, IF(OFFSET($A$1,$S9-1,0)=".","", IF(OFFSET($A$1,$S9-1,0)=OFFSET($A$1,$S9-1,1),1,2)))),"") | AA9: =IFERROR(IF(S9<>"", IF(Z9<>"", IF(COUNTIF(OFFSET($A$1,$S9-1,Z9),"*g*"), Z9,IF(COUNTIF(OFFSET($A$1,$S9-1,Z9+1),"*g*"),Z9+2, IF(OFFSET($A$1,$S9-1,Z9)=".","", IF(OFFSET($A$1,$S9-1,Z9)=OFFSET($A$1,$S9-1,Z9+1),Z9+1,Z9+2)))), IF(COUNTIF(OFFSET($A$1,$S9-1,2),"*g*"), 2,IF(COUNTIF(OFFSET($A$1,$S9-1,2+1),"*g*"),2+2, IF(OFFSET($A$1,$S9-1,2)=".","", IF(OFFSET($A$1,$S9-1,2)=OFFSET($A$1,$S9-1,2+1), IF(OFFSET($A$1,$S9-1,2+1)=0,"",2+1), IF(OFFSET($A$1,$S9-1,2)<>"",2, IF(OFFSET($A$1,$S9-1,2+1)<>"",2+1,""))))))),""),"") | AB9: =IFERROR(IF(S9<>"", IF(COUNTIF(OFFSET($A$1,$S9-1,AA9),"*g*"), AA9,IF(COUNTIF(OFFSET($A$1,$S9-1,AA9+1),"*g*"),AA9+2, IF(OFFSET($A$1,$S9-1,AA9)=".","", IF(OFFSET($A$1,$S9-1,AA9)=OFFSET($A$1,$S9-1,AA9+1),AA9+1,AA9+2)))),""),"") | AC9: =IFERROR(IF(S9<>"", IF(COUNTIF(OFFSET($A$1,$S9-1,AB9),"*g*"), AB9,IF(COUNTIF(OFFSET($A$1,$S9-1,AB9+1),"*g*"),AB9+2, IF(OFFSET($A$1,$S9-1,AB9)=".","", IF(OFFSET($A$1,$S9-1,AB9)=OFFSET($A$1,$S9-1,AB9+1),AB9+1, IF(OFFSET($A$1,$S9-1,AB9+1)<>0,AB9+2, IF(OFFSET($A$1,$S9-1,AB9)<>0,AB9+1,"")))))),""),"") | AE9: =IF(R9<>"", IF(AND($S9-$R8>3,COUNTIF(OFFSET($A$1,$R8+($S9-$R8-4),0),"<>*テキスト*")), IF(OFFSET($A$1,$R8+($S9-$R8-4),0)=OFFSET($A$1,$R8+($S9-$R8-4),1),1, IF(OFFSET($A$1,$R8+($S9-$R8-4),0)=OFFSET($A$1,$R8+($S9-$R8-4),2),2, IF(OFFSET($A$1,$R8+($S9-$R8-4),0)=OFFSET($A$1,$R8+($S9-$R8-4),3),3,4))), IF(AND($S9-$R8>2,COUNTIF(OFFSET($A$1,$R8+($S9-$R8-3),0),"<>*テキスト*")), IF(OFFSET($A$1,$R8+($S9-$R8-3),0)=OFFSET($A$1,$R8+($S9-$R8-3),1),1, IF(OFFSET($A$1,$R8+($S9-$R8-3),0)=OFFSET($A$1,$R8+($S9-$R8-3),2),2, IF(OFFSET($A$1,$R8+($S9-$R8-3),0)=OFFSET($A$1,$R8+($S9-$R8-3),3),3,4))), IF(COUNTIF(OFFSET($A$1,$R8+($S9-$R8-2),0),"*様*"),1, IF(COUNTIF(OFFSET($A$1,$R8+($S9-$R8-2),1),"*様*"),2, IF(COUNTIF(OFFSET($A$1,$R8+($S9-$R8-2),2),"*様*"),3,4))))),"") | AF9: =IF(R9<>"", IF(AND($S9-$R8>3,COUNTIF(OFFSET($A$1,$R8+($S9-$R8-4),0),"<>*テキスト*")), IFERROR(IF(OFFSET($A$1,$R8+($S9-$R8-4),AE9)=0,"", IF(OFFSET($A$1,$R8+($S9-$R8-4),AE9)=OFFSET($A$1,$R8+($S9-$R8-4),AE9+1),1+AE9, IF(OFFSET($A$1,$R8+($S9-$R8-4),AE9)=OFFSET($A$1,$R8+($S9-$R8-4),AE9+2),2+AE9, IF(OFFSET($A$1,$R8+($S9-$R8-4),AE9)=OFFSET($A$1,$R8+($S9-$R8-4),AE9+3),3+AE9,3+AE9)))),""), IF(AND($S9-$R8>2,COUNTIF(OFFSET($A$1,$R8+($S9-$R8-3),0),"<>*テキスト*")), IFERROR(IF(OFFSET($A$1,$R8+($S9-$R8-3),AE9)=0,"", IF(OFFSET($A$1,$R8+($S9-$R8-3),AE9)=OFFSET($A$1,$R8+($S9-$R8-3),AE9+1),1+AE9, IF(OFFSET($A$1,$R8+($S9-$R8-3),AE9)=OFFSET($A$1,$R8+($S9-$R8-3),AE9+2),2+AE9, IF(OFFSET($A$1,$R8+($S9-$R8-3),AE9)=OFFSET($A$1,$R8+($S9-$R8-3),AE9+3),3+AE9,3+AE9)))),""), IF(COUNTIF(OFFSET($A$1,$R8+($S9-$R8-2),AE9),"*様*"),1+AE9, IF(COUNTIF(OFFSET($A$1,$R8+($S9-$R8-2),AE9+1),"*様*"),2+AE9, IF(COUNTIF(OFFSET($A$1,$R8+($S9-$R8-2),AE9+2),"*様*"),3+AE9,4+AE9))))),"") | AG9: =IF(R9<>"", IF(AND($S9-$R8>3,COUNTIF(OFFSET($A$1,$R8+($S9-$R8-4),0),"<>*テキスト*")), IFERROR(IF(OFFSET($A$1,$R8+($S9-$R8-4),AF9)=0,"", IF(OFFSET($A$1,$R8+($S9-$R8-4),AF9)=OFFSET($A$1,$R8+($S9-$R8-4),AF9+1),1+AF9, IF(OFFSET($A$1,$R8+($S9-$R8-4),AF9)=OFFSET($A$1,$R8+($S9-$R8-4),AF9+2),2+AF9, IF(OFFSET($A$1,$R8+($S9-$R8-4),AF9)=OFFSET($A$1,$R8+($S9-$R8-4),AF9+3),3+AF9,3+AF9)))),""), IF(AND($S9-$R8>2,COUNTIF(OFFSET($A$1,$R8+($S9-$R8-3),0),"<>*テキスト*")), IFERROR(IF(OFFSET($A$1,$R8+($S9-$R8-3),AF9)=0,"", IF(OFFSET($A$1,$R8+($S9-$R8-3),AF9)=OFFSET($A$1,$R8+($S9-$R8-3),AF9+1),1+AF9, IF(OFFSET($A$1,$R8+($S9-$R8-3),AF9)=OFFSET($A$1,$R8+($S9-$R8-3),AF9+2),2+AF9, IF(OFFSET($A$1,$R8+($S9-$R8-3),AF9)=OFFSET($A$1,$R8+($S9-$R8-3),AF9+3),3+AF9,3+AF9)))),""), IF(COUNTIF(OFFSET($A$1,$R8+($S9-$R8-2),AF9),"*様*"),1+AF9, IF(COUNTIF(OFFSET($A$1,$R8+($S9-$R8-2),AF9+1),"*様*"),2+AF9, IF(COUNTIF(OFFSET($A$1,$R8+($S9-$R8-2),AF9+2),"*様*"),3+AF9,4+AF9))))),"") | AH9: =IF(R9<>"", IF(AND($S9-$R8>3,COUNTIF(OFFSET($A$1,$R8+($S9-$R8-4),0),"<>*テキスト*")), IFERROR(IF(OFFSET($A$1,$R8+($S9-$R8-4),AG9)=0,"", IF(OFFSET($A$1,$R8+($S9-$R8-4),AG9)=OFFSET($A$1,$R8+($S9-$R8-4),AG9+1),1+AG9, IF(OFFSET($A$1,$R8+($S9-$R8-4),AG9)=OFFSET($A$1,$R8+($S9-$R8-4),AG9+2),2+AG9, IF(OFFSET($A$1,$R8+($S9-$R8-4),AG9)=OFFSET($A$1,$R8+($S9-$R8-4),AG9+3),3+AG9,3+AG9)))),""), IF(AND($S9-$R8>2,COUNTIF(OFFSET($A$1,$R8+($S9-$R8-3),0),"<>*テキスト*")), IFERROR(IF(OFFSET($A$1,$R8+($S9-$R8-3),AG9)=0,"", IF(OFFSET($A$1,$R8+($S9-$R8-3),AG9)=OFFSET($A$1,$R8+($S9-$R8-3),AG9+1),1+AG9, IF(OFFSET($A$1,$R8+($S9-$R8-3),AG9)=OFFSET($A$1,$R8+($S9-$R8-3),AG9+2),2+AG9, IF(OFFSET($A$1,$R8+($S9-$R8-3),AG9)=OFFSET($A$1,$R8+($S9-$R8-3),AG9+3),3+AG9,3+AG9)))),""), IF(COUNTIF(OFFSET($A$1,$R8+($S9-$R8-2),AG9),"*様*"),1+AG9, IF(COUNTIF(OFFSET($A$1,$R8+($S9-$R8-2),AG9+1),"*様*"),2+AG9, IF(COUNTIF(OFFSET($A$1,$R8+($S9-$R8-2),AG9+2),"*様*"),3+AG9,4+AG9))))),"") | AI9: =IF(R9<>"", IF(AG9<>"","", IF(COUNTIF(OFFSET($A$1,$R8+($S9-$R8-3),0),"*様*"),1, IF(COUNTIF(OFFSET($A$1,$R8+($S9-$R8-3),1),"*様*"),2, IF(COUNTIF(OFFSET($A$1,$R8+($S9-$R8-3),2),"*様*"),3,4)))),"") | AJ9: =IF(R9<>"", IF(AH9<>"","", IF(AI9<>"", IF(COUNTIF(OFFSET($A$1,$R8+($S9-$R8-3),AI9),"*様*"),1+AI9, IF(COUNTIF(OFFSET($A$1,$R8+($S9-$R8-3),AI9+1),"*様*"),2+AI9, IF(COUNTIF(OFFSET($A$1,$R8+($S9-$R8-3),AI9+2),"*様*"),3+AI9,4+AI9))), IF(COUNTIF(OFFSET($A$1,$R8+($S9-$R8-3),0),"*様*"),1, IF(COUNTIF(OFFSET($A$1,$R8+($S9-$R8-3),1),"*様*"),2, IF(COUNTIF(OFFSET($A$1,$R8+($S9-$R8-3),2),"*様*"),3,4))))),"")
O10: =IF(COUNTIF(A10,"*/*"),ROW(),0) -> 0 | P10: =IF(O10<>0,O10-1,0) -> 0 | R10: {=IFERROR(_xlfn.AGGREGATE(15, 6, ($O$2:$O$350)/($O$2:$O$350<>0), ROWS($R$2:R10)), "")} | S10: {=IFERROR(_xlfn.AGGREGATE(15, 6, ($P$2:$P$350)/($P$2:$P$350<>0), ROWS($R$2:R10)), "")} | U10: =IF(R10<>"", IF(COUNTIF(OFFSET($A$1,$R10-1,0),"*/*"), IF(COUNTIF(OFFSET($A$1,$R10-1,1),"*/*"),"",2),1),"") | V10: =IF(R10<>"",IF(U10<>"", IF(COUNTIF(OFFSET($A$1,$R10-1,U10),"*/*"), IF(COUNTIF(OFFSET($A$1,$R10-1,U10+1),"*/*"),"",U10+2),U10+1), IF(COUNTIF(OFFSET($A$1,$R10-1,1),"*/*"), IF(COUNTIF(OFFSET($A$1,$R10-1,1+1),"*/*"),"",1+2),1+1)),"") | W10: =IF(R10<>"",IF(V10<>"", IF(COUNTIF(OFFSET($A$1,$R10-1,V10),"*/*"), IF(COUNTIF(OFFSET($A$1,$R10-1,V10+1),"*/*"),"",V10+2),V10+1), IF(COUNTIF(OFFSET($A$1,$R10-1,2),"*/*"), IF(COUNTIF(OFFSET($A$1,$R10-1,2+1),"*/*"),"",2+2),2+1)),"") | X10: =IF(R10<>"",IF(W10<>"", IF(COUNTIF(OFFSET($A$1,$R10-1,W10),"*/*"), IF(COUNTIF(OFFSET($A$1,$R10-1,W10+1),"*/*"),"",W10+2),W10+1), IF(COUNTIF(OFFSET($A$1,$R10-1,5),"*/*"), IF(COUNTIF(OFFSET($A$1,$R10-1,5+1),"*/*"),"", IF(OFFSET($A$1,R10-1,5+2-1)=0,"",5+2)),IF(OFFSET($A$1,R10-1,5+1-1)=0,"",5+1))),"") | Z10: =IF(S10<>"", IF(COUNTIF(OFFSET($A$1,$S10-1,0),"*g*"), 1,IF(COUNTIF(OFFSET($A$1,$S10-1,1),"*g*"),2, IF(OFFSET($A$1,$S10-1,0)=".","", IF(OFFSET($A$1,$S10-1,0)=OFFSET($A$1,$S10-1,1),1,2)))),"") | AA10: =IFERROR(IF(S10<>"", IF(Z10<>"", IF(COUNTIF(OFFSET($A$1,$S10-1,Z10),"*g*"), Z10,IF(COUNTIF(OFFSET($A$1,$S10-1,Z10+1),"*g*"),Z10+2, IF(OFFSET($A$1,$S10-1,Z10)=".","", IF(OFFSET($A$1,$S10-1,Z10)=OFFSET($A$1,$S10-1,Z10+1),Z10+1,Z10+2)))), IF(COUNTIF(OFFSET($A$1,$S10-1,2),"*g*"), 2,IF(COUNTIF(OFFSET($A$1,$S10-1,2+1),"*g*"),2+2, IF(OFFSET($A$1,$S10-1,2)=".","", IF(OFFSET($A$1,$S10-1,2)=OFFSET($A$1,$S10-1,2+1), IF(OFFSET($A$1,$S10-1,2+1)=0,"",2+1), IF(OFFSET($A$1,$S10-1,2)<>"",2, IF(OFFSET($A$1,$S10-1,2+1)<>"",2+1,""))))))),""),"") | AB10: =IFERROR(IF(S10<>"", IF(COUNTIF(OFFSET($A$1,$S10-1,AA10),"*g*"), AA10,IF(COUNTIF(OFFSET($A$1,$S10-1,AA10+1),"*g*"),AA10+2, IF(OFFSET($A$1,$S10-1,AA10)=".","", IF(OFFSET($A$1,$S10-1,AA10)=OFFSET($A$1,$S10-1,AA10+1),AA10+1,AA10+2)))),""),"") | AC10: =IFERROR(IF(S10<>"", IF(COUNTIF(OFFSET($A$1,$S10-1,AB10),"*g*"), AB10,IF(COUNTIF(OFFSET($A$1,$S10-1,AB10+1),"*g*"),AB10+2, IF(OFFSET($A$1,$S10-1,AB10)=".","", IF(OFFSET($A$1,$S10-1,AB10)=OFFSET($A$1,$S10-1,AB10+1),AB10+1, IF(OFFSET($A$1,$S10-1,AB10+1)<>0,AB10+2, IF(OFFSET($A$1,$S10-1,AB10)<>0,AB10+1,"")))))),""),"") | AE10: =IF(R10<>"", IF(AND($S10-$R9>3,COUNTIF(OFFSET($A$1,$R9+($S10-$R9-4),0),"<>*テキスト*")), IF(OFFSET($A$1,$R9+($S10-$R9-4),0)=OFFSET($A$1,$R9+($S10-$R9-4),1),1, IF(OFFSET($A$1,$R9+($S10-$R9-4),0)=OFFSET($A$1,$R9+($S10-$R9-4),2),2, IF(OFFSET($A$1,$R9+($S10-$R9-4),0)=OFFSET($A$1,$R9+($S10-$R9-4),3),3,4))), IF(AND($S10-$R9>2,COUNTIF(OFFSET($A$1,$R9+($S10-$R9-3),0),"<>*テキスト*")), IF(OFFSET($A$1,$R9+($S10-$R9-3),0)=OFFSET($A$1,$R9+($S10-$R9-3),1),1, IF(OFFSET($A$1,$R9+($S10-$R9-3),0)=OFFSET($A$1,$R9+($S10-$R9-3),2),2, IF(OFFSET($A$1,$R9+($S10-$R9-3),0)=OFFSET($A$1,$R9+($S10-$R9-3),3),3,4))), IF(COUNTIF(OFFSET($A$1,$R9+($S10-$R9-2),0),"*様*"),1, IF(COUNTIF(OFFSET($A$1,$R9+($S10-$R9-2),1),"*様*"),2, IF(COUNTIF(OFFSET($A$1,$R9+($S10-$R9-2),2),"*様*"),3,4))))),"") | AF10: =IF(R10<>"", IF(AND($S10-$R9>3,COUNTIF(OFFSET($A$1,$R9+($S10-$R9-4),0),"<>*テキスト*")), IFERROR(IF(OFFSET($A$1,$R9+($S10-$R9-4),AE10)=0,"", IF(OFFSET($A$1,$R9+($S10-$R9-4),AE10)=OFFSET($A$1,$R9+($S10-$R9-4),AE10+1),1+AE10, IF(OFFSET($A$1,$R9+($S10-$R9-4),AE10)=OFFSET($A$1,$R9+($S10-$R9-4),AE10+2),2+AE10, IF(OFFSET($A$1,$R9+($S10-$R9-4),AE10)=OFFSET($A$1,$R9+($S10-$R9-4),AE10+3),3+AE10,3+AE10)))),""), IF(AND($S10-$R9>2,COUNTIF(OFFSET($A$1,$R9+($S10-$R9-3),0),"<>*テキスト*")), IFERROR(IF(OFFSET($A$1,$R9+($S10-$R9-3),AE10)=0,"", IF(OFFSET($A$1,$R9+($S10-$R9-3),AE10)=OFFSET($A$1,$R9+($S10-$R9-3),AE10+1),1+AE10, IF(OFFSET($A$1,$R9+($S10-$R9-3),AE10)=OFFSET($A$1,$R9+($S10-$R9-3),AE10+2),2+AE10, IF(OFFSET($A$1,$R9+($S10-$R9-3),AE10)=OFFSET($A$1,$R9+($S10-$R9-3),AE10+3),3+AE10,3+AE10)))),""), IF(COUNTIF(OFFSET($A$1,$R9+($S10-$R9-2),AE10),"*様*"),1+AE10, IF(COUNTIF(OFFSET($A$1,$R9+($S10-$R9-2),AE10+1),"*様*"),2+AE10, IF(COUNTIF(OFFSET($A$1,$R9+($S10-$R9-2),AE10+2),"*様*"),3+AE10,4+AE10))))),"") | AG10: =IF(R10<>"", IF(AND($S10-$R9>3,COUNTIF(OFFSET($A$1,$R9+($S10-$R9-4),0),"<>*テキスト*")), IFERROR(IF(OFFSET($A$1,$R9+($S10-$R9-4),AF10)=0,"", IF(OFFSET($A$1,$R9+($S10-$R9-4),AF10)=OFFSET($A$1,$R9+($S10-$R9-4),AF10+1),1+AF10, IF(OFFSET($A$1,$R9+($S10-$R9-4),AF10)=OFFSET($A$1,$R9+($S10-$R9-4),AF10+2),2+AF10, IF(OFFSET($A$1,$R9+($S10-$R9-4),AF10)=OFFSET($A$1,$R9+($S10-$R9-4),AF10+3),3+AF10,3+AF10)))),""), IF(AND($S10-$R9>2,COUNTIF(OFFSET($A$1,$R9+($S10-$R9-3),0),"<>*テキスト*")), IFERROR(IF(OFFSET($A$1,$R9+($S10-$R9-3),AF10)=0,"", IF(OFFSET($A$1,$R9+($S10-$R9-3),AF10)=OFFSET($A$1,$R9+($S10-$R9-3),AF10+1),1+AF10, IF(OFFSET($A$1,$R9+($S10-$R9-3),AF10)=OFFSET($A$1,$R9+($S10-$R9-3),AF10+2),2+AF10, IF(OFFSET($A$1,$R9+($S10-$R9-3),AF10)=OFFSET($A$1,$R9+($S10-$R9-3),AF10+3),3+AF10,3+AF10)))),""), IF(COUNTIF(OFFSET($A$1,$R9+($S10-$R9-2),AF10),"*様*"),1+AF10, IF(COUNTIF(OFFSET($A$1,$R9+($S10-$R9-2),AF10+1),"*様*"),2+AF10, IF(COUNTIF(OFFSET($A$1,$R9+($S10-$R9-2),AF10+2),"*様*"),3+AF10,4+AF10))))),"") | AH10: =IF(R10<>"", IF(AND($S10-$R9>3,COUNTIF(OFFSET($A$1,$R9+($S10-$R9-4),0),"<>*テキスト*")), IFERROR(IF(OFFSET($A$1,$R9+($S10-$R9-4),AG10)=0,"", IF(OFFSET($A$1,$R9+($S10-$R9-4),AG10)=OFFSET($A$1,$R9+($S10-$R9-4),AG10+1),1+AG10, IF(OFFSET($A$1,$R9+($S10-$R9-4),AG10)=OFFSET($A$1,$R9+($S10-$R9-4),AG10+2),2+AG10, IF(OFFSET($A$1,$R9+($S10-$R9-4),AG10)=OFFSET($A$1,$R9+($S10-$R9-4),AG10+3),3+AG10,3+AG10)))),""), IF(AND($S10-$R9>2,COUNTIF(OFFSET($A$1,$R9+($S10-$R9-3),0),"<>*テキスト*")), IFERROR(IF(OFFSET($A$1,$R9+($S10-$R9-3),AG10)=0,"", IF(OFFSET($A$1,$R9+($S10-$R9-3),AG10)=OFFSET($A$1,$R9+($S10-$R9-3),AG10+1),1+AG10, IF(OFFSET($A$1,$R9+($S10-$R9-3),AG10)=OFFSET($A$1,$R9+($S10-$R9-3),AG10+2),2+AG10, IF(OFFSET($A$1,$R9+($S10-$R9-3),AG10)=OFFSET($A$1,$R9+($S10-$R9-3),AG10+3),3+AG10,3+AG10)))),""), IF(COUNTIF(OFFSET($A$1,$R9+($S10-$R9-2),AG10),"*様*"),1+AG10, IF(COUNTIF(OFFSET($A$1,$R9+($S10-$R9-2),AG10+1),"*様*"),2+AG10, IF(COUNTIF(OFFSET($A$1,$R9+($S10-$R9-2),AG10+2),"*様*"),3+AG10,4+AG10))))),"") | AI10: =IF(R10<>"", IF(AG10<>"","", IF(COUNTIF(OFFSET($A$1,$R9+($S10-$R9-3),0),"*様*"),1, IF(COUNTIF(OFFSET($A$1,$R9+($S10-$R9-3),1),"*様*"),2, IF(COUNTIF(OFFSET($A$1,$R9+($S10-$R9-3),2),"*様*"),3,4)))),"") | AJ10: =IF(R10<>"", IF(AH10<>"","", IF(AI10<>"", IF(COUNTIF(OFFSET($A$1,$R9+($S10-$R9-3),AI10),"*様*"),1+AI10, IF(COUNTIF(OFFSET($A$1,$R9+($S10-$R9-3),AI10+1),"*様*"),2+AI10, IF(COUNTIF(OFFSET($A$1,$R9+($S10-$R9-3),AI10+2),"*様*"),3+AI10,4+AI10))), IF(COUNTIF(OFFSET($A$1,$R9+($S10-$R9-3),0),"*様*"),1, IF(COUNTIF(OFFSET($A$1,$R9+($S10-$R9-3),1),"*様*"),2, IF(COUNTIF(OFFSET($A$1,$R9+($S10-$R9-3),2),"*様*"),3,4))))),"")
